Workbook

Sheet Tabla de Emisiones y Remociones
A1: Categories | B1: 2017 | C1: 2018 | D1: 2019 | E1: 2020 | F1: 2021 | G1: 2022 | H1: 2023
A2: Total National Emissions and Removals | B2: 77.109 | C2: 79.915 | D2: 84.314 | E2: 78.53 | F2: 88.892 | G2: 91.427 | H2: 97.324
A3: 1 - Energy | B3: 67.534 | C3: 70.317 | D3: 74.494 | E3: 69.087 | F3: 78.504 | G3: 80.656 | H3: 85.978
A4: 1.A - Fuel Combustion Activities | B4: 45.431 | C4: 45.676 | D4: 47.548 | E4: 45.126 | F4: 51.749 | G4: 55.988 | H4: 58.95
A5: 1.A.1 - Energy Industries | B5: 23.296 | C5: 24.048 | D5: 24.825 | E5: 23.427 | F5: 26.089 | G5: 27.76 | H5: 32.539
A6: 1.A.2 - Manufacturing Industries and Construction | B6: 1.509 | C6: 1.64 | D6: 1.794 | E6: 1.57 | F6: 2.273 | G6: 2.07 | H6: 1.98
A7: 1.A.3 - Transport | B7: 19.795 | C7: 19.149 | D7: 20.072 | E7: 19.293 | F7: 22.453 | G7: 25.193 | H7: 23.403
A8: 1.A.4 - Other Sectors | B8: 831 | C8: 840 | D8: 856 | E8: 836 | F8: 933 | G8: 965 | H8: 1.029
A9: 1.B - Fugitive emissions from fuels | B9: 22.103 | C9: 24.64 | D9: 26.946 | E9: 23.961 | F9: 26.755 | G9: 24.668 | H9: 27.028
A10: 1.C - Carbon dioxide Transport and Storage | B10: 0 | C10: 0 | D10: 0 | E10: 0 | F10: 0 | G10: 0 | H10: 0
A11: 2 - Industrial Processes and Product Use | B11: 5.203 | C11: 5.1 | D11: 5.307 | E11: 4.918 | F11: 5.845 | G11: 6.144 | H11: 6.658
A12: 2.A - Mineral Industry | B12: 1.244 | C12: 1.367 | D12: 1.281 | E12: 1.331 | F12: 1.524 | G12: 1.698 | H12: 1.51
... A36: 4.D - Wastewater Treatment and Discharge | B36: 496 | C36: 503 | D36: 477 | E36: 482 | F36: 487 | G36: 492 | H36: 496
A38: Total National Emissions and Removals | B38: =+B2 | C38: =+C2 | D38: =+D2 | E38: =+E2 | F38: =+F2 | G38: =+G2 | H38: =+H2
A39: 1 - Energy | B39: =+B3 | C39: =+C3 | D39: =+D3 | E39: =+E3 | F39: =+F3 | G39: =+G3 | H39: =+H3
A40: 1.A - Fuel Combustion Activities | B40: =+B4 | C40: =+C4 | D40: =+D4 | E40: =+E4 | F40: =+F4 | G40: =+G4 | H40: =+H4
A41: 1.A.1 - Energy Industries | B41: =+B5 | C41: =+C5 | D41: =+D5 | E41: =+E5 | F41: =+F5 | G41: =+G5 | H41: =+H5
A42: 1.A.2 - Manufacturing Industries and Construction | B42: =+B6 | C42: =+C6 | D42: =+D6 | E42: =+E6 | F42: =+F6 | G42: =+G6 | H42: =+H6
A43: 1.A.3 - Transport | B43: =+B7 | C43: =+C7 | D43: =+D7 | E43: =+E7 | F43: =+F7 | G43: =+G7 | H43: =+H7
A44: 1.A.4 - Other Sectors | B44: =+B8/1000 | C44: =+C8/1000 | D44: =+D8/1000 | E44: =+E8/1000 | F44: =+F8/1000 | G44: =+G8/1000 | H44: =+H8
A45: 1.B - Fugitive emissions from fuels | B45: =+B9 | C45: =+C9 | D45: =+D9 | E45: =+E9 | F45: =+F9 | G45: =+G9 | H45: =+H9
A46: 1.C - Carbon dioxide Transport and Storage | B46: =+B10 | C46: =+C10 | D46: =+D10 | E46: =+E10 | F46: =+F10 | G46: =+G10 | H46: =+H10
A47: 2 - Industrial Processes and Product Use | B47: =+B11 | C47: =+C11 | D47: =+D11 | E47: =+E11 | F47: =+F11 | G47: =+G11 | H47: =+H11
A48: 2.A - Mineral Industry | B48: =+B12 | C48: =+C12 | D48: =+D12 | E48: =+E12 | F48: =+F12 | G48: =+G12 | H48: =+H12
A49: 2.A.1 - Cement production | B49: =+B13 | C49: =+C13 | D49: =+D13 | E49: =+E13 | F49: =+F13 | G49: =+G13 | H49: =+H13
A50: 2.A.2 - Lime production | B50: =+B14/1000 | C50: =+C14/1000 | D50: =+D14/1000 | E50: =+E14/1000 | F50: =+F14/1000 | G50: =+G14/1000 | H50: =+H14/1000
A51: 2.B - Chemical Industry | B51: =+B15/1000 | C51: =+C15/1000 | D51: =+D15/1000 | E51: =+E15/1000 | F51: =+F15/1000 | G51: =+G15/1000 | H51: =+H15/1000
A52: 2.B.1 - Ammonia Production | B52: =+B16/1000 | C52: =+C16/1000 | D52: =+D16/1000 | E52: =+E16/1000 | F52: =+F16/1000 | G52: =+G16/1000 | H52: =+H16/1000
A53: 2.B.8 - Petrochemical and Carbon Black Production | B53: =+B17/1000 | C53: =+C17/1000 | D53: =+D17/1000 | E53: =+E17/1000 | F53: =+F17/1000 | G53: =+G17/1000 | H53: =+H17/1000
A54: 2.C - Metal Industry | B54: =+B18/1000 | C54: =+C18/1000 | D54: =+D18 | E54: =+E18 | F54: =+F18 | G54: =+G18 | H54: =+H18
A55: 2.C.1 - Iron and Steel Production | B55: =+B19/1000 | C55: =+C19/1000 | D55: =+D19 | E55: =+E19 | F55: =+F19 | G55: =+G19 | H55: =+H19
A56: 2.D - Non-Energy Products from Fuels and Solvent Use | B56: =+B20/100 | C56: =+C20/100 | D56: =+D20/100 | E56: =+E20/100 | F56: =+F20/100 | G56: =+G20/100 | H56: =+H20/100
A57: 2.F - Product Uses as Substitutes for Ozone Depleting Substances | B57: 2.12 | C57: 2.107 | D57: 2.18 | E57: 2.262 | F57: 2.183 | G57: 2.238 | H57: 2.104
A58: 2.F.1 - Refrigeration and Air Conditioning | B58: 2.12 | C58: 2.107 | D58: 2.18 | E58: 2.262 | F58: 2.183 | G58: 2.238 | H58: 2.104
A59: 3 - Agriculture, Forestry, and Other Land Use | B59: =+B23 | C59: =+C23 | D59: =+D23 | E59: =+E23 | F59: =+F23 | G59: =+G23 | H59: =+H23
A60: 3.A - Livestock | B60: =+B24 | C60: =+C24 | D60: =+D24 | E60: =+E24 | F60: =+F24 | G60: =+G24 | H60: =+H24
A61: 3.A.1 - Enteric Fermentation | B61: =+B25 | C61: =+C25 | D61: =+D25 | E61: =+E25 | F61: =+F25 | G61: =+G25 | H61: =+H25
A62: 3.A.2 - Manure Management | B62: =+B26/1000 | C62: =+C26/1000 | D62: =+D26/1000 | E62: =+E26/1000 | F62: =+F26/1000 | G62: =+G26/1000 | H62: =+H26/1000
A63: 3.B.1 - Forest land | B63: -0.65303622 | C63: -0.78364347 | D63: -0.94037216 | E63: -1.1284466 | F63: -1.3541359 | G63: -1.6249631 | H63: -1.9499557
A64: 3.C - Aggregate sources and non-CO2 emissions sources on land | B64: =+B27 | C64: =+C27 | D64: =+D27/1000 | E64: =+E27 | F64: =+F27 | G64: =+G27 | H64: =+H27
...

Sheet 2017
A1: Categories | B1: total | C1: co2 | D1: ch4 | E1: n2o | F1: hfcs | G1: pfcs
A2: Total National Emissions and Removals | B2: =+'Tabla de Emisiones y Remociones'!B38 | C2: =+C3+C18+C31+C44 | D2: =+D3+D18+D31+D44 | E2: =+E3+E18+E31+E44 | F2: =+F3+F18+F31+F44 | G2: =+G3+G18+G31+G44 | H2: =+H3+H18+H31+H44
A3: 1 - Energy | B3: =+'Tabla de Emisiones y Remociones'!B39 | C3: =+C4+C13 | D3: =+D4+D13 | E3: =+E4+E13 | H3: =+SUM(C3:G3)
A4: 1.A - Fuel Combustion Activities | B4: =+'Tabla de Emisiones y Remociones'!B40 | C4: =+C5+C6+C7+C8+C11+C12 | D4: =+D5+D6+D7+D8+D11+D12 | E4: =+E5+E6+E7+E8+E11+E12
A5: 1.A.1 - Energy Industries | B5: =+'Tabla de Emisiones y Remociones'!B41 | C5: =+B5*0.997544526 | D5: =+B5*0.001565661 | E5: =+B5*0.000889813
A6: 1.A.1 - Electricity and Heat Generation | B6: =+B$5*0.7 | C6: =+C$5*0.7 | D6: =+D$5*0.7 | E6: =+E$5*0.7
A7: 1.A.1 - Fuel Production | B7: =+B$5*0.3 | C7: =+C$5*0.3 | D7: =+D$5*0.3 | E7: =+E$5*0.3
A8: 1.A.2 - Manufacturing Industries and Construction | B8: =+'Tabla de Emisiones y Remociones'!B42 | C8: =+B8*0.997804185 | D8: =+B8*0.000829605 | E8: =+B8*0.00136621
A9: 1.A.2.a - Iron and Steel | B9: =+B8*0.63 | C9: =+C8*0.63 | D9: =+D8*0.63 | E9: =+E8*0.63
A10: 1.A.2.f - Cement (Energy) | B10: =+B8*0.37 | C10: =+C8*0.37 | D10: =+D8*0.37 | E10: =+E8*0.37
A11: 1.A.3 - Transport | B11: =+'Tabla de Emisiones y Remociones'!B43 | C11: =+B11*0.980386029 | D11: =+B11*0.010583264 | E11: =+B11*0.009030706
A12: 1.A.4 - Other Sectors | B12: =+'Tabla de Emisiones y Remociones'!B44 | C12: =+B12*0.930398755 | D12: =+B12*0.062442227 | E12: =+B12*0.007159018
A13: 1.B - Fugitive emissions from fuels | B13: =+'Tabla de Emisiones y Remociones'!B45 | C13: =SUM(C14:C16) | D13: =SUM(D14:D16)
A14: 1.B - Fugitive emissions from fuels - Fugitive | B14: =B13*0.188 | C14: =B14*0.2 | D14: =B14*0.8
A15: 1.B - Fugitive emissions from fuels - Venting | B15: =B13*0.58 | C15: =B15*0.3 | D15: =+B15*0.7
A16: 1.B - Fugitive emissions from fuels - Flaring | B16: =B13*0.232 | C16: =B16*0.5 | D16: =B16*0.5
A17: 1.C - Carbon dioxide Transport and Storage | B17: =+'Tabla de Emisiones y Remociones'!B46 | C17: 0 | D17: 0 | E17: 0 | F17: 0 | G17: 0 | H17: 0
A18: 2 - Industrial Processes and Product Use | B18: =+'Tabla de Emisiones y Remociones'!B47 | C18: =+C19+C23+C26+C28+C29 | D18: =+D19+D23+D26+D28+D29 | E18: =+E19+E23+E26+E28+E29 | F18: =+F19+F23+F26+F28+F29 | H18: =+SUM(C18:G18)
A19: 2.A - Mineral Industry | B19: =+'Tabla de Emisiones y Remociones'!B48 | C19: =+C20+C21
A20: 2.A.1 - Cement production | B20: =+'Tabla de Emisiones y Remociones'!B49 | C20: =+B20*1
A21: 2.A.2 - Lime production | B21: =+'Tabla de Emisiones y Remociones'!B50 | C21: =+B21*1
A22: 2.A.3 - Glass production | B22: 0 | C22: 0
A23: 2.B - Chemical Industry | B23: =+'Tabla de Emisiones y Remociones'!B51 | C23: =+B23*0.35429321 | D23: =+B23*0.000491157 | E23: =+B23*0.051078759 | F23: =+B23*0.594136874
A24: 2.B.1 - Ammonia Production | B24: =+'Tabla de Emisiones y Remociones'!B52 | C24: =+B24*0.35429321 | D24: =+B24*0.000491157 | E24: =+B24*0.051078759 | F24: =+B24*0.594136874
A25: 2.B.8 - Petrochemical and Carbon Black Production | B25: =+'Tabla de Emisiones y Remociones'!B53 | C25: =+B25*0.35429321 | D25: =+B25*0.000491157 | E25: =+B25*0.051078759 | F25: =+B25*0.594136874
A26: 2.C - Metal Industry | B26: =+'Tabla de Emisiones y Remociones'!B54 | C26: =+C27 | D26: =+D27
A27: 2.C.1 - Iron and Steel Production | B27: =+'Tabla de Emisiones y Remociones'!B55 | C27: =+B27*0.98 | D27: =+B27*0.02
A28: 2.D - Non-Energy Products from Fuels and Solvent Use | B28: =+'Tabla de Emisiones y Remociones'!B56 | C28: =+B28
A29: 2.F - Product Uses as Substitutes for Ozone Depleting Substances | B29: =+'Tabla de Emisiones y Remociones'!B57 | F29: =+F30 | G29: =+G30
A30: 2.F.1 - Refrigeration and Air Conditioning | B30: =+'Tabla de Emisiones y Remociones'!B58 | F30: =+B30/2 | G30: =+B30/2
A31: 3 - Agriculture, Forestry, and Other Land Use | B31: =+'Tabla de Emisiones y Remociones'!B59 | C31: =+SUM(C32+C37) | D31: =+SUM(D32+D37) | E31: =+SUM(E32+E37) | H31: =+SUM(C31:G31)
A32: 3.A - Livestock | B32: =+'Tabla de Emisiones y Remociones'!B60 | D32: =+D33+D34 | E32: =+E33+E34
A33: 3.A.1 - Enteric Fermentation | B33: =+'Tabla de Emisiones y Remociones'!B61 | D33: =+B33*0.996032041 | E33: =+B33*0.003967959
A34: 3.A.2 - Manure Management | B34: =+'Tabla de Emisiones y Remociones'!B62 | D34: =+B34
A35: 3.B - Land | B35: =+B36 | C35: =+C36
A36: 3.B.1 - Forest land | B36: =+'Tabla de Emisiones y Remociones'!B63 | C36: =+B36
A37: 3.C - Aggregate sources and non-CO2 emissions sources on land | B37: =+'Tabla de Emisiones y Remociones'!B64 | C37: =+SUM(C38:C43) | D37: =+SUM(D38:D43) | E37: =+SUM(E38:E43)
A38: 3.C.1 - Burning | B38: =+'Tabla de Emisiones y Remociones'!B65 | D38: =+B38*0.996032041 | E38: =+B38*0.003967959
A39: 3.C.2 - Liming | B39: =+'Tabla de Emisiones y Remociones'!B66 | C39: 0 | D39: 0 | E39: 0
A40: 3.C.3 - Urea application | B40: =+'Tabla de Emisiones y Remociones'!B67 | C40: =+B40
...

Sheet 2018
A1: Categories | B1: total | C1: co2 | D1: ch4 | E1: n2o | F1: hfcs | G1: pfcs
A2: Total National Emissions and Removals | B2: =+'Tabla de Emisiones y Remociones'!C38 | C2: =+C3+C18+C31+C44 | D2: =+D3+D18+D31+D44 | E2: =+E3+E18+E31+E44 | F2: =+F3+F18+F31+F44 | G2: =+G3+G18+G31+G44 | H2: =+H3+H18+H31+H44
A3: 1 - Energy | B3: =+'Tabla de Emisiones y Remociones'!C39 | C3: =+C4+C13 | D3: =+D4+D13 | E3: =+E4+E13 | H3: =+SUM(C3:G3)
A4: 1.A - Fuel Combustion Activities | B4: =+'Tabla de Emisiones y Remociones'!C40 | C4: =+C5+C6+C7+C8+C11+C12 | D4: =+D5+D6+D7+D8+D11+D12 | E4: =+E5+E6+E7+E8+E11+E12
A5: 1.A.1 - Energy Industries | B5: =+'Tabla de Emisiones y Remociones'!C41 | C5: =+B5*0.997544526 | D5: =+B5*0.001565661 | E5: =+B5*0.000889813
A6: 1.A.1 - Electricity and Heat Generation | B6: =+B$5*0.7 | C6: =+C$5*0.7 | D6: =+D$5*0.7 | E6: =+E$5*0.7
A7: 1.A.1 - Fuel Production | B7: =+B$5*0.3 | C7: =+C$5*0.3 | D7: =+D$5*0.3 | E7: =+E$5*0.3
A8: 1.A.2 - Manufacturing Industries and Construction | B8: =+'Tabla de Emisiones y Remociones'!C42 | C8: =+B8*0.997804185 | D8: =+B8*0.000829605 | E8: =+B8*0.00136621
A9: 1.A.2.a - Iron and Steel | B9: =+B8*0.63 | C9: =+C8*0.63 | D9: =+D8*0.63 | E9: =+E8*0.63
A10: 1.A.2.f - Cement (Energy) | B10: =+B8*0.37 | C10: =+C8*0.37 | D10: =+D8*0.37 | E10: =+E8*0.37
A11: 1.A.3 - Transport | B11: =+'Tabla de Emisiones y Remociones'!C43 | C11: =+B11*0.980386029 | D11: =+B11*0.010583264 | E11: =+B11*0.009030706
A12: 1.A.4 - Other Sectors | B12: =+'Tabla de Emisiones y Remociones'!C44 | C12: =+B12*0.930398755 | D12: =+B12*0.062442227 | E12: =+B12*0.007159018
A13: 1.B - Fugitive emissions from fuels | B13: =+'Tabla de Emisiones y Remociones'!C45 | C13: =SUM(C14:C16) | D13: =SUM(D14:D16)
A14: 1.B - Fugitive emissions from fuels - Fugitive | B14: =B13*0.188 | C14: =B14*0.2 | D14: =B14*0.8
A15: 1.B - Fugitive emissions from fuels - Venting | B15: =B13*0.58 | C15: =B15*0.3 | D15: =+B15*0.7
A16: 1.B - Fugitive emissions from fuels - Flaring | B16: =B13*0.232 | C16: =B16*0.5 | D16: =B16*0.5
A17: 1.C - Carbon dioxide Transport and Storage | B17: =+'Tabla de Emisiones y Remociones'!C46 | C17: 0 | D17: 0 | E17: 0 | F17: 0 | G17: 0 | H17: 0
A18: 2 - Industrial Processes and Product Use | B18: =+'Tabla de Emisiones y Remociones'!C47 | C18: =+C19+C23+C26+C28+C29 | D18: =+D19+D23+D26+D28+D29 | E18: =+E19+E23+E26+E28+E29 | F18: =+F19+F23+F26+F28+F29 | H18: =+SUM(C18:G18)
A19: 2.A - Mineral Industry | B19: =+'Tabla de Emisiones y Remociones'!C48 | C19: =+C20+C21
A20: 2.A.1 - Cement production | B20: =+'Tabla de Emisiones y Remociones'!C49 | C20: =+B20*1
A21: 2.A.2 - Lime production | B21: =+'Tabla de Emisiones y Remociones'!C50 | C21: =+B21*1
A22: 2.A.3 - Glass production | B22: 0 | C22: 0
A23: 2.B - Chemical Industry | B23: =+'Tabla de Emisiones y Remociones'!C51 | C23: =+B23*0.35429321 | D23: =+B23*0.000491157 | E23: =+B23*0.051078759 | F23: =+B23*0.594136874
A24: 2.B.1 - Ammonia Production | B24: =+'Tabla de Emisiones y Remociones'!C52 | C24: =+B24*0.35429321 | D24: =+B24*0.000491157 | E24: =+B24*0.051078759 | F24: =+B24*0.594136874
A25: 2.B.8 - Petrochemical and Carbon Black Production | B25: =+'Tabla de Emisiones y Remociones'!C53 | C25: =+B25*0.35429321 | D25: =+B25*0.000491157 | E25: =+B25*0.051078759 | F25: =+B25*0.594136874
A26: 2.C - Metal Industry | B26: =+'Tabla de Emisiones y Remociones'!C54 | C26: =+C27 | D26: =+D27
A27: 2.C.1 - Iron and Steel Production | B27: =+'Tabla de Emisiones y Remociones'!C55 | C27: =+B27*0.98 | D27: =+B27*0.02
A28: 2.D - Non-Energy Products from Fuels and Solvent Use | B28: =+'Tabla de Emisiones y Remociones'!C56 | C28: =+B28
A29: 2.F - Product Uses as Substitutes for Ozone Depleting Substances | B29: =+'Tabla de Emisiones y Remociones'!C57 | F29: =+F30 | G29: =+G30
A30: 2.F.1 - Refrigeration and Air Conditioning | B30: =+'Tabla de Emisiones y Remociones'!C58 | F30: =+B30/2 | G30: =+B30/2
A31: 3 - Agriculture, Forestry, and Other Land Use | B31: =+'Tabla de Emisiones y Remociones'!C59 | C31: =+SUM(C32+C37) | D31: =+SUM(D32+D37) | E31: =+SUM(E32+E37) | H31: =+SUM(C31:G31)
A32: 3.A - Livestock | B32: =+'Tabla de Emisiones y Remociones'!C60 | D32: =+D33+D34 | E32: =+E33+E34
A33: 3.A.1 - Enteric Fermentation | B33: =+'Tabla de Emisiones y Remociones'!C61 | D33: =+B33*0.996032041 | E33: =+B33*0.003967959
A34: 3.A.2 - Manure Management | B34: =+'Tabla de Emisiones y Remociones'!C62 | D34: =+B34
A35: 3.B - Land | B35: =+B36 | C35: =+C36
A36: 3.B.1 - Forest land | B36: =+'Tabla de Emisiones y Remociones'!C63 | C36: =+B36
A37: 3.C - Aggregate sources and non-CO2 emissions sources on land | B37: =+'Tabla de Emisiones y Remociones'!C64 | C37: =+SUM(C38:C43) | D37: =+SUM(D38:D43) | E37: =+SUM(E38:E43)
A38: 3.C.1 - Burning | B38: =+'Tabla de Emisiones y Remociones'!C65 | D38: =+B38*0.996032041 | E38: =+B38*0.003967959
A39: 3.C.2 - Liming | B39: =+'Tabla de Emisiones y Remociones'!C66 | C39: 0 | D39: 0 | E39: 0
A40: 3.C.3 - Urea application | B40: =+'Tabla de Emisiones y Remociones'!C67 | C40: =+B40
...

Sheet 2019
A1: Categories | B1: total | C1: co2 | D1: ch4 | E1: n2o | F1: hfcs | G1: pfcs
A2: Total National Emissions and Removals | B2: =+'Tabla de Emisiones y Remociones'!D38 | C2: =+C3+C18+C31+C44 | D2: =+D3+D18+D31+D44 | E2: =+E3+E18+E31+E44 | F2: =+F3+F18+F31+F44 | G2: =+G3+G18+G31+G44 | H2: =+H3+H18+H31+H44
A3: 1 - Energy | B3: =+'Tabla de Emisiones y Remociones'!D39 | C3: =+C4+C13 | D3: =+D4+D13 | E3: =+E4+E13 | H3: =+SUM(C3:G3)
A4: 1.A - Fuel Combustion Activities | B4: =+'Tabla de Emisiones y Remociones'!D40 | C4: =+C5+C6+C7+C8+C11+C12 | D4: =+D5+D6+D7+D8+D11+D12 | E4: =+E5+E6+E7+E8+E11+E12
A5: 1.A.1 - Energy Industries | B5: =+'Tabla de Emisiones y Remociones'!D41 | C5: =+B5*0.997544526 | D5: =+B5*0.001565661 | E5: =+B5*0.000889813
A6: 1.A.1 - Electricity and Heat Generation | B6: =+B$5*0.7 | C6: =+C$5*0.7 | D6: =+D$5*0.7 | E6: =+E$5*0.7
A7: 1.A.1 - Fuel Production | B7: =+B$5*0.3 | C7: =+C$5*0.3 | D7: =+D$5*0.3 | E7: =+E$5*0.3
A8: 1.A.2 - Manufacturing Industries and Construction | B8: =+'Tabla de Emisiones y Remociones'!D42 | C8: =+B8*0.997804185 | D8: =+B8*0.000829605 | E8: =+B8*0.00136621
A9: 1.A.2.a - Iron and Steel | B9: =+B8*0.63 | C9: =+C8*0.63 | D9: =+D8*0.63 | E9: =+E8*0.63
A10: 1.A.2.f - Cement (Energy) | B10: =+B8*0.37 | C10: =+C8*0.37 | D10: =+D8*0.37 | E10: =+E8*0.37
A11: 1.A.3 - Transport | B11: =+'Tabla de Emisiones y Remociones'!D43 | C11: =+B11*0.980386029 | D11: =+B11*0.010583264 | E11: =+B11*0.009030706
A12: 1.A.4 - Other Sectors | B12: =+'Tabla de Emisiones y Remociones'!D44 | C12: =+B12*0.930398755 | D12: =+B12*0.062442227 | E12: =+B12*0.007159018
A13: 1.B - Fugitive emissions from fuels | B13: =+'Tabla de Emisiones y Remociones'!D45 | C13: =SUM(C14:C16) | D13: =SUM(D14:D16)
A14: 1.B - Fugitive emissions from fuels - Fugitive | B14: =B13*0.188 | C14: =B14*0.2 | D14: =B14*0.8
A15: 1.B - Fugitive emissions from fuels - Venting | B15: =B13*0.58 | C15: =B15*0.3 | D15: =+B15*0.7
A16: 1.B - Fugitive emissions from fuels - Flaring | B16: =B13*0.232 | C16: =B16*0.5 | D16: =B16*0.5
A17: 1.C - Carbon dioxide Transport and Storage | B17: =+'Tabla de Emisiones y Remociones'!D46 | C17: 0 | D17: 0 | E17: 0 | F17: 0 | G17: 0 | H17: 0
A18: 2 - Industrial Processes and Product Use | B18: =+'Tabla de Emisiones y Remociones'!D47 | C18: =+C19+C23+C26+C28+C29 | D18: =+D19+D23+D26+D28+D29 | E18: =+E19+E23+E26+E28+E29 | F18: =+F19+F23+F26+F28+F29 | H18: =+SUM(C18:G18)
A19: 2.A - Mineral Industry | B19: =+'Tabla de Emisiones y Remociones'!D48 | C19: =+C20+C21
A20: 2.A.1 - Cement production | B20: =+'Tabla de Emisiones y Remociones'!D49 | C20: =+B20*1
A21: 2.A.2 - Lime production | B21: =+'Tabla de Emisiones y Remociones'!D50 | C21: =+B21*1
A22: 2.A.3 - Glass production | B22: 0 | C22: 0
A23: 2.B - Chemical Industry | B23: =+'Tabla de Emisiones y Remociones'!D51 | C23: =+B23*0.35429321 | D23: =+B23*0.000491157 | E23: =+B23*0.051078759 | F23: =+B23*0.594136874
A24: 2.B.1 - Ammonia Production | B24: =+'Tabla de Emisiones y Remociones'!D52 | C24: =+B24*0.35429321 | D24: =+B24*0.000491157 | E24: =+B24*0.051078759 | F24: =+B24*0.594136874
A25: 2.B.8 - Petrochemical and Carbon Black Production | B25: =+'Tabla de Emisiones y Remociones'!D53 | C25: =+B25*0.35429321 | D25: =+B25*0.000491157 | E25: =+B25*0.051078759 | F25: =+B25*0.594136874
A26: 2.C - Metal Industry | B26: =+'Tabla de Emisiones y Remociones'!D54 | C26: =+C27 | D26: =+D27
A27: 2.C.1 - Iron and Steel Production | B27: =+'Tabla de Emisiones y Remociones'!D55 | C27: =+B27*0.98 | D27: =+B27*0.02
A28: 2.D - Non-Energy Products from Fuels and Solvent Use | B28: =+'Tabla de Emisiones y Remociones'!D56 | C28: =+B28
A29: 2.F - Product Uses as Substitutes for Ozone Depleting Substances | B29: =+'Tabla de Emisiones y Remociones'!D57 | F29: =+F30 | G29: =+G30
A30: 2.F.1 - Refrigeration and Air Conditioning | B30: =+'Tabla de Emisiones y Remociones'!D58 | F30: =+B30/2 | G30: =+B30/2
A31: 3 - Agriculture, Forestry, and Other Land Use | B31: =+'Tabla de Emisiones y Remociones'!D59 | C31: =+SUM(C32+C37) | D31: =+SUM(D32+D37) | E31: =+SUM(E32+E37) | H31: =+SUM(C31:G31)
A32: 3.A - Livestock | B32: =+'Tabla de Emisiones y Remociones'!D60 | D32: =+D33+D34 | E32: =+E33+E34
A33: 3.A.1 - Enteric Fermentation | B33: =+'Tabla de Emisiones y Remociones'!D61 | D33: =+B33*0.996032041 | E33: =+B33*0.003967959
A34: 3.A.2 - Manure Management | B34: =+'Tabla de Emisiones y Remociones'!D62 | D34: =+B34
A35: 3.B - Land | B35: =+B36 | C35: =+C36
A36: 3.B.1 - Forest land | B36: =+'Tabla de Emisiones y Remociones'!D63 | C36: =+B36
A37: 3.C - Aggregate sources and non-CO2 emissions sources on land | B37: =+'Tabla de Emisiones y Remociones'!D64 | C37: =+SUM(C38:C43) | D37: =+SUM(D38:D43) | E37: =+SUM(E38:E43)
A38: 3.C.1 - Burning | B38: =+'Tabla de Emisiones y Remociones'!D65 | D38: =+B38*0.996032041 | E38: =+B38*0.003967959
A39: 3.C.2 - Liming | B39: =+'Tabla de Emisiones y Remociones'!D66 | C39: 0 | D39: 0 | E39: 0
A40: 3.C.3 - Urea application | B40: =+'Tabla de Emisiones y Remociones'!D67 | C40: =+B40
...

Sheet 2020
A1: Categories | B1: total | C1: co2 | D1: ch4 | E1: n2o | F1: hfcs | G1: pfcs
A2: Total National Emissions and Removals | B2: =+'Tabla de Emisiones y Remociones'!E38 | C2: =+C3+C18+C31+C44 | D2: =+D3+D18+D31+D44 | E2: =+E3+E18+E31+E44 | F2: =+F3+F18+F31+F44 | G2: =+G3+G18+G31+G44 | H2: =+H3+H18+H31+H44
A3: 1 - Energy | B3: =+'Tabla de Emisiones y Remociones'!E39 | C3: =+C4+C13 | D3: =+D4+D13 | E3: =+E4+E13 | H3: =+SUM(C3:G3)
A4: 1.A - Fuel Combustion Activities | B4: =+'Tabla de Emisiones y Remociones'!E40 | C4: =+C5+C6+C7+C8+C11+C12 | D4: =+D5+D6+D7+D8+D11+D12 | E4: =+E5+E6+E7+E8+E11+E12
A5: 1.A.1 - Energy Industries | B5: =+'Tabla de Emisiones y Remociones'!E41 | C5: =+B5*0.997544526 | D5: =+B5*0.001565661 | E5: =+B5*0.000889813
A6: 1.A.1 - Electricity and Heat Generation | B6: =+B$5*0.7 | C6: =+C$5*0.7 | D6: =+D$5*0.7 | E6: =+E$5*0.7
A7: 1.A.1 - Fuel Production | B7: =+B$5*0.3 | C7: =+C$5*0.3 | D7: =+D$5*0.3 | E7: =+E$5*0.3
A8: 1.A.2 - Manufacturing Industries and Construction | B8: =+'Tabla de Emisiones y Remociones'!E42 | C8: =+B8*0.997804185 | D8: =+B8*0.000829605 | E8: =+B8*0.00136621
A9: 1.A.2.a - Iron and Steel | B9: =+B8*0.63 | C9: =+C8*0.63 | D9: =+D8*0.63 | E9: =+E8*0.63
A10: 1.A.2.f - Cement (Energy) | B10: =+B8*0.37 | C10: =+C8*0.37 | D10: =+D8*0.37 | E10: =+E8*0.37
A11: 1.A.3 - Transport | B11: =+'Tabla de Emisiones y Remociones'!E43 | C11: =+B11*0.980386029 | D11: =+B11*0.010583264 | E11: =+B11*0.009030706
A12: 1.A.4 - Other Sectors | B12: =+'Tabla de Emisiones y Remociones'!E44 | C12: =+B12*0.930398755 | D12: =+B12*0.062442227 | E12: =+B12*0.007159018
A13: 1.B - Fugitive emissions from fuels | B13: =+'Tabla de Emisiones y Remociones'!E45 | C13: =SUM(C14:C16) | D13: =SUM(D14:D16)
A14: 1.B - Fugitive emissions from fuels - Fugitive | B14: =B13*0.188 | C14: =B14*0.2 | D14: =B14*0.8
A15: 1.B - Fugitive emissions from fuels - Venting | B15: =B13*0.58 | C15: =B15*0.3 | D15: =+B15*0.7
A16: 1.B - Fugitive emissions from fuels - Flaring | B16: =B13*0.232 | C16: =B16*0.5 | D16: =B16*0.5
A17: 1.C - Carbon dioxide Transport and Storage | B17: =+'Tabla de Emisiones y Remociones'!E46 | C17: 0 | D17: 0 | E17: 0 | F17: 0 | G17: 0 | H17: 0
A18: 2 - Industrial Processes and Product Use | B18: =+'Tabla de Emisiones y Remociones'!E47 | C18: =+C19+C23+C26+C28+C29 | D18: =+D19+D23+D26+D28+D29 | E18: =+E19+E23+E26+E28+E29 | F18: =+F19+F23+F26+F28+F29 | H18: =+SUM(C18:G18)
A19: 2.A - Mineral Industry | B19: =+'Tabla de Emisiones y Remociones'!E48 | C19: =+C20+C21
A20: 2.A.1 - Cement production | B20: =+'Tabla de Emisiones y Remociones'!E49 | C20: =+B20*1
A21: 2.A.2 - Lime production | B21: =+'Tabla de Emisiones y Remociones'!E50 | C21: =+B21*1
A22: 2.A.3 - Glass production | B22: 0 | C22: 0
A23: 2.B - Chemical Industry | B23: =+'Tabla de Emisiones y Remociones'!E51 | C23: =+B23*0.35429321 | D23: =+B23*0.000491157 | E23: =+B23*0.051078759 | F23: =+B23*0.594136874
A24: 2.B.1 - Ammonia Production | B24: =+'Tabla de Emisiones y Remociones'!E52 | C24: =+B24*0.35429321 | D24: =+B24*0.000491157 | E24: =+B24*0.051078759 | F24: =+B24*0.594136874
A25: 2.B.8 - Petrochemical and Carbon Black Production | B25: =+'Tabla de Emisiones y Remociones'!E53 | C25: =+B25*0.35429321 | D25: =+B25*0.000491157 | E25: =+B25*0.051078759 | F25: =+B25*0.594136874
A26: 2.C - Metal Industry | B26: =+'Tabla de Emisiones y Remociones'!E54 | C26: =+C27 | D26: =+D27
A27: 2.C.1 - Iron and Steel Production | B27: =+'Tabla de Emisiones y Remociones'!E55 | C27: =+B27*0.98 | D27: =+B27*0.02
A28: 2.D - Non-Energy Products from Fuels and Solvent Use | B28: =+'Tabla de Emisiones y Remociones'!E56 | C28: =+B28
A29: 2.F - Product Uses as Substitutes for Ozone Depleting Substances | B29: =+'Tabla de Emisiones y Remociones'!E57 | F29: =+F30 | G29: =+G30
A30: 2.F.1 - Refrigeration and Air Conditioning | B30: =+'Tabla de Emisiones y Remociones'!E58 | F30: =+B30/2 | G30: =+B30/2
A31: 3 - Agriculture, Forestry, and Other Land Use | B31: =+'Tabla de Emisiones y Remociones'!E59 | C31: =+SUM(C32+C37) | D31: =+SUM(D32+D37) | E31: =+SUM(E32+E37) | H31: =+SUM(C31:G31)
A32: 3.A - Livestock | B32: =+'Tabla de Emisiones y Remociones'!E60 | D32: =+D33+D34 | E32: =+E33+E34
A33: 3.A.1 - Enteric Fermentation | B33: =+'Tabla de Emisiones y Remociones'!E61 | D33: =+B33*0.996032041 | E33: =+B33*0.003967959
A34: 3.A.2 - Manure Management | B34: =+'Tabla de Emisiones y Remociones'!E62 | D34: =+B34
A35: 3.B - Land | B35: =+B36 | C35: =+C36
A36: 3.B.1 - Forest land | B36: =+'Tabla de Emisiones y Remociones'!E63 | C36: =+B36
A37: 3.C - Aggregate sources and non-CO2 emissions sources on land | B37: =+'Tabla de Emisiones y Remociones'!E64 | C37: =+SUM(C38:C43) | D37: =+SUM(D38:D43) | E37: =+SUM(E38:E43)
A38: 3.C.1 - Burning | B38: =+'Tabla de Emisiones y Remociones'!E65 | D38: =+B38*0.996032041 | E38: =+B38*0.003967959
A39: 3.C.2 - Liming | B39: =+'Tabla de Emisiones y Remociones'!E66 | C39: 0 | D39: 0 | E39: 0
A40: 3.C.3 - Urea application | B40: =+'Tabla de Emisiones y Remociones'!E67 | C40: =+B40
...

Sheet 2021
A1: Categories | B1: total | C1: co2 | D1: ch4 | E1: n2o | F1: hfcs | G1: pfcs
A2: Total National Emissions and Removals | B2: =+'Tabla de Emisiones y Remociones'!F38 | C2: =+C3+C18+C31+C44 | D2: =+D3+D18+D31+D44 | E2: =+E3+E18+E31+E44 | F2: =+F3+F18+F31+F44 | G2: =+G3+G18+G31+G44 | H2: =+H3+H18+H31+H44
A3: 1 - Energy | B3: =+'Tabla de Emisiones y Remociones'!F39 | C3: =+C4+C13 | D3: =+D4+D13 | E3: =+E4+E13 | H3: =+SUM(C3:G3)
A4: 1.A - Fuel Combustion Activities | B4: =+'Tabla de Emisiones y Remociones'!F40 | C4: =+C5+C6+C7+C8+C11+C12 | D4: =+D5+D6+D7+D8+D11+D12 | E4: =+E5+E6+E7+E8+E11+E12
A5: 1.A.1 - Energy Industries | B5: =+'Tabla de Emisiones y Remociones'!F41 | C5: =+B5*0.997544526 | D5: =+B5*0.001565661 | E5: =+B5*0.000889813
A6: 1.A.1 - Electricity and Heat Generation | B6: =+B$5*0.7 | C6: =+C$5*0.7 | D6: =+D$5*0.7 | E6: =+E$5*0.7
A7: 1.A.1 - Fuel Production | B7: =+B$5*0.3 | C7: =+C$5*0.3 | D7: =+D$5*0.3 | E7: =+E$5*0.3
A8: 1.A.2 - Manufacturing Industries and Construction | B8: =+'Tabla de Emisiones y Remociones'!F42 | C8: =+B8*0.997804185 | D8: =+B8*0.000829605 | E8: =+B8*0.00136621
A9: 1.A.2.a - Iron and Steel | B9: =+B8*0.63 | C9: =+C8*0.63 | D9: =+D8*0.63 | E9: =+E8*0.63
A10: 1.A.2.f - Cement (Energy) | B10: =+B8*0.37 | C10: =+C8*0.37 | D10: =+D8*0.37 | E10: =+E8*0.37
A11: 1.A.3 - Transport | B11: =+'Tabla de Emisiones y Remociones'!F43 | C11: =+B11*0.980386029 | D11: =+B11*0.010583264 | E11: =+B11*0.009030706
A12: 1.A.4 - Other Sectors | B12: =+'Tabla de Emisiones y Remociones'!F44 | C12: =+B12*0.930398755 | D12: =+B12*0.062442227 | E12: =+B12*0.007159018
A13: 1.B - Fugitive emissions from fuels | B13: =+'Tabla de Emisiones y Remociones'!F45 | C13: =SUM(C14:C16) | D13: =SUM(D14:D16)
A14: 1.B - Fugitive emissions from fuels - Fugitive | B14: =B13*0.188 | C14: =B14*0.2 | D14: =B14*0.8
A15: 1.B - Fugitive emissions from fuels - Venting | B15: =B13*0.58 | C15: =B15*0.3 | D15: =+B15*0.7
A16: 1.B - Fugitive emissions from fuels - Flaring | B16: =B13*0.232 | C16: =B16*0.5 | D16: =B16*0.5
A17: 1.C - Carbon dioxide Transport and Storage | B17: =+'Tabla de Emisiones y Remociones'!F46 | C17: 0 | D17: 0 | E17: 0 | F17: 0 | G17: 0 | H17: 0
A18: 2 - Industrial Processes and Product Use | B18: =+'Tabla de Emisiones y Remociones'!F47 | C18: =+C19+C23+C26+C28+C29 | D18: =+D19+D23+D26+D28+D29 | E18: =+E19+E23+E26+E28+E29 | F18: =+F19+F23+F26+F28+F29 | H18: =+SUM(C18:G18)
A19: 2.A - Mineral Industry | B19: =+'Tabla de Emisiones y Remociones'!F48 | C19: =+C20+C21
A20: 2.A.1 - Cement production | B20: =+'Tabla de Emisiones y Remociones'!F49 | C20: =+B20*1
A21: 2.A.2 - Lime production | B21: =+'Tabla de Emisiones y Remociones'!F50 | C21: =+B21*1
A22: 2.A.3 - Glass production | B22: 0 | C22: 0
A23: 2.B - Chemical Industry | B23: =+'Tabla de Emisiones y Remociones'!F51 | C23: =+B23*0.35429321 | D23: =+B23*0.000491157 | E23: =+B23*0.051078759 | F23: =+B23*0.594136874
A24: 2.B.1 - Ammonia Production | B24: =+'Tabla de Emisiones y Remociones'!F52 | C24: =+B24*0.35429321 | D24: =+B24*0.000491157 | E24: =+B24*0.051078759 | F24: =+B24*0.594136874
A25: 2.B.8 - Petrochemical and Carbon Black Production | B25: =+'Tabla de Emisiones y Remociones'!F53 | C25: =+B25*0.35429321 | D25: =+B25*0.000491157 | E25: =+B25*0.051078759 | F25: =+B25*0.594136874
A26: 2.C - Metal Industry | B26: =+'Tabla de Emisiones y Remociones'!F54 | C26: =+C27 | D26: =+D27
A27: 2.C.1 - Iron and Steel Production | B27: =+'Tabla de Emisiones y Remociones'!F55 | C27: =+B27*0.98 | D27: =+B27*0.02
A28: 2.D - Non-Energy Products from Fuels and Solvent Use | B28: =+'Tabla de Emisiones y Remociones'!F56 | C28: =+B28
A29: 2.F - Product Uses as Substitutes for Ozone Depleting Substances | B29: =+'Tabla de Emisiones y Remociones'!F57 | F29: =+F30 | G29: =+G30
A30: 2.F.1 - Refrigeration and Air Conditioning | B30: =+'Tabla de Emisiones y Remociones'!F58 | F30: =+B30/2 | G30: =+B30/2
A31: 3 - Agriculture, Forestry, and Other Land Use | B31: =+'Tabla de Emisiones y Remociones'!F59 | C31: =+SUM(C32+C37) | D31: =+SUM(D32+D37) | E31: =+SUM(E32+E37) | H31: =+SUM(C31:G31)
A32: 3.A - Livestock | B32: =+'Tabla de Emisiones y Remociones'!F60 | D32: =+D33+D34 | E32: =+E33+E34
A33: 3.A.1 - Enteric Fermentation | B33: =+'Tabla de Emisiones y Remociones'!F61 | D33: =+B33*0.996032041 | E33: =+B33*0.003967959
A34: 3.A.2 - Manure Management | B34: =+'Tabla de Emisiones y Remociones'!F62 | D34: =+B34
A35: 3.B - Land | B35: =+B36 | C35: =+C36
A36: 3.B.1 - Forest land | B36: =+'Tabla de Emisiones y Remociones'!F63 | C36: =+B36
A37: 3.C - Aggregate sources and non-CO2 emissions sources on land | B37: =+'Tabla de Emisiones y Remociones'!F64 | C37: =+SUM(C38:C43) | D37: =+SUM(D38:D43) | E37: =+SUM(E38:E43)
A38: 3.C.1 - Burning | B38: =+'Tabla de Emisiones y Remociones'!F65 | D38: =+B38*0.996032041 | E38: =+B38*0.003967959
A39: 3.C.2 - Liming | B39: =+'Tabla de Emisiones y Remociones'!F66 | C39: 0 | D39: 0 | E39: 0
A40: 3.C.3 - Urea application | B40: =+'Tabla de Emisiones y Remociones'!F67 | C40: =+B40
...

Sheet 2022
A1: Categories | B1: total | C1: co2 | D1: ch4 | E1: n2o | F1: hfcs | G1: pfcs
A2: Total National Emissions and Removals | B2: =+'Tabla de Emisiones y Remociones'!G38 | C2: =+C3+C18+C31+C44 | D2: =+D3+D18+D31+D44 | E2: =+E3+E18+E31+E44 | F2: =+F3+F18+F31+F44 | G2: =+G3+G18+G31+G44 | H2: =+H3+H18+H31+H44
A3: 1 - Energy | B3: =+'Tabla de Emisiones y Remociones'!G39 | C3: =+C4+C13 | D3: =+D4+D13 | E3: =+E4+E13 | H3: =+SUM(C3:G3)
A4: 1.A - Fuel Combustion Activities | B4: =+'Tabla de Emisiones y Remociones'!G40 | C4: =+C5+C6+C7+C8+C11+C12 | D4: =+D5+D6+D7+D8+D11+D12 | E4: =+E5+E6+E7+E8+E11+E12
A5: 1.A.1 - Energy Industries | B5: =+'Tabla de Emisiones y Remociones'!G41 | C5: =+B5*0.997544526 | D5: =+B5*0.001565661 | E5: =+B5*0.000889813
A6: 1.A.1 - Electricity and Heat Generation | B6: =+B$5*0.7 | C6: =+C$5*0.7 | D6: =+D$5*0.7 | E6: =+E$5*0.7
A7: 1.A.1 - Fuel Production | B7: =+B$5*0.3 | C7: =+C$5*0.3 | D7: =+D$5*0.3 | E7: =+E$5*0.3
A8: 1.A.2 - Manufacturing Industries and Construction | B8: =+'Tabla de Emisiones y Remociones'!G42 | C8: =+B8*0.997804185 | D8: =+B8*0.000829605 | E8: =+B8*0.00136621
A9: 1.A.2.a - Iron and Steel | B9: =+B8*0.63 | C9: =+C8*0.63 | D9: =+D8*0.63 | E9: =+E8*0.63
A10: 1.A.2.f - Cement (Energy) | B10: =+B8*0.37 | C10: =+C8*0.37 | D10: =+D8*0.37 | E10: =+E8*0.37
A11: 1.A.3 - Transport | B11: =+'Tabla de Emisiones y Remociones'!G43 | C11: =+B11*0.980386029 | D11: =+B11*0.010583264 | E11: =+B11*0.009030706
A12: 1.A.4 - Other Sectors | B12: =+'Tabla de Emisiones y Remociones'!G44 | C12: =+B12*0.930398755 | D12: =+B12*0.062442227 | E12: =+B12*0.007159018
A13: 1.B - Fugitive emissions from fuels | B13: =+'Tabla de Emisiones y Remociones'!G45 | C13: =SUM(C14:C16) | D13: =SUM(D14:D16)
A14: 1.B - Fugitive emissions from fuels - Fugitive | B14: =B13*0.188 | C14: =B14*0.2 | D14: =B14*0.8
A15: 1.B - Fugitive emissions from fuels - Venting | B15: =B13*0.58 | C15: =B15*0.3 | D15: =+B15*0.7
A16: 1.B - Fugitive emissions from fuels - Flaring | B16: =B13*0.232 | C16: =B16*0.5 | D16: =B16*0.5
A17: 1.C - Carbon dioxide Transport and Storage | B17: =+'Tabla de Emisiones y Remociones'!G46 | C17: 0 | D17: 0 | E17: 0 | F17: 0 | G17: 0 | H17: 0
A18: 2 - Industrial Processes and Product Use | B18: =+'Tabla de Emisiones y Remociones'!G47 | C18: =+C19+C23+C26+C28+C29 | D18: =+D19+D23+D26+D28+D29 | E18: =+E19+E23+E26+E28+E29 | F18: =+F19+F23+F26+F28+F29 | G18: =+G29 | H18: =+SUM(C18:G18)
A19: 2.A - Mineral Industry | B19: =+'Tabla de Emisiones y Remociones'!G48 | C19: =+C20+C21
A20: 2.A.1 - Cement production | B20: =+'Tabla de Emisiones y Remociones'!G49 | C20: =+B20*1
A21: 2.A.2 - Lime production | B21: =+'Tabla de Emisiones y Remociones'!G50 | C21: =+B21*1
A22: 2.A.3 - Glass production | B22: 0 | C22: 0
A23: 2.B - Chemical Industry | B23: =+'Tabla de Emisiones y Remociones'!G51 | C23: =+B23*0.35429321 | D23: =+B23*0.000491157 | E23: =+B23*0.051078759 | F23: =+B23*0.594136874
A24: 2.B.1 - Ammonia Production | B24: =+'Tabla de Emisiones y Remociones'!G52 | C24: =+B24*0.35429321 | D24: =+B24*0.000491157 | E24: =+B24*0.051078759 | F24: =+B24*0.594136874
A25: 2.B.8 - Petrochemical and Carbon Black Production | B25: =+'Tabla de Emisiones y Remociones'!G53 | C25: =+B25*0.35429321 | D25: =+B25*0.000491157 | E25: =+B25*0.051078759 | F25: =+B25*0.594136874
A26: 2.C - Metal Industry | B26: =+'Tabla de Emisiones y Remociones'!G54 | C26: =+C27 | D26: =+D27
A27: 2.C.1 - Iron and Steel Production | B27: =+'Tabla de Emisiones y Remociones'!G55 | C27: =+B27*0.98 | D27: =+B27*0.02
A28: 2.D - Non-Energy Products from Fuels and Solvent Use | B28: =+'Tabla de Emisiones y Remociones'!G56 | C28: =+B28
A29: 2.F - Product Uses as Substitutes for Ozone Depleting Substances | B29: =+'Tabla de Emisiones y Remociones'!G57 | F29: =+F30 | G29: =+G30
A30: 2.F.1 - Refrigeration and Air Conditioning | B30: =+'Tabla de Emisiones y Remociones'!G58 | F30: =+B30/2 | G30: =+B30/2
A31: 3 - Agriculture, Forestry, and Other Land Use | B31: =+'Tabla de Emisiones y Remociones'!G59 | C31: =+SUM(C32+C37) | D31: =+SUM(D32+D37) | E31: =+SUM(E32+E37) | H31: =+SUM(C31:G31)
A32: 3.A - Livestock | B32: =+'Tabla de Emisiones y Remociones'!G60 | D32: =+D33+D34 | E32: =+E33+E34
A33: 3.A.1 - Enteric Fermentation | B33: =+'Tabla de Emisiones y Remociones'!G61 | D33: =+B33*0.996032041 | E33: =+B33*0.003967959
A34: 3.A.2 - Manure Management | B34: =+'Tabla de Emisiones y Remociones'!G62 | D34: =+B34
A35: 3.B - Land | B35: =+B36 | C35: =+C36
A36: 3.B.1 - Forest land | B36: =+'Tabla de Emisiones y Remociones'!G63 | C36: =+B36
A37: 3.C - Aggregate sources and non-CO2 emissions sources on land | B37: =+'Tabla de Emisiones y Remociones'!G64 | C37: =+SUM(C38:C43) | D37: =+SUM(D38:D43) | E37: =+SUM(E38:E43)
A38: 3.C.1 - Burning | B38: =+'Tabla de Emisiones y Remociones'!G65 | D38: =+B38*0.996032041 | E38: =+B38*0.003967959
A39: 3.C.2 - Liming | B39: =+'Tabla de Emisiones y Remociones'!G66 | C39: 0 | D39: 0 | E39: 0
A40: 3.C.3 - Urea application | B40: =+'Tabla de Emisiones y Remociones'!G67 | C40: =+B40
...

Sheet 2023
A1: Categories | B1: total | C1: co2 | D1: ch4 | E1: n2o | F1: hfcs | G1: pfcs
A2: Total National Emissions and Removals | B2: =+'Tabla de Emisiones y Remociones'!H38 | C2: =+C3+C18+C31+C44 | D2: =+D3+D18+D31+D44 | E2: =+E3+E18+E31+E44 | F2: =+F3+F18+F31+F44 | G2: =+G3+G18+G31+G44 | H2: =+H3+H18+H31+H44
A3: 1 - Energy | B3: =+'Tabla de Emisiones y Remociones'!H39 | C3: =+C4+C13 | D3: =+D4+D13 | E3: =+E4+E13 | H3: =+SUM(C3:G3)
A4: 1.A - Fuel Combustion Activities | B4: =+'Tabla de Emisiones y Remociones'!H40 | C4: =+C5+C6+C7+C8+C11+C12 | D4: =+D5+D6+D7+D8+D11+D12 | E4: =+E5+E6+E7+E8+E11+E12
A5: 1.A.1 - Energy Industries | B5: =+'Tabla de Emisiones y Remociones'!H41 | C5: =+B5*0.997544526 | D5: =+B5*0.001565661 | E5: =+B5*0.000889813
A6: 1.A.1 - Electricity and Heat Generation | B6: =+B$5*0.7 | C6: =+C$5*0.7 | D6: =+D$5*0.7 | E6: =+E$5*0.7
A7: 1.A.1 - Fuel Production | B7: =+B$5*0.3 | C7: =+C$5*0.3 | D7: =+D$5*0.3 | E7: =+E$5*0.3
A8: 1.A.2 - Manufacturing Industries and Construction | B8: =+'Tabla de Emisiones y Remociones'!H42 | C8: =+B8*0.997804185 | D8: =+B8*0.000829605 | E8: =+B8*0.00136621
A9: 1.A.2.a - Iron and Steel | B9: =+B8*0.63 | C9: =+C8*0.63 | D9: =+D8*0.63 | E9: =+E8*0.63
A10: 1.A.2.f - Cement (Energy) | B10: =+B8*0.37 | C10: =+C8*0.37 | D10: =+D8*0.37 | E10: =+E8*0.37
A11: 1.A.3 - Transport | B11: =+'Tabla de Emisiones y Remociones'!H43 | C11: =+B11*0.980386029 | D11: =+B11*0.010583264 | E11: =+B11*0.009030706
A12: 1.A.4 - Other Sectors | B12: =+'Tabla de Emisiones y Remociones'!H44 | C12: =+B12*0.930398755 | D12: =+B12*0.062442227 | E12: =+B12*0.007159018
A13: 1.B - Fugitive emissions from fuels | B13: =+'Tabla de Emisiones y Remociones'!H45 | C13: =SUM(C14:C16) | D13: =SUM(D14:D16)
A14: 1.B - Fugitive emissions from fuels - Fugitive | B14: =B13*0.188 | C14: =B14*0.2 | D14: =B14*0.8
A15: 1.B - Fugitive emissions from fuels - Venting | B15: =B13*0.58 | C15: =B15*0.3 | D15: =+B15*0.7
A16: 1.B - Fugitive emissions from fuels - Flaring | B16: =B13*0.232 | C16: =B16*0.5 | D16: =B16*0.5
A17: 1.C - Carbon dioxide Transport and Storage | B17: =+'Tabla de Emisiones y Remociones'!H46 | C17: 0 | D17: 0 | E17: 0 | F17: 0 | G17: 0 | H17: 0
A18: 2 - Industrial Processes and Product Use | B18: =+'Tabla de Emisiones y Remociones'!H47 | C18: =+C19+C23+C26+C28+C29 | D18: =+D19+D23+D26+D28+D29 | E18: =+E19+E23+E26+E28+E29 | F18: =+F19+F23+F26+F28+F29 | G18: =+G29 | H18: =+SUM(C18:G18)
A19: 2.A - Mineral Industry | B19: =+'Tabla de Emisiones y Remociones'!H48 | C19: =+C20+C21
A20: 2.A.1 - Cement production | B20: =+'Tabla de Emisiones y Remociones'!H49 | C20: =+B20*1
A21: 2.A.2 - Lime production | B21: =+'Tabla de Emisiones y Remociones'!H50 | C21: =+B21*1
A22: 2.A.3 - Glass production | B22: 0 | C22: 0
A23: 2.B - Chemical Industry | B23: =+'Tabla de Emisiones y Remociones'!H51 | C23: =+B23*0.35429321 | D23: =+B23*0.000491157 | E23: =+B23*0.051078759 | F23: =+B23*0.594136874
A24: 2.B.1 - Ammonia Production | B24: =+'Tabla de Emisiones y Remociones'!H52 | C24: =+B24*0.35429321 | D24: =+B24*0.000491157 | E24: =+B24*0.051078759 | F24: =+B24*0.594136874
A25: 2.B.8 - Petrochemical and Carbon Black Production | B25: =+'Tabla de Emisiones y Remociones'!H53 | C25: =+B25*0.35429321 | D25: =+B25*0.000491157 | E25: =+B25*0.051078759 | F25: =+B25*0.594136874
A26: 2.C - Metal Industry | B26: =+'Tabla de Emisiones y Remociones'!H54 | C26: =+C27 | D26: =+D27
A27: 2.C.1 - Iron and Steel Production | B27: =+'Tabla de Emisiones y Remociones'!H55 | C27: =+B27*0.98 | D27: =+B27*0.02
A28: 2.D - Non-Energy Products from Fuels and Solvent Use | B28: =+'Tabla de Emisiones y Remociones'!H56 | C28: =+B28
A29: 2.F - Product Uses as Substitutes for Ozone Depleting Substances | B29: =+'Tabla de Emisiones y Remociones'!H57 | F29: =+F30 | G29: =+G30
A30: 2.F.1 - Refrigeration and Air Conditioning | B30: =+'Tabla de Emisiones y Remociones'!H58 | F30: =+B30/2 | G30: =+B30/2
A31: 3 - Agriculture, Forestry, and Other Land Use | B31: =+'Tabla de Emisiones y Remociones'!H59 | C31: =+SUM(C32+C35+CC2737) | D31: =+SUM(D32+D37) | E31: =+SUM(E32+E37) | H31: =+SUM(C31:G31)
A32: 3.A - Livestock | B32: =+'Tabla de Emisiones y Remociones'!H60 | D32: =+D33+D34 | E32: =+E33+E34
A33: 3.A.1 - Enteric Fermentation | B33: =+'Tabla de Emisiones y Remociones'!H61 | D33: =+B33*0.996032041 | E33: =+B33*0.003967959
A34: 3.A.2 - Manure Management | B34: =+'Tabla de Emisiones y Remociones'!H62 | D34: =+B34
A35: 3.B - Land | B35: =+B36 | C35: =+C36
A36: 3.B.1 - Forest land | B36: =+'Tabla de Emisiones y Remociones'!H63 | C36: =+B36
A37: 3.C - Aggregate sources and non-CO2 emissions sources on land | B37: =+'Tabla de Emisiones y Remociones'!H64 | C37: =+SUM(C38:C43) | D37: =+SUM(D38:D43) | E37: =+SUM(E38:E43)
A38: 3.C.1 - Burning | B38: =+'Tabla de Emisiones y Remociones'!H65 | D38: =+B38*0.996032041 | E38: =+B38*0.003967959
A39: 3.C.2 - Liming | B39: =+'Tabla de Emisiones y Remociones'!H66 | C39: 0 | D39: 0 | E39: 0
A40: 3.C.3 - Urea application | B40: =+'Tabla de Emisiones y Remociones'!H67 | C40: =+B40
...

Sheet Notes - 1.A.1 Split
A1: Correccion al desglose 1.A.1 - Energy Industries
A3: Problema detectado en version anterior:
A4: - Las celdas de '1.A.1 - Electricity and Heat Generation' y '1.A.1 - Fuel Production'
A5: contenian la formula =B$5/2 (split 50/50 hard-coded en el archivo).
A6: - Las dos filas eran identicas en los 7 anos (2017-2023) y para los 3 gases (CO2, CH4, N2O).
A7: - No tiene fundamento metodologico: el dato fuente entrega 1.A.1 agregado.
A9: Metodologia aplicada en esta version:
A10: - Split 70% Electricity & Heat Generation / 30% Fuel Production.
A11: - Implementado como formulas: '=+B$5*0.70' y '=+B$5*0.30' (analogo para C, D, E).
A12: - El padre '1.A.1 - Energy Industries' no se modifica.
A14: Justificacion del 70/30 para Libia:
A15: 1. Bottom-up con slide 14 NDC (mix de combustibles power gen 2023 = 12.2 Mtoe):
... A29: Generado: 2026-05-05
