Workbook

Sheet Assumptions
A1: CONVERSION ASSUMPTIONS — MtCO2e to MMcfd (v2, CCD-anchored)
A3: A. PHYSICS — CH4 conversion (used for Fugitive and Venting)
A4: Parameter | B4: Value | C4: Unit | D4: Source / Note
A5: GWP100 CH4 (AR5) | B5: 28 | C5: kg CO2e / kg CH4 | D5: IPCC AR5 WG1 Ch.8, Table 8.7 (consistent with UNFCCC reporting)
A6: CH4 share — Fugitive emissions | B6: 0.95 | C6: fraction | D6: IPCC 2006 GL Vol.2 Ch.4 — typical natural-gas fugitive composition
A7: CH4 share — Venting emissions | B7: 0.95 | C7: fraction | D7: IPCC 2006 GL Vol.2 Ch.4 — venting from associated gas operations
A8: CH4 density (std cond.) | B8: 0.0191 | C8: kg / scf | D8: Pure CH4 at 60°F, 14.73 psia (US standard)
A9: Days per year | B9: 365 | C9: days | D9: Annual to daily conversion
A10: Mt to kg | B10: 1000000000 | C10: kg / Mt | D10: 1 Mt = 1e9 kg
A11: scf to MMcf | B11: 1000000 | C11: scf / MMcf | D11: 1 MMcf = 1e6 scf
A12: Derived: CH4 factor — Fugitive (k_F) | B12: =B10/B5/B6/B8/B9/B11 -> 5.3925246 | C12: MMcfd / MtCO2e | D12: k_F = 1e9 / GWP / share_F / ρ_CH4 / 365 / 1e6 ≈ 5.41 MMcfd/MtCO2e
A13: Derived: CH4 factor — Venting (k_V) | B13: =B10/B5/B7/B8/B9/B11 -> 5.3925246 | C13: MMcfd / MtCO2e | D13: Same physics as k_F; share_V = 0.95
A15: B. CCD ANCHORS — Flaring (BAU)
A16: BAU 2024 flaring volume (CCD reference) | B16: 607 | C16: MMcfd | D16: CCD §B.1: "Libya flared approximately 6.3 Bcm of natural gas, or 607 MMcfd" (2024)
A17: BAU 2030 flaring volume (CCD reference) | B17: 991 | C17: MMcfd | D17: CCD §B.2: "could increase from 607 MMcfd in 2024, to nearly 1 Bcfd by 2030" (rounded to 991)
A18: SISEPUEDE BAU 2024 flaring (MtCO2e) | B18: =SISEPUEDE!D5 -> 6.2913515 | C18: MtCO2e | D18: Reference value used to back out implied EF for 2024
A19: SISEPUEDE BAU 2030 flaring (MtCO2e) | B19: =SISEPUEDE!D11 -> 11.586339 | C19: MtCO2e | D19: Reference value used to back out implied EF for 2030
A20: Implied flaring factor — 2024 (k_Fl_24) | B20: =B16/B18 -> 96.481654 | C20: MMcfd / MtCO2e | D20: CCD vol(2024) divided by SISEPUEDE BAU Fl MtCO2e(2024). Higher than 2030 EF (heavier CH4 slip in current flare operations).
A21: Implied flaring factor — 2030 (k_Fl_30) | B21: =B17/B19 -> 85.53176 | C21: MMcfd / MtCO2e | D21: CCD vol(2030) divided by SISEPUEDE BAU Fl MtCO2e(2030). The two anchors are interpolated linearly 2024 to 2030.
A23: C. METHODOLOGY (v2)
A24: Fugitive volume (MMcfd) | B24: MtCO2e_F × k_F (physics: CH4 mass / density)
A25: Venting volume (MMcfd) | B25: MtCO2e_V × k_V (physics: CH4 mass / density)
A26: Flaring volume (MMcfd) | B26: MtCO2e_Fl × k_Fl(t) (CCD-calibrated, time-varying)
A27: Gas Recovery vol. (MMcfd) | B27: MtCO2e_GR × k_Fl(t) (recovered gas ≈ NG-quality, same EF as flared)
A28: Flaring factor k_Fl(t) | B28: 2023 ≤ t ≤ 2024 → k_Fl_24 ; 2024<t<2030 → linear interp ; t ≥ 2030 → k_Fl_30
A31: D. YEAR-BY-YEAR FLARING FACTOR k_Fl(t)
A32: Year | B32: k_Fl(t) | C32: Unit | D32: Logic
A33: 2023 | B33: =IF(A33<=2024,$B$20,IF(A33>=2030,$B$21,$B$20+($B$21-$B$20)*(A33-2024)/(2030-2024))) -> 96.481654 | C33: MMcfd / MtCO2e | D33: Held flat at 2024 anchor (extrapolation)
A34: 2024 | B34: =IF(A34<=2024,$B$20,IF(A34>=2030,$B$21,$B$20+($B$21-$B$20)*(A34-2024)/(2030-2024))) -> 96.481654 | C34: MMcfd / MtCO2e | D34: Anchor: matches CCD 607 MMcfd by construction
A35: 2025 | B35: =IF(A35<=2024,$B$20,IF(A35>=2030,$B$21,$B$20+($B$21-$B$20)*(A35-2024)/(2030-2024))) -> 94.656671 | C35: MMcfd / MtCO2e | D35: Linear interpolation between anchors
A36: 2026 | B36: =IF(A36<=2024,$B$20,IF(A36>=2030,$B$21,$B$20+($B$21-$B$20)*(A36-2024)/(2030-2024))) -> 92.831689 | C36: MMcfd / MtCO2e | D36: Linear interpolation between anchors
A37: 2027 | B37: =IF(A37<=2024,$B$20,IF(A37>=2030,$B$21,$B$20+($B$21-$B$20)*(A37-2024)/(2030-2024))) -> 91.006707 | C37: MMcfd / MtCO2e | D37: Linear interpolation between anchors
A38: 2028 | B38: =IF(A38<=2024,$B$20,IF(A38>=2030,$B$21,$B$20+($B$21-$B$20)*(A38-2024)/(2030-2024))) -> 89.181724 | C38: MMcfd / MtCO2e | D38: Linear interpolation between anchors
A39: 2029 | B39: =IF(A39<=2024,$B$20,IF(A39>=2030,$B$21,$B$20+($B$21-$B$20)*(A39-2024)/(2030-2024))) -> 87.356742 | C39: MMcfd / MtCO2e | D39: Linear interpolation between anchors
A40: 2030 | B40: =IF(A40<=2024,$B$20,IF(A40>=2030,$B$21,$B$20+($B$21-$B$20)*(A40-2024)/(2030-2024))) -> 85.53176 | C40: MMcfd / MtCO2e | D40: Anchor: matches CCD 991 MMcfd by construction
A41: 2031 | B41: =IF(A41<=2024,$B$20,IF(A41>=2030,$B$21,$B$20+($B$21-$B$20)*(A41-2024)/(2030-2024))) -> 85.53176 | C41: MMcfd / MtCO2e | D41: Held flat at 2030 anchor (extrapolation)
A42: 2032 | B42: =IF(A42<=2024,$B$20,IF(A42>=2030,$B$21,$B$20+($B$21-$B$20)*(A42-2024)/(2030-2024))) -> 85.53176 | C42: MMcfd / MtCO2e | D42: Held flat at 2030 anchor (extrapolation)
A43: 2033 | B43: =IF(A43<=2024,$B$20,IF(A43>=2030,$B$21,$B$20+($B$21-$B$20)*(A43-2024)/(2030-2024))) -> 85.53176 | C43: MMcfd / MtCO2e | D43: Held flat at 2030 anchor (extrapolation)
A44: 2034 | B44: =IF(A44<=2024,$B$20,IF(A44>=2030,$B$21,$B$20+($B$21-$B$20)*(A44-2024)/(2030-2024))) -> 85.53176 | C44: MMcfd / MtCO2e | D44: Held flat at 2030 anchor (extrapolation)
... A60: 2050 | B60: =IF(A60<=2024,$B$20,IF(A60>=2030,$B$21,$B$20+($B$21-$B$20)*(A60-2024)/(2030-2024))) -> 85.53176 | C60: MMcfd / MtCO2e | D60: Held flat at 2030 anchor (extrapolation)
...

Sheet MMcfd
A1: VOLUMETRIC ESTIMATES — MMcfd (v2, CCD-anchored, category-specific factors)
B3: Year-specific | C3: BAU | F3: Unconditional | J3: Conditional | N3: Totals (MMcfd)
A4: Year | B4: k_Fl(t) | C4: Fugitive | D4: Venting | E4: Flaring | F4: Fugitive | G4: Venting | H4: Flaring | I4: Gas Recovery | J4: Fugitive | K4: Venting | L4: Flaring | M4: Gas Recovery | N4: BAU total | O4: Uncond total | P4: Cond total
A5: 2023 | B5: =Assumptions!B33 -> 96.481654 | C5: =SISEPUEDE!B4*Assumptions!$B$12 -> 27.400841 | D5: =SISEPUEDE!C4*Assumptions!$B$13 -> 84.534509 | E5: =SISEPUEDE!D4*B5 -> 604.98782 | F5: =SISEPUEDE!B32*Assumptions!$B$12 -> 27.400841 | G5: =SISEPUEDE!C32*Assumptions!$B$13 -> 84.534509 | H5: =SISEPUEDE!D32*B5 -> 604.98782 | I5: =SISEPUEDE!E32*B5 -> 0 | J5: =SISEPUEDE!B60*Assumptions!$B$12 -> 27.400841 | K5: =SISEPUEDE!C60*Assumptions!$B$13 -> 84.534509 | L5: =SISEPUEDE!D60*B5 -> 604.98782 | M5: =SISEPUEDE!E60*B5 -> 0 | N5: =SUM(C5:E5) -> 716.92317 | O5: =SUM(F5:I5) -> 716.92317 | P5: =SUM(J5:M5) -> 716.92317
A6: 2024 | B6: =Assumptions!B34 -> 96.481654 | C6: =SISEPUEDE!B5*Assumptions!$B$12 -> 27.262825 | D6: =SISEPUEDE!C5*Assumptions!$B$13 -> 84.777163 | E6: =SISEPUEDE!D5*B6 -> 607 | F6: =SISEPUEDE!B33*Assumptions!$B$12 -> 27.26187 | G6: =SISEPUEDE!C33*Assumptions!$B$13 -> 84.845865 | H6: =SISEPUEDE!D33*B6 -> 607.96568 | I6: =SISEPUEDE!E33*B6 -> 29.846545 | J6: =SISEPUEDE!B61*Assumptions!$B$12 -> 27.261209 | K6: =SISEPUEDE!C61*Assumptions!$B$13 -> 84.860222 | L6: =SISEPUEDE!D61*B6 -> 608.17697 | M6: =SISEPUEDE!E61*B6 -> 558.51036 | N6: =SUM(C6:E6) -> 719.03999 | O6: =SUM(F6:I6) -> 749.91996 | P6: =SUM(J6:M6) -> 1278.8088
A7: 2025 | B7: =Assumptions!B35 -> 94.656671 | C7: =SISEPUEDE!B6*Assumptions!$B$12 -> 27.300484 | D7: =SISEPUEDE!C6*Assumptions!$B$13 -> 84.907958 | E7: =SISEPUEDE!D6*B7 -> 596.52847 | F7: =SISEPUEDE!B34*Assumptions!$B$12 -> 27.298548 | G7: =SISEPUEDE!C34*Assumptions!$B$13 -> 85.046847 | H7: =SISEPUEDE!D34*B7 -> 598.4439 | I7: =SISEPUEDE!E34*B7 -> 59.891194 | J7: =SISEPUEDE!B62*Assumptions!$B$12 -> 27.29721 | K7: =SISEPUEDE!C62*Assumptions!$B$13 -> 85.075899 | L7: =SISEPUEDE!D62*B7 -> 598.86338 | M7: =SISEPUEDE!E62*B7 -> 1095.4345 | N7: =SUM(C7:E7) -> 708.73691 | O7: =SUM(F7:I7) -> 770.68049 | P7: =SUM(J7:M7) -> 1806.671
A8: 2026 | B8: =Assumptions!B36 -> 92.831689 | C8: =SISEPUEDE!B7*Assumptions!$B$12 -> 32.08435 | D8: =SISEPUEDE!C7*Assumptions!$B$13 -> 87.694301 | E8: =SISEPUEDE!D7*B8 -> 706.75872 | F8: =SISEPUEDE!B35*Assumptions!$B$12 -> 31.439625 | G8: =SISEPUEDE!C35*Assumptions!$B$13 -> 90.727383 | H8: =SISEPUEDE!D35*B8 -> 695.40572 | I8: =SISEPUEDE!E35*B8 -> 91.770352 | J8: =SISEPUEDE!B63*Assumptions!$B$12 -> 25.663623 | K8: =SISEPUEDE!C63*Assumptions!$B$13 -> 71.051979 | L8: =SISEPUEDE!D63*B8 -> 244.15006 | M8: =SISEPUEDE!E63*B8 -> 1601.8452 | N8: =SUM(C8:E8) -> 826.53737 | O8: =SUM(F8:I8) -> 909.34308 | P8: =SUM(J8:M8) -> 1942.7108
A9: 2027 | B9: =Assumptions!B37 -> 91.006707 | C9: =SISEPUEDE!B8*Assumptions!$B$12 -> 33.03676 | D9: =SISEPUEDE!C8*Assumptions!$B$13 -> 90.221738 | E9: =SISEPUEDE!D8*B9 -> 736.91186 | F9: =SISEPUEDE!B36*Assumptions!$B$12 -> 31.711265 | G9: =SISEPUEDE!C36*Assumptions!$B$13 -> 96.250659 | H9: =SISEPUEDE!D36*B9 -> 711.03076 | I9: =SISEPUEDE!E36*B9 -> 126.48127 | J9: =SISEPUEDE!B64*Assumptions!$B$12 -> 19.819047 | K9: =SISEPUEDE!C64*Assumptions!$B$13 -> 56.796625 | L9: =SISEPUEDE!D64*B9 -> 24.779247 | M9: =SISEPUEDE!E64*B9 -> 2053.2777 | N9: =SUM(C9:E9) -> 860.17036 | O9: =SUM(F9:I9) -> 965.47396 | P9: =SUM(J9:M9) -> 2154.6726
A10: 2028 | B10: =Assumptions!B38 -> 89.181724 | C10: =SISEPUEDE!B9*Assumptions!$B$12 -> 33.852556 | D10: =SISEPUEDE!C9*Assumptions!$B$13 -> 92.224596 | E10: =SISEPUEDE!D9*B10 -> 818.17376 | F10: =SISEPUEDE!B37*Assumptions!$B$12 -> 31.795067 | G10: =SISEPUEDE!C37*Assumptions!$B$13 -> 101.47288 | H10: =SISEPUEDE!D37*B10 -> 694.41061 | I10: =SISEPUEDE!E37*B10 -> 164.28609 | J10: =SISEPUEDE!B65*Assumptions!$B$12 -> 13.529399 | K10: =SISEPUEDE!C65*Assumptions!$B$13 -> 42.440681 | L10: =SISEPUEDE!D65*B10 -> 2.0356774 | M10: =SISEPUEDE!E65*B10 -> 2428.5289 | N10: =SUM(C10:E10) -> 944.25091 | O10: =SUM(F10:I10) -> 991.96465 | P10: =SUM(J10:M10) -> 2486.5347
A11: 2029 | B11: =Assumptions!B39 -> 87.356742 | C11: =SISEPUEDE!B10*Assumptions!$B$12 -> 34.48932 | D11: =SISEPUEDE!C10*Assumptions!$B$13 -> 93.498343 | E11: =SISEPUEDE!D10*B11 -> 903.19312 | F11: =SISEPUEDE!B38*Assumptions!$B$12 -> 31.687696 | G11: =SISEPUEDE!C38*Assumptions!$B$13 -> 106.24412 | H11: =SISEPUEDE!D38*B11 -> 674.75243 | I11: =SISEPUEDE!E38*B11 -> 204.60181 | J11: =SISEPUEDE!B66*Assumptions!$B$12 -> 6.8911991 | K11: =SISEPUEDE!C66*Assumptions!$B$13 -> 28.568285 | L11: =SISEPUEDE!D66*B11 -> 0.37828569 | M11: =SISEPUEDE!E66*B11 -> 2718.9442 | N11: =SUM(C11:E11) -> 1031.1808 | O11: =SUM(F11:I11) -> 1017.2861 | P11: =SUM(J11:M11) -> 2754.782
A12: 2030 | B12: =Assumptions!B40 -> 85.53176 | C12: =SISEPUEDE!B11*Assumptions!$B$12 -> 34.999998 | D12: =SISEPUEDE!C11*Assumptions!$B$13 -> 93.907523 | E12: =SISEPUEDE!D11*B12 -> 991 | F12: =SISEPUEDE!B39*Assumptions!$B$12 -> 31.44563 | G12: =SISEPUEDE!C39*Assumptions!$B$13 -> 110.43233 | H12: =SISEPUEDE!D39*B12 -> 651.7908 | I12: =SISEPUEDE!E39*B12 -> 246.37781 | J12: =SISEPUEDE!B67*Assumptions!$B$12 -> 0.0068861922 | K12: =SISEPUEDE!C67*Assumptions!$B$13 -> 15.999512 | L12: =SISEPUEDE!D67*B12 -> 0 | M12: =SISEPUEDE!E67*B12 -> 2925.6032 | N12: =SUM(C12:E12) -> 1119.9075 | O12: =SUM(F12:I12) -> 1040.0466 | P12: =SUM(J12:M12) -> 2941.6096
A13: 2031 | B13: =Assumptions!B41 -> 85.53176 | C13: =SISEPUEDE!B12*Assumptions!$B$12 -> 33.991947 | D13: =SISEPUEDE!C12*Assumptions!$B$13 -> 93.398917 | E13: =SISEPUEDE!D12*B13 -> 1062.03 | F13: =SISEPUEDE!B40*Assumptions!$B$12 -> 29.850377 | G13: =SISEPUEDE!C40*Assumptions!$B$13 -> 113.95385 | H13: =SISEPUEDE!D40*B13 -> 615.14925 | I13: =SISEPUEDE!E40*B13 -> 294.74149 | J13: =SISEPUEDE!B68*Assumptions!$B$12 -> 0.0065330848 | K13: =SISEPUEDE!C68*Assumptions!$B$13 -> 5.4696735 | L13: =SISEPUEDE!D68*B13 -> 0 | M13: =SISEPUEDE!E68*B13 -> 3121.8629 | N13: =SUM(C13:E13) -> 1189.4209 | O13: =SUM(F13:I13) -> 1053.695 | P13: =SUM(J13:M13) -> 3127.3392
A14: 2032 | B14: =Assumptions!B42 -> 85.53176 | C14: =SISEPUEDE!B13*Assumptions!$B$12 -> 32.960711 | D14: =SISEPUEDE!C13*Assumptions!$B$13 -> 92.022547 | E14: =SISEPUEDE!D13*B14 -> 1134.8571 | F14: =SISEPUEDE!B41*Assumptions!$B$12 -> 28.27849 | G14: =SISEPUEDE!C41*Assumptions!$B$13 -> 116.81264 | H14: =SISEPUEDE!D41*B14 -> 578.46436 | I14: =SISEPUEDE!E41*B14 -> 344.60629 | J14: =SISEPUEDE!B69*Assumptions!$B$12 -> 0.0061850398 | K14: =SISEPUEDE!C69*Assumptions!$B$13 -> 0 | L14: =SISEPUEDE!D69*B14 -> 0 | M14: =SISEPUEDE!E69*B14 -> 3234.6464 | N14: =SUM(C14:E14) -> 1259.8404 | O14: =SUM(F14:I14) -> 1068.1618 | P14: =SUM(J14:M14) -> 3234.6526
A15: 2033 | B15: =Assumptions!B43 -> 85.53176 | C15: =SISEPUEDE!B14*Assumptions!$B$12 -> 31.905981 | D15: =SISEPUEDE!C14*Assumptions!$B$13 -> 89.885155 | E15: =SISEPUEDE!D14*B15 -> 1209.5239 | F15: =SISEPUEDE!B42*Assumptions!$B$12 -> 26.730507 | G15: =SISEPUEDE!C42*Assumptions!$B$13 -> 119.0645 | H15: =SISEPUEDE!D42*B15 -> 541.84338 | I15: =SISEPUEDE!E42*B15 -> 395.37772 | J15: =SISEPUEDE!B70*Assumptions!$B$12 -> 0.0058428137 | K15: =SISEPUEDE!C70*Assumptions!$B$13 -> 0 | L15: =SISEPUEDE!D70*B15 -> 0 | M15: =SISEPUEDE!E70*B15 -> 3295.6237 | N15: =SUM(C15:E15) -> 1331.315 | O15: =SUM(F15:I15) -> 1083.0161 | P15: =SUM(J15:M15) -> 3295.6295
A16: 2034 | B16: =Assumptions!B44 -> 85.53176 | C16: =SISEPUEDE!B15*Assumptions!$B$12 -> 30.827443 | D16: =SISEPUEDE!C15*Assumptions!$B$13 -> 87.116611 | E16: =SISEPUEDE!D15*B16 -> 1286.0736 | F16: =SISEPUEDE!B43*Assumptions!$B$12 -> 25.207098 | G16: =SISEPUEDE!C43*Assumptions!$B$13 -> 120.79024 | H16: =SISEPUEDE!D43*B16 -> 505.38191 | I16: =SISEPUEDE!E43*B16 -> 446.68625 | J16: =SISEPUEDE!B71*Assumptions!$B$12 -> 0.0055070202 | K16: =SISEPUEDE!C71*Assumptions!$B$13 -> 0 | L16: =SISEPUEDE!D71*B16 -> 0 | M16: =SISEPUEDE!E71*B16 -> 3320.8654 | N16: =SUM(C16:E16) -> 1404.0177 | O16: =SUM(F16:I16) -> 1098.0655 | P16: =SUM(J16:M16) -> 3320.8709
... A32: 2050 | B32: =Assumptions!B60 -> 85.53176 | C32: =SISEPUEDE!B31*Assumptions!$B$12 -> 10.162591 | D32: =SISEPUEDE!C31*Assumptions!$B$13 -> 15.214037 | E32: =SISEPUEDE!D31*B32 -> 2829.0369 | F32: =SISEPUEDE!B59*Assumptions!$B$12 -> 5.0771342 | G32: =SISEPUEDE!C59*Assumptions!$B$13 -> 117.72538 | H32: =SISEPUEDE!D59*B32 -> 1.3057521 | I32: =SISEPUEDE!E59*B32 -> 1346.3157 | J32: =SISEPUEDE!B87*Assumptions!$B$12 -> 0.0013580551 | K32: =SISEPUEDE!C87*Assumptions!$B$13 -> 0 | L32: =SISEPUEDE!D87*B32 -> 0 | M32: =SISEPUEDE!E87*B32 -> 3352.6434 | N32: =SUM(C32:E32) -> 2854.4136 | O32: =SUM(F32:I32) -> 1470.424 | P32: =SUM(J32:M32) -> 3352.6447
A34: Units: MMcfd. Yellow cells are CCD-calibrated anchors (BAU flaring 2024 = 607 MMcfd; 2030 = 991 MMcfd).
A35: Fugitive & Venting use the physics-based CH4 factor (Assumptions!B12, B13). Flaring & Gas Recovery use k_Fl(t) from Assumptions column B.
A36: Mass conservation in MtCO2e holds in the SISEPUEDE sheet (BAU = scenario_F + V + Fl + GR). Volumetric totals are not required to match across scenarios.

Sheet SISEPUEDE
A1: MTCO2
A3: Metric | B3: Fugitive | C3: Venting | D3: Flaring | E3: Gas Recovery | F3: Strategy
A4: 2023 | B4: 5.081264 | C4: 15.67624 | D4: 6.270496 | E4: 0 | F4: BAU
A5: 2024 | B5: 5.05567 | C5: 15.721238 | D5: 6.2913515 | E5: 0 | F5: BAU
A6: 2025 | B6: 5.0626537 | C6: 15.745493 | D6: 6.3020225 | E6: 0 | F6: BAU
A7: 2026 | B7: 5.9497828 | C7: 16.262198 | D7: 7.6133347 | E7: 0 | F7: BAU
A8: 2027 | B8: 6.1263995 | C8: 16.730891 | D8: 8.0973358 | E8: 0 | F8: BAU
A9: 2028 | B9: 6.2776822 | C9: 17.102304 | D9: 9.1742312 | E9: 0 | F9: BAU
A10: 2029 | B10: 6.395765 | C10: 17.33851 | D10: 10.339135 | E10: 0 | F10: BAU
A11: 2030 | B11: 6.4904661 | C11: 17.41439 | D11: 11.586339 | E11: 0 | F11: BAU
A12: 2031 | B12: 6.3035312 | C12: 17.320073 | D12: 12.416791 | E12: 0 | F12: BAU
A13: 2032 | B13: 6.112297 | C13: 17.064836 | D13: 13.268254 | E13: 0 | F13: BAU
A14: 2033 | B14: 5.9167057 | C14: 16.668474 | D14: 14.141225 | E14: 0 | F14: BAU
A15: 2034 | B15: 5.7166996 | C15: 16.15507 | D15: 15.036211 | E15: 0 | F15: BAU
... A30: 2049 | B30: 2.1637761 | C30: 3.7524431 | D30: 31.71284 | E30: 0 | F30: BAU
A31: 2050 | B31: 1.8845701 | C31: 2.8213198 | D31: 33.075865 | E31: 0 | F31: BAU
A32: 2023 | B32: 5.081264 | C32: 15.67624 | D32: 6.270496 | E32: 0 | F32: Unconditional
A33: 2024 | B33: 5.0554929 | C33: 15.733978 | D33: 6.3013605 | E33: 0.30934944 | F33: Unconditional
A34: 2025 | B34: 5.0622946 | C34: 15.771249 | D34: 6.322258 | E34: 0.63272026 | F34: Unconditional
A35: 2026 | B35: 5.8302237 | C35: 16.824658 | D35: 7.4910381 | E35: 0.98856708 | F35: Unconditional
A36: 2027 | B36: 5.8805972 | C36: 17.848905 | D36: 7.812949 | E36: 1.3898017 | F36: Unconditional
A37: 2028 | B37: 5.8961376 | C37: 18.817324 | D37: 7.7864676 | E37: 1.8421498 | F37: Unconditional
A38: 2029 | B38: 5.8762266 | C38: 19.702111 | D38: 7.7241025 | E38: 2.342141 | F38: Unconditional
A39: 2030 | B39: 5.8313374 | C39: 20.478781 | D39: 7.6204535 | E39: 2.8805418 | F39: Unconditional
A40: 2031 | B40: 5.5355106 | C40: 21.131819 | D40: 7.1920565 | E40: 3.4459889 | F40: Unconditional
A41: 2032 | B41: 5.2440169 | C41: 21.661959 | D41: 6.7631528 | E41: 4.0289863 | F41: Unconditional
A42: 2033 | B42: 4.956956 | C42: 22.079548 | D42: 6.3349962 | E42: 4.6225837 | F42: Unconditional
A43: 2034 | B43: 4.6744522 | C43: 22.399571 | D43: 5.9087047 | E43: 5.2224607 | F43: Unconditional
... A58: 2049 | B58: 1.124285 | C58: 22.01308 | D58: 0.30418357 | E58: 15.304208 | F58: Unconditional
A59: 2050 | B59: 0.94151341 | C59: 21.831219 | D59: 0.015266284 | E59: 15.740536 | F59: Unconditional
A60: 2023 | B60: 5.081264 | C60: 15.67624 | D60: 6.270496 | E60: 0 | F60: Conditional
A61: 2024 | B61: 5.0553704 | C61: 15.736641 | D61: 6.3035504 | E61: 5.7887727 | F61: Conditional
A62: 2025 | B62: 5.0620465 | C62: 15.776636 | D62: 6.3266896 | E62: 11.572713 | F62: Conditional
A63: 2026 | B63: 4.7591111 | C63: 13.176014 | D63: 2.6300293 | E63: 17.25537 | F63: Conditional
A64: 2027 | B64: 3.6752817 | C64: 10.532474 | D64: 0.27227935 | E64: 22.561828 | F64: Conditional
A65: 2028 | B65: 2.5089175 | C65: 7.8702806 | D65: 0.022826172 | E65: 27.23124 | F65: Conditional
A66: 2029 | B66: 1.2779171 | C66: 5.297757 | D66: 0.0043303548 | E66: 31.124606 | F66: Conditional
A67: 2030 | B67: 0.0012769886 | C67: 2.9669799 | D67: 0 | E67: 34.204876 | F67: Conditional
A68: 2031 | B68: 0.0012115077 | C68: 1.0143066 | D68: 0 | E68: 36.499459 | F68: Conditional
A69: 2032 | B69: 0.0011469655 | C69: 0 | D69: 0 | E69: 37.818074 | F69: Conditional
...

Sheet Gas Recovery Revenue
A1: GAS RECOVERY — REVENUE FROM SELLING RECOVERED GAS AT NATURAL-GAS PRICES
A3: INPUTS (yellow cells are user-editable)
A5: Parameter | B5: Value | C5: Unit | D5: Source / Note
A6: NG heating value (HHV) | B6: 1.03 | C6: MMBtu / Mcf | D6: EPA AP-42 / EIA — typical pipeline natural gas (≈1,030 Btu/scf)
A7: Days per year | B7: 365 | C7: days
A8: Mcf per MMcf | B8: 1000 | C8: Mcf / MMcf
A9: Reference NG price — Low (Henry Hub long-term) | B9: 4 | C9: USD / MMBtu | D9: EIA AEO 2025 reference Henry Hub avg 2025-2050 (≈$3.5-4.5)
A10: Reference NG price — Central (TTF/NBP medium-term) | B10: 8 | C10: USD / MMBtu | D10: IEA WEO 2024 European import price 2030 ≈ $8/MMBtu (real)
A11: Reference NG price — High (Stress / current EU) | B11: 12 | C11: USD / MMBtu | D11: IEA WEO 2024 high-price scenario / 2024 NBP avg ≈ $10.7/MMBtu (CCD §B.1)
A13: HOW THE REVENUE IS COMPUTED
A14: Annual recovered volume (MMcf/yr) = MMcfd × 365
A15: Annual energy (MMBtu/yr) = Annual volume (Mcf/yr) × HHV (MMBtu/Mcf) = MMcfd × 365 × 1,000 × 1.030
A16: Annual revenue (USD/yr) = Annual energy × NG price (USD/MMBtu)
A17: Cumulative revenue 2024-2030 / 2024-2050 are reported in the bottom block.
A19: ANNUAL REVENUE (USD millions)
B20: GR volume (MMcfd) | D20: Annual energy (M MMBtu) | F20: Unconditional revenue ($M) | I20: Conditional revenue ($M)
A21: Year | B21: Uncond. | C21: Cond. | D21: Uncond. | E21: Cond. | F21: Low | G21: Central | H21: High | I21: Low | J21: Central | K21: High
A22: 2023 | B22: =MMcfd!I5 -> 0 | C22: =MMcfd!M5 -> 0 | D22: =B22*$B$7*$B$8*$B$6/1000000 -> 0 | E22: =C22*$B$7*$B$8*$B$6/1000000 -> 0 | F22: =D22*$B$9 -> 0 | G22: =D22*$B$10 -> 0 | H22: =D22*$B$11 -> 0 | I22: =E22*$B$9 -> 0 | J22: =E22*$B$10 -> 0 | K22: =E22*$B$11 -> 0
A23: 2024 | B23: =MMcfd!I6 -> 29.846545 | C23: =MMcfd!M6 -> 558.51036 | D23: =B23*$B$7*$B$8*$B$6/1000000 -> 11.220809 | E23: =C23*$B$7*$B$8*$B$6/1000000 -> 209.97197 | F23: =D23*$B$9 -> 44.883235 | G23: =D23*$B$10 -> 89.76647 | H23: =D23*$B$11 -> 134.6497 | I23: =E23*$B$9 -> 839.88788 | J23: =E23*$B$10 -> 1679.7758 | K23: =E23*$B$11 -> 2519.6636
A24: 2025 | B24: =MMcfd!I7 -> 59.891194 | C24: =MMcfd!M7 -> 1095.4345 | D24: =B24*$B$7*$B$8*$B$6/1000000 -> 22.516094 | E24: =C24*$B$7*$B$8*$B$6/1000000 -> 411.82861 | F24: =D24*$B$9 -> 90.064377 | G24: =D24*$B$10 -> 180.12875 | H24: =D24*$B$11 -> 270.19313 | I24: =E24*$B$9 -> 1647.3144 | J24: =E24*$B$10 -> 3294.6289 | K24: =E24*$B$11 -> 4941.9433
A25: 2026 | B25: =MMcfd!I8 -> 91.770352 | C25: =MMcfd!M8 -> 1601.8452 | D25: =B25*$B$7*$B$8*$B$6/1000000 -> 34.501064 | E25: =C25*$B$7*$B$8*$B$6/1000000 -> 602.21369 | F25: =D25*$B$9 -> 138.00425 | G25: =D25*$B$10 -> 276.00851 | H25: =D25*$B$11 -> 414.01276 | I25: =E25*$B$9 -> 2408.8548 | J25: =E25*$B$10 -> 4817.7096 | K25: =E25*$B$11 -> 7226.5643
A26: 2027 | B26: =MMcfd!I9 -> 126.48127 | C26: =MMcfd!M9 -> 2053.2777 | D26: =B26*$B$7*$B$8*$B$6/1000000 -> 47.550635 | E26: =C26*$B$7*$B$8*$B$6/1000000 -> 771.92974 | F26: =D26*$B$9 -> 190.20254 | G26: =D26*$B$10 -> 380.40508 | H26: =D26*$B$11 -> 570.60762 | I26: =E26*$B$9 -> 3087.719 | J26: =E26*$B$10 -> 6175.4379 | K26: =E26*$B$11 -> 9263.1569
A27: 2028 | B27: =MMcfd!I10 -> 164.28609 | C27: =MMcfd!M10 -> 2428.5289 | D27: =B27*$B$7*$B$8*$B$6/1000000 -> 61.763357 | E27: =C27*$B$7*$B$8*$B$6/1000000 -> 913.00545 | F27: =D27*$B$9 -> 247.05343 | G27: =D27*$B$10 -> 494.10686 | H27: =D27*$B$11 -> 741.16029 | I27: =E27*$B$9 -> 3652.0218 | J27: =E27*$B$10 -> 7304.0436 | K27: =E27*$B$11 -> 10956.065
A28: 2029 | B28: =MMcfd!I11 -> 204.60181 | C28: =MMcfd!M11 -> 2718.9442 | D28: =B28*$B$7*$B$8*$B$6/1000000 -> 76.920051 | E28: =C28*$B$7*$B$8*$B$6/1000000 -> 1022.1871 | F28: =D28*$B$9 -> 307.6802 | G28: =D28*$B$10 -> 615.36041 | H28: =D28*$B$11 -> 923.04061 | I28: =E28*$B$9 -> 4088.7483 | J28: =E28*$B$10 -> 8177.4965 | K28: =E28*$B$11 -> 12266.245
A29: 2030 | B29: =MMcfd!I12 -> 246.37781 | C29: =MMcfd!M12 -> 2925.6032 | D29: =B29*$B$7*$B$8*$B$6/1000000 -> 92.625738 | E29: =C29*$B$7*$B$8*$B$6/1000000 -> 1099.8805 | F29: =D29*$B$9 -> 370.50295 | G29: =D29*$B$10 -> 741.00591 | H29: =D29*$B$11 -> 1111.5089 | I29: =E29*$B$9 -> 4399.5221 | J29: =E29*$B$10 -> 8799.0442 | K29: =E29*$B$11 -> 13198.566
A30: 2031 | B30: =MMcfd!I13 -> 294.74149 | C30: =MMcfd!M13 -> 3121.8629 | D30: =B30*$B$7*$B$8*$B$6/1000000 -> 110.80806 | E30: =C30*$B$7*$B$8*$B$6/1000000 -> 1173.6644 | F30: =D30*$B$9 -> 443.23226 | G30: =D30*$B$10 -> 886.46451 | H30: =D30*$B$11 -> 1329.6968 | I30: =E30*$B$9 -> 4694.6575 | J30: =E30*$B$10 -> 9389.315 | K30: =E30*$B$11 -> 14083.973
A31: 2032 | B31: =MMcfd!I14 -> 344.60629 | C31: =MMcfd!M14 -> 3234.6464 | D31: =B31*$B$7*$B$8*$B$6/1000000 -> 129.55473 | E31: =C31*$B$7*$B$8*$B$6/1000000 -> 1216.0653 | F31: =D31*$B$9 -> 518.21893 | G31: =D31*$B$10 -> 1036.4379 | H31: =D31*$B$11 -> 1554.6568 | I31: =E31*$B$9 -> 4864.2613 | J31: =E31*$B$10 -> 9728.5225 | K31: =E31*$B$11 -> 14592.784
A32: 2033 | B32: =MMcfd!I15 -> 395.37772 | C32: =MMcfd!M15 -> 3295.6237 | D32: =B32*$B$7*$B$8*$B$6/1000000 -> 148.64225 | E32: =C32*$B$7*$B$8*$B$6/1000000 -> 1238.9897 | F32: =D32*$B$9 -> 594.56902 | G32: =D32*$B$10 -> 1189.138 | H32: =D32*$B$11 -> 1783.7071 | I32: =E32*$B$9 -> 4955.9589 | J32: =E32*$B$10 -> 9911.9178 | K32: =E32*$B$11 -> 14867.877
A33: 2034 | B33: =MMcfd!I16 -> 446.68625 | C33: =MMcfd!M16 -> 3320.8654 | D33: =B33*$B$7*$B$8*$B$6/1000000 -> 167.9317 | E33: =C33*$B$7*$B$8*$B$6/1000000 -> 1248.4793 | F33: =D33*$B$9 -> 671.72679 | G33: =D33*$B$10 -> 1343.4536 | H33: =D33*$B$11 -> 2015.1804 | I33: =E33*$B$9 -> 4993.9174 | J33: =E33*$B$10 -> 9987.8347 | K33: =E33*$B$11 -> 14981.752
... A49: 2050 | B49: =MMcfd!I32 -> 1346.3157 | C49: =MMcfd!M32 -> 3352.6434 | D49: =B49*$B$7*$B$8*$B$6/1000000 -> 506.1474 | E49: =C49*$B$7*$B$8*$B$6/1000000 -> 1260.4263 | F49: =D49*$B$9 -> 2024.5896 | G49: =D49*$B$10 -> 4049.1792 | H49: =D49*$B$11 -> 6073.7688 | I49: =E49*$B$9 -> 5041.7051 | J49: =E49*$B$10 -> 10083.41 | K49: =E49*$B$11 -> 15125.115
A51: HEADLINE REVENUE NUMBERS
B52: Volume context | F52: Unconditional ($M, USD) | I52: Conditional ($M, USD)
A53: Metric | B53: Uncond MMcfd | C53: Cond MMcfd | D53: Uncond Bcf/yr | E53: Cond Bcf/yr | F53: Low | G53: Central | H53: High | I53: Low | J53: Central | K53: High
A54: 2030 (point) | B54: =B29 -> 246.37781 | C54: =C29 -> 2925.6032 | D54: =B29*$B$7/1000 -> 89.927901 | E54: =C29*$B$7/1000 -> 1067.8452 | F54: =F29 -> 370.50295 | G54: =G29 -> 741.00591 | H54: =H29 -> 1111.5089 | I54: =I29 -> 4399.5221 | J54: =J29 -> 8799.0442 | K54: =K29 -> 13198.566
A55: Cumulative 2024-2030 ($M) | B55: =AVERAGE(B23:B29) -> 131.89358 | C55: =AVERAGE(C23:C29) -> 1911.7349 | D55: =SUM(B23:B29)*$B$7/1000 -> 336.9881 | E55: =SUM(C23:C29)*$B$7/1000 -> 4884.4826 | F55: =SUM(F23:F29) -> 1388.391 | G55: =SUM(G23:G29) -> 2776.782 | H55: =SUM(H23:H29) -> 4165.173 | I55: =SUM(I23:I29) -> 20124.068 | J55: =SUM(J23:J29) -> 40248.136 | K55: =SUM(K23:K29) -> 60372.205
A56: Cumulative 2024-2050 ($M) | B56: =AVERAGE(B23:B49) -> 633.99932 | C56: =AVERAGE(C23:C49) -> 2957.2297 | D56: =SUM(B23:B49)*$B$7/1000 -> 6248.0633 | E56: =SUM(C23:C49)*$B$7/1000 -> 29143.499 | F56: =SUM(F23:F49) -> 25742.021 | G56: =SUM(G23:G49) -> 51484.042 | H56: =SUM(H23:H49) -> 77226.063 | I56: =SUM(I23:I49) -> 120071.21 | J56: =SUM(J23:J49) -> 240142.43 | K56: =SUM(K23:K49) -> 360213.64
A58: SANITY CHECK vs. CCD report
A59: CCD: 2024 lost value (Bcf flared × $10.70/MMBtu) | B59: $1.8 billion (BAU 2024)
A60: Implied price benchmark (CCD 2024 NBP) | B60: $10.70 / MMBtu — falls between Central ($8) and High ($12)
A61: CCD: cumulative BAU lost value to 2030 | B61: $32.1 billion (entire decade ending 2030)
...

Sheet Summary
A1: Long-format summary: emissions and volumetric estimates
A3: Year | B3: Strategy | C3: Category | D3: Value | E3: Unit | F3: Source | H3: BAU - MtCO2e
A4: 2023 | B4: BAU | C4: Fugitive | D4: =SISEPUEDE!B4 -> 5.081264 | E4: MtCO2e | F4: SISEPUEDE | H4: Year | I4: Fugitive | J4: Venting | K4: Flaring
A5: 2024 | B5: BAU | C5: Fugitive | D5: =SISEPUEDE!B5 -> 5.05567 | E5: MtCO2e | F5: SISEPUEDE | H5: 2023 | I5: =SISEPUEDE!B4 -> 5.081264 | J5: =SISEPUEDE!C4 -> 15.67624 | K5: =SISEPUEDE!D4 -> 6.270496
A6: 2025 | B6: BAU | C6: Fugitive | D6: =SISEPUEDE!B6 -> 5.0626537 | E6: MtCO2e | F6: SISEPUEDE | H6: 2024 | I6: =SISEPUEDE!B5 -> 5.05567 | J6: =SISEPUEDE!C5 -> 15.721238 | K6: =SISEPUEDE!D5 -> 6.2913515
A7: 2026 | B7: BAU | C7: Fugitive | D7: =SISEPUEDE!B7 -> 5.9497828 | E7: MtCO2e | F7: SISEPUEDE | H7: 2025 | I7: =SISEPUEDE!B6 -> 5.0626537 | J7: =SISEPUEDE!C6 -> 15.745493 | K7: =SISEPUEDE!D6 -> 6.3020225
A8: 2027 | B8: BAU | C8: Fugitive | D8: =SISEPUEDE!B8 -> 6.1263995 | E8: MtCO2e | F8: SISEPUEDE | H8: 2026 | I8: =SISEPUEDE!B7 -> 5.9497828 | J8: =SISEPUEDE!C7 -> 16.262198 | K8: =SISEPUEDE!D7 -> 7.6133347
A9: 2028 | B9: BAU | C9: Fugitive | D9: =SISEPUEDE!B9 -> 6.2776822 | E9: MtCO2e | F9: SISEPUEDE | H9: 2027 | I9: =SISEPUEDE!B8 -> 6.1263995 | J9: =SISEPUEDE!C8 -> 16.730891 | K9: =SISEPUEDE!D8 -> 8.0973358
A10: 2029 | B10: BAU | C10: Fugitive | D10: =SISEPUEDE!B10 -> 6.395765 | E10: MtCO2e | F10: SISEPUEDE | H10: 2028 | I10: =SISEPUEDE!B9 -> 6.2776822 | J10: =SISEPUEDE!C9 -> 17.102304 | K10: =SISEPUEDE!D9 -> 9.1742312
A11: 2030 | B11: BAU | C11: Fugitive | D11: =SISEPUEDE!B11 -> 6.4904661 | E11: MtCO2e | F11: SISEPUEDE | H11: 2029 | I11: =SISEPUEDE!B10 -> 6.395765 | J11: =SISEPUEDE!C10 -> 17.33851 | K11: =SISEPUEDE!D10 -> 10.339135
A12: 2031 | B12: BAU | C12: Fugitive | D12: =SISEPUEDE!B12 -> 6.3035312 | E12: MtCO2e | F12: SISEPUEDE | H12: 2030 | I12: =SISEPUEDE!B11 -> 6.4904661 | J12: =SISEPUEDE!C11 -> 17.41439 | K12: =SISEPUEDE!D11 -> 11.586339
A13: 2032 | B13: BAU | C13: Fugitive | D13: =SISEPUEDE!B13 -> 6.112297 | E13: MtCO2e | F13: SISEPUEDE | H13: 2031 | I13: =SISEPUEDE!B12 -> 6.3035312 | J13: =SISEPUEDE!C12 -> 17.320073 | K13: =SISEPUEDE!D12 -> 12.416791
A14: 2033 | B14: BAU | C14: Fugitive | D14: =SISEPUEDE!B14 -> 5.9167057 | E14: MtCO2e | F14: SISEPUEDE | H14: 2032 | I14: =SISEPUEDE!B13 -> 6.112297 | J14: =SISEPUEDE!C13 -> 17.064836 | K14: =SISEPUEDE!D13 -> 13.268254
A15: 2034 | B15: BAU | C15: Fugitive | D15: =SISEPUEDE!B15 -> 5.7166996 | E15: MtCO2e | F15: SISEPUEDE | H15: 2033 | I15: =SISEPUEDE!B14 -> 5.9167057 | J15: =SISEPUEDE!C14 -> 16.668474 | K15: =SISEPUEDE!D14 -> 14.141225
A16: 2035 | B16: BAU | C16: Fugitive | D16: =SISEPUEDE!B16 -> 5.5122204 | E16: MtCO2e | F16: SISEPUEDE | H16: 2034 | I16: =SISEPUEDE!B15 -> 5.7166996 | J16: =SISEPUEDE!C15 -> 16.15507 | K16: =SISEPUEDE!D15 -> 15.036211
... A31: 2050 | B31: BAU | C31: Fugitive | D31: =SISEPUEDE!B31 -> 1.8845701 | E31: MtCO2e | F31: SISEPUEDE | H31: 2049 | I31: =SISEPUEDE!B30 -> 2.1637761 | J31: =SISEPUEDE!C30 -> 3.7524431 | K31: =SISEPUEDE!D30 -> 31.71284
A32: 2023 | B32: BAU | C32: Venting | D32: =SISEPUEDE!C4 -> 15.67624 | E32: MtCO2e | F32: SISEPUEDE | H32: 2050 | I32: =SISEPUEDE!B31 -> 1.8845701 | J32: =SISEPUEDE!C31 -> 2.8213198 | K32: =SISEPUEDE!D31 -> 33.075865
A33: 2024 | B33: BAU | C33: Venting | D33: =SISEPUEDE!C5 -> 15.721238 | E33: MtCO2e | F33: SISEPUEDE
A34: 2025 | B34: BAU | C34: Venting | D34: =SISEPUEDE!C6 -> 15.745493 | E34: MtCO2e | F34: SISEPUEDE
A35: 2026 | B35: BAU | C35: Venting | D35: =SISEPUEDE!C7 -> 16.262198 | E35: MtCO2e | F35: SISEPUEDE | H35: Unconditional - MtCO2e
A36: 2027 | B36: BAU | C36: Venting | D36: =SISEPUEDE!C8 -> 16.730891 | E36: MtCO2e | F36: SISEPUEDE | H36: Year | I36: Fugitive | J36: Venting | K36: Flaring | L36: Gas Recovery
A37: 2028 | B37: BAU | C37: Venting | D37: =SISEPUEDE!C9 -> 17.102304 | E37: MtCO2e | F37: SISEPUEDE | H37: 2023 | I37: =SISEPUEDE!B32 -> 5.081264 | J37: =SISEPUEDE!C32 -> 15.67624 | K37: =SISEPUEDE!D32 -> 6.270496 | L37: =SISEPUEDE!E32 -> 0
A38: 2029 | B38: BAU | C38: Venting | D38: =SISEPUEDE!C10 -> 17.33851 | E38: MtCO2e | F38: SISEPUEDE | H38: 2024 | I38: =SISEPUEDE!B33 -> 5.0554929 | J38: =SISEPUEDE!C33 -> 15.733978 | K38: =SISEPUEDE!D33 -> 6.3013605 | L38: =SISEPUEDE!E33 -> 0.30934944
A39: 2030 | B39: BAU | C39: Venting | D39: =SISEPUEDE!C11 -> 17.41439 | E39: MtCO2e | F39: SISEPUEDE | H39: 2025 | I39: =SISEPUEDE!B34 -> 5.0622946 | J39: =SISEPUEDE!C34 -> 15.771249 | K39: =SISEPUEDE!D34 -> 6.322258 | L39: =SISEPUEDE!E34 -> 0.63272026
A40: 2031 | B40: BAU | C40: Venting | D40: =SISEPUEDE!C12 -> 17.320073 | E40: MtCO2e | F40: SISEPUEDE | H40: 2026 | I40: =SISEPUEDE!B35 -> 5.8302237 | J40: =SISEPUEDE!C35 -> 16.824658 | K40: =SISEPUEDE!D35 -> 7.4910381 | L40: =SISEPUEDE!E35 -> 0.98856708
A41: 2032 | B41: BAU | C41: Venting | D41: =SISEPUEDE!C13 -> 17.064836 | E41: MtCO2e | F41: SISEPUEDE | H41: 2027 | I41: =SISEPUEDE!B36 -> 5.8805972 | J41: =SISEPUEDE!C36 -> 17.848905 | K41: =SISEPUEDE!D36 -> 7.812949 | L41: =SISEPUEDE!E36 -> 1.3898017
A42: 2033 | B42: BAU | C42: Venting | D42: =SISEPUEDE!C14 -> 16.668474 | E42: MtCO2e | F42: SISEPUEDE | H42: 2028 | I42: =SISEPUEDE!B37 -> 5.8961376 | J42: =SISEPUEDE!C37 -> 18.817324 | K42: =SISEPUEDE!D37 -> 7.7864676 | L42: =SISEPUEDE!E37 -> 1.8421498
A43: 2034 | B43: BAU | C43: Venting | D43: =SISEPUEDE!C15 -> 16.15507 | E43: MtCO2e | F43: SISEPUEDE | H43: 2029 | I43: =SISEPUEDE!B38 -> 5.8762266 | J43: =SISEPUEDE!C38 -> 19.702111 | K43: =SISEPUEDE!D38 -> 7.7241025 | L43: =SISEPUEDE!E38 -> 2.342141
A44: 2035 | B44: BAU | C44: Venting | D44: =SISEPUEDE!C16 -> 15.548828 | E44: MtCO2e | F44: SISEPUEDE | H44: 2030 | I44: =SISEPUEDE!B39 -> 5.8313374 | J44: =SISEPUEDE!C39 -> 20.478781 | K44: =SISEPUEDE!D39 -> 7.6204535 | L44: =SISEPUEDE!E39 -> 2.8805418
A45: 2036 | B45: BAU | C45: Venting | D45: =SISEPUEDE!C17 -> 14.871561 | E45: MtCO2e | F45: SISEPUEDE | H45: 2031 | I45: =SISEPUEDE!B40 -> 5.5355106 | J45: =SISEPUEDE!C40 -> 21.131819 | K45: =SISEPUEDE!D40 -> 7.1920565 | L45: =SISEPUEDE!E40 -> 3.4459889
A46: 2037 | B46: BAU | C46: Venting | D46: =SISEPUEDE!C18 -> 14.141423 | E46: MtCO2e | F46: SISEPUEDE | H46: 2032 | I46: =SISEPUEDE!B41 -> 5.2440169 | J46: =SISEPUEDE!C41 -> 21.661959 | K46: =SISEPUEDE!D41 -> 6.7631528 | L46: =SISEPUEDE!E41 -> 4.0289863
A47: 2038 | B47: BAU | C47: Venting | D47: =SISEPUEDE!C19 -> 13.372518 | E47: MtCO2e | F47: SISEPUEDE | H47: 2033 | I47: =SISEPUEDE!B42 -> 4.956956 | J47: =SISEPUEDE!C42 -> 22.079548 | K47: =SISEPUEDE!D42 -> 6.3349962 | L47: =SISEPUEDE!E42 -> 4.6225837
A48: 2039 | B48: BAU | C48: Venting | D48: =SISEPUEDE!C20 -> 12.575076 | E48: MtCO2e | F48: SISEPUEDE | H48: 2034 | I48: =SISEPUEDE!B43 -> 4.6744522 | J48: =SISEPUEDE!C43 -> 22.399571 | K48: =SISEPUEDE!D43 -> 5.9087047 | L48: =SISEPUEDE!E43 -> 5.2224607
... A59: 2050 | B59: BAU | C59: Venting | D59: =SISEPUEDE!C31 -> 2.8213198 | E59: MtCO2e | F59: SISEPUEDE | H59: 2045 | I59: =SISEPUEDE!B54 -> 1.9323661 | J59: =SISEPUEDE!C54 -> 22.666228 | K59: =SISEPUEDE!D54 -> 1.5919726 | L59: =SISEPUEDE!E54 -> 12.422762
A60: 2023 | B60: BAU | C60: Flaring | D60: =SISEPUEDE!D4 -> 6.270496 | E60: MtCO2e | F60: SISEPUEDE | H60: 2046 | I60: =SISEPUEDE!B55 -> 1.7193825 | J60: =SISEPUEDE!C55 -> 22.522906 | K60: =SISEPUEDE!D55 -> 1.2514206 | L60: =SISEPUEDE!E55 -> 13.16066
A61: 2024 | B61: BAU | C61: Flaring | D61: =SISEPUEDE!D5 -> 6.2913515 | E61: MtCO2e | F61: SISEPUEDE | H61: 2047 | I61: =SISEPUEDE!B56 -> 1.5135158 | J61: =SISEPUEDE!C56 -> 22.363415 | K61: =SISEPUEDE!D56 -> 0.92286014 | L61: =SISEPUEDE!E56 -> 13.908251
A62: 2025 | B62: BAU | C62: Flaring | D62: =SISEPUEDE!D6 -> 6.3020225 | E62: MtCO2e | F62: SISEPUEDE | H62: 2048 | I62: =SISEPUEDE!B57 -> 1.3150523 | J62: =SISEPUEDE!C57 -> 22.191935 | K62: =SISEPUEDE!D57 -> 0.60691175 | L62: =SISEPUEDE!E57 -> 14.662699
A63: 2026 | B63: BAU | C63: Flaring | D63: =SISEPUEDE!D7 -> 7.6133347 | E63: MtCO2e | F63: SISEPUEDE | H63: 2049 | I63: =SISEPUEDE!B58 -> 1.124285 | J63: =SISEPUEDE!C58 -> 22.01308 | K63: =SISEPUEDE!D58 -> 0.30418357 | L63: =SISEPUEDE!E58 -> 15.304208
A64: 2027 | B64: BAU | C64: Flaring | D64: =SISEPUEDE!D8 -> 8.0973358 | E64: MtCO2e | F64: SISEPUEDE | H64: 2050 | I64: =SISEPUEDE!B59 -> 0.94151341 | J64: =SISEPUEDE!C59 -> 21.831219 | K64: =SISEPUEDE!D59 -> 0.015266284 | L64: =SISEPUEDE!E59 -> 15.740536
A65: 2028 | B65: BAU | C65: Flaring | D65: =SISEPUEDE!D9 -> 9.1742312 | E65: MtCO2e | F65: SISEPUEDE
...

Sheet tableau
A1: Year | B1: Strategy | C1: Category | D1: Value | E1: Unit
A2: =Summary!A4 -> 2023 | B2: =Summary!B4 -> BAU | C2: =Summary!C4 -> Fugitive | D2: =Summary!D4 -> 5.081264 | E2: =Summary!E4 -> MtCO2e
A3: =Summary!A5 -> 2024 | B3: =Summary!B5 -> BAU | C3: =Summary!C5 -> Fugitive | D3: =Summary!D5 -> 5.05567 | E3: =Summary!E5 -> MtCO2e
A4: =Summary!A6 -> 2025 | B4: =Summary!B6 -> BAU | C4: =Summary!C6 -> Fugitive | D4: =Summary!D6 -> 5.0626537 | E4: =Summary!E6 -> MtCO2e
A5: =Summary!A7 -> 2026 | B5: =Summary!B7 -> BAU | C5: =Summary!C7 -> Fugitive | D5: =Summary!D7 -> 5.9497828 | E5: =Summary!E7 -> MtCO2e
A6: =Summary!A8 -> 2027 | B6: =Summary!B8 -> BAU | C6: =Summary!C8 -> Fugitive | D6: =Summary!D8 -> 6.1263995 | E6: =Summary!E8 -> MtCO2e
A7: =Summary!A9 -> 2028 | B7: =Summary!B9 -> BAU | C7: =Summary!C9 -> Fugitive | D7: =Summary!D9 -> 6.2776822 | E7: =Summary!E9 -> MtCO2e
A8: =Summary!A10 -> 2029 | B8: =Summary!B10 -> BAU | C8: =Summary!C10 -> Fugitive | D8: =Summary!D10 -> 6.395765 | E8: =Summary!E10 -> MtCO2e
A9: =Summary!A11 -> 2030 | B9: =Summary!B11 -> BAU | C9: =Summary!C11 -> Fugitive | D9: =Summary!D11 -> 6.4904661 | E9: =Summary!E11 -> MtCO2e
A10: =Summary!A12 -> 2031 | B10: =Summary!B12 -> BAU | C10: =Summary!C12 -> Fugitive | D10: =Summary!D12 -> 6.3035312 | E10: =Summary!E12 -> MtCO2e
A11: =Summary!A13 -> 2032 | B11: =Summary!B13 -> BAU | C11: =Summary!C13 -> Fugitive | D11: =Summary!D13 -> 6.112297 | E11: =Summary!E13 -> MtCO2e
A12: =Summary!A14 -> 2033 | B12: =Summary!B14 -> BAU | C12: =Summary!C14 -> Fugitive | D12: =Summary!D14 -> 5.9167057 | E12: =Summary!E14 -> MtCO2e
A13: =Summary!A15 -> 2034 | B13: =Summary!B15 -> BAU | C13: =Summary!C15 -> Fugitive | D13: =Summary!D15 -> 5.7166996 | E13: =Summary!E15 -> MtCO2e
... A617: =Summary!A619 -> 2050 | B617: =Summary!B619 -> Conditional | C617: =Summary!C619 -> Gas Recovery | D617: =Summary!D619 -> 3352.6434 | E617: =Summary!E619 -> MMcfd
A618: =Summary!A622 -> 2023 | B618: =Summary!B622 -> Unconditional | C618: =Summary!C622 -> Gas Recovery Revenue (Low, $4/MMBtu) | D618: =Summary!D622 -> 0 | E618: =Summary!E622 -> USD millions
A619: =Summary!A623 -> 2024 | B619: =Summary!B623 -> Unconditional | C619: =Summary!C623 -> Gas Recovery Revenue (Low, $4/MMBtu) | D619: =Summary!D623 -> 44.883235 | E619: =Summary!E623 -> USD millions
A620: =Summary!A624 -> 2025 | B620: =Summary!B624 -> Unconditional | C620: =Summary!C624 -> Gas Recovery Revenue (Low, $4/MMBtu) | D620: =Summary!D624 -> 90.064377 | E620: =Summary!E624 -> USD millions
A621: =Summary!A625 -> 2026 | B621: =Summary!B625 -> Unconditional | C621: =Summary!C625 -> Gas Recovery Revenue (Low, $4/MMBtu) | D621: =Summary!D625 -> 138.00425 | E621: =Summary!E625 -> USD millions
A622: =Summary!A626 -> 2027 | B622: =Summary!B626 -> Unconditional | C622: =Summary!C626 -> Gas Recovery Revenue (Low, $4/MMBtu) | D622: =Summary!D626 -> 190.20254 | E622: =Summary!E626 -> USD millions
A623: =Summary!A627 -> 2028 | B623: =Summary!B627 -> Unconditional | C623: =Summary!C627 -> Gas Recovery Revenue (Low, $4/MMBtu) | D623: =Summary!D627 -> 247.05343 | E623: =Summary!E627 -> USD millions
A624: =Summary!A628 -> 2029 | B624: =Summary!B628 -> Unconditional | C624: =Summary!C628 -> Gas Recovery Revenue (Low, $4/MMBtu) | D624: =Summary!D628 -> 307.6802 | E624: =Summary!E628 -> USD millions
A625: =Summary!A629 -> 2030 | B625: =Summary!B629 -> Unconditional | C625: =Summary!C629 -> Gas Recovery Revenue (Low, $4/MMBtu) | D625: =Summary!D629 -> 370.50295 | E625: =Summary!E629 -> USD millions
A626: =Summary!A630 -> 2031 | B626: =Summary!B630 -> Unconditional | C626: =Summary!C630 -> Gas Recovery Revenue (Low, $4/MMBtu) | D626: =Summary!D630 -> 443.23226 | E626: =Summary!E630 -> USD millions
A627: =Summary!A631 -> 2032 | B627: =Summary!B631 -> Unconditional | C627: =Summary!C631 -> Gas Recovery Revenue (Low, $4/MMBtu) | D627: =Summary!D631 -> 518.21893 | E627: =Summary!E631 -> USD millions
A628: =Summary!A632 -> 2033 | B628: =Summary!B632 -> Unconditional | C628: =Summary!C632 -> Gas Recovery Revenue (Low, $4/MMBtu) | D628: =Summary!D632 -> 594.56902 | E628: =Summary!E632 -> USD millions
A629: =Summary!A633 -> 2034 | B629: =Summary!B633 -> Unconditional | C629: =Summary!C633 -> Gas Recovery Revenue (Low, $4/MMBtu) | D629: =Summary!D633 -> 671.72679 | E629: =Summary!E633 -> USD millions
... A785: =Summary!A789 -> 2050 | B785: =Summary!B789 -> Conditional | C785: =Summary!C789 -> Gas Recovery Revenue (High, $12/MMBtu) | D785: =Summary!D789 -> 15125.115 | E785: =Summary!E789 -> USD millions

Sheet Sheet1
