Workbook

Sheet Assumptions
A1: Conversion Assumptions: MtCO2e -> MMcfd
A3: Parameter | B3: Value | C3: Unit | D3: Source / Note
A4: GWP100 CH4 (AR5) | B4: 28 | C4: kg CO2e / kg CH4 | D4: IPCC AR5 WG1 Ch.8, Table 8.7
A5: CH4 share - Fugitive | B5: 0.95 | C5: fraction | D5: IPCC 2006 GL Vol.2 Ch.4 - typical natural gas
A6: CH4 share - Venting | B6: 0.95 | C6: fraction | D6: IPCC 2006 GL Vol.2 Ch.4 - typical natural gas
A7: CH4 density (std cond.) | B7: 0.0191 | C7: kg/scf | D7: At 60F, 14.73 psia (US standard)
A8: Natural gas density (std cond.) | B8: 0.0416 | C8: kg/scf | D8: Avg. specific gravity ~0.65
A9: CO2 emission factor - flaring (NG) | B9: 0.0315 | C9: kg CO2 / scf NG | D9: Calibrated from BAU flaring reference 2023-2030 (mean implied EF)
A10: Days per year | B10: 365 | C10: days | D10: Annual -> daily conversion
A11: Mt to kg conversion | B11: 1000000000 | C11: kg / Mt | D11: 1 Mt = 1e9 kg
A12: scf to MMcf | B12: 1000000 | C12: scf / MMcf | D12: 1 MMcf = 1e6 scf
A14: Methodology
A15: FUGITIVE & VENTING (CH4-driven):
A16: MMcfd = (MtCO2e * Mt2kg) / GWP100 / CH4_share / NG_density / scf2MMcf / Days
A17: CO2e -> kg CH4 -> kg natural gas (uncombusted) -> scf NG -> MMcf -> per day
A19: FLARING (CO2 from gas combustion):
A20: MMcfd = (MtCO2 * Mt2kg) / EF_flare / scf2MMcf / Days
A21: CO2 emitted -> scf NG burned -> MMcf -> per day
A23: GAS RECOVERY: CH4-rich captured gas, conversion identical to Fugitive (95% CH4)
A24: NOTE: Flaring EF calibrated to BAU reference curve (mean 2023-2030). Implied EF varies 0.028-0.034 across years; single-value calibration introduces ~5-10% deviation at endpoints.
A26: GAS RECOVERY (UPDATED): computed as volumetric residual = BAU total volume - (F+V+Fl) of scenario. This enforces mass conservation: total gas associated with oil production is invariant across scenarios; only its destination changes.

Sheet MMcfd
A1: Volumetric estimates (MMcfd)
A2: BAU | F2: Unconditional | L2: Conditional
A3: Metric | B3: Fugitive | C3: Venting | D3: Flaring | F3: Year | G3: Fugitive | H3: Venting | I3: Flaring | J3: Gas Recovery | L3: Year | M3: Fugitive | N3: Venting | O3: Flaring | P3: Gas Recovery
A4: 2023 | B4: =(SISEPUEDE!B4*Assumptions!$B$11)/Assumptions!$B$4/Assumptions!$B$5/Assumptions!$B$8/Assumptions!$B$12/Assumptions!$B$10 -> 12.56865 | C4: =(SISEPUEDE!C4*Assumptions!$B$11)/Assumptions!$B$4/Assumptions!$B$6/Assumptions!$B$8/Assumptions!$B$12/Assumptions!$B$10 -> 38.832564 | D4: =(SISEPUEDE!D4*Assumptions!$B$11)/Assumptions!$B$9/Assumptions!$B$12/Assumptions!$B$10 -> 545.10435 | F4: 2023 | G4: =(SISEPUEDE!G4*Assumptions!$B$11)/Assumptions!$B$4/Assumptions!$B$5/Assumptions!$B$8/Assumptions!$B$12/Assumptions!$B$10 -> 12.56865 | H4: =(SISEPUEDE!H4*Assumptions!$B$11)/Assumptions!$B$4/Assumptions!$B$6/Assumptions!$B$8/Assumptions!$B$12/Assumptions!$B$10 -> 38.832564 | I4: =(SISEPUEDE!I4*Assumptions!$B$11)/Assumptions!$B$9/Assumptions!$B$12/Assumptions!$B$10 -> 545.10435 | J4: =(B4+C4+D4)-(G4+H4+I4) -> 0 | L4: 2023 | M4: =(SISEPUEDE!M4*Assumptions!$B$11)/Assumptions!$B$4/Assumptions!$B$5/Assumptions!$B$8/Assumptions!$B$12/Assumptions!$B$10 -> 12.56865 | N4: =(SISEPUEDE!N4*Assumptions!$B$11)/Assumptions!$B$4/Assumptions!$B$6/Assumptions!$B$8/Assumptions!$B$12/Assumptions!$B$10 -> 38.832564 | O4: =(SISEPUEDE!O4*Assumptions!$B$11)/Assumptions!$B$9/Assumptions!$B$12/Assumptions!$B$10 -> 545.10435 | P4: =(B4+C4+D4)-(M4+N4+O4) -> 0
A5: 2024 | B5: =(SISEPUEDE!B5*Assumptions!$B$11)/Assumptions!$B$4/Assumptions!$B$5/Assumptions!$B$8/Assumptions!$B$12/Assumptions!$B$10 -> 12.47127 | C5: =(SISEPUEDE!C5*Assumptions!$B$11)/Assumptions!$B$4/Assumptions!$B$6/Assumptions!$B$8/Assumptions!$B$12/Assumptions!$B$10 -> 38.546117 | D5: =(SISEPUEDE!D5*Assumptions!$B$11)/Assumptions!$B$9/Assumptions!$B$12/Assumptions!$B$10 -> 620.88214 | F5: 2024 | G5: =(SISEPUEDE!G5*Assumptions!$B$11)/Assumptions!$B$4/Assumptions!$B$5/Assumptions!$B$8/Assumptions!$B$12/Assumptions!$B$10 -> 12.270128 | H5: =(SISEPUEDE!H5*Assumptions!$B$11)/Assumptions!$B$4/Assumptions!$B$6/Assumptions!$B$8/Assumptions!$B$12/Assumptions!$B$10 -> 40.719772 | I5: =(SISEPUEDE!I5*Assumptions!$B$11)/Assumptions!$B$9/Assumptions!$B$12/Assumptions!$B$10 -> 513.87432 | J5: =(B5+C5+D5)-(G5+H5+I5) -> 105.03531 | L5: 2024 | M5: =(SISEPUEDE!M5*Assumptions!$B$11)/Assumptions!$B$4/Assumptions!$B$5/Assumptions!$B$8/Assumptions!$B$12/Assumptions!$B$10 -> 12.779042 | N5: =(SISEPUEDE!N5*Assumptions!$B$11)/Assumptions!$B$4/Assumptions!$B$6/Assumptions!$B$8/Assumptions!$B$12/Assumptions!$B$10 -> 37.114114 | O5: =(SISEPUEDE!O5*Assumptions!$B$11)/Assumptions!$B$9/Assumptions!$B$12/Assumptions!$B$10 -> 545.96875 | P5: =(B5+C5+D5)-(M5+N5+O5) -> 76.037625
A6: 2025 | B6: =(SISEPUEDE!B6*Assumptions!$B$11)/Assumptions!$B$4/Assumptions!$B$5/Assumptions!$B$8/Assumptions!$B$12/Assumptions!$B$10 -> 12.372005 | C6: =(SISEPUEDE!C6*Assumptions!$B$11)/Assumptions!$B$4/Assumptions!$B$6/Assumptions!$B$8/Assumptions!$B$12/Assumptions!$B$10 -> 38.253046 | D6: =(SISEPUEDE!D6*Assumptions!$B$11)/Assumptions!$B$9/Assumptions!$B$12/Assumptions!$B$10 -> 696.71901 | F6: 2025 | G6: =(SISEPUEDE!G6*Assumptions!$B$11)/Assumptions!$B$4/Assumptions!$B$5/Assumptions!$B$8/Assumptions!$B$12/Assumptions!$B$10 -> 11.969823 | H6: =(SISEPUEDE!H6*Assumptions!$B$11)/Assumptions!$B$4/Assumptions!$B$6/Assumptions!$B$8/Assumptions!$B$12/Assumptions!$B$10 -> 42.599371 | I6: =(SISEPUEDE!I6*Assumptions!$B$11)/Assumptions!$B$9/Assumptions!$B$12/Assumptions!$B$10 -> 482.66049 | J6: =(B6+C6+D6)-(G6+H6+I6) -> 210.11438 | L6: 2025 | M6: =(SISEPUEDE!M6*Assumptions!$B$11)/Assumptions!$B$4/Assumptions!$B$5/Assumptions!$B$8/Assumptions!$B$12/Assumptions!$B$10 -> 12.212613 | N6: =(SISEPUEDE!N6*Assumptions!$B$11)/Assumptions!$B$4/Assumptions!$B$6/Assumptions!$B$8/Assumptions!$B$12/Assumptions!$B$10 -> 37.117897 | O6: =(SISEPUEDE!O6*Assumptions!$B$11)/Assumptions!$B$9/Assumptions!$B$12/Assumptions!$B$10 -> 513.22005 | P6: =(B6+C6+D6)-(M6+N6+O6) -> 184.7935
A7: 2026 | B7: =(SISEPUEDE!B7*Assumptions!$B$11)/Assumptions!$B$4/Assumptions!$B$5/Assumptions!$B$8/Assumptions!$B$12/Assumptions!$B$10 -> 12.266806 | C7: =(SISEPUEDE!C7*Assumptions!$B$11)/Assumptions!$B$4/Assumptions!$B$6/Assumptions!$B$8/Assumptions!$B$12/Assumptions!$B$10 -> 37.939115 | D7: =(SISEPUEDE!D7*Assumptions!$B$11)/Assumptions!$B$9/Assumptions!$B$12/Assumptions!$B$10 -> 772.67077 | F7: 2026 | G7: =(SISEPUEDE!G7*Assumptions!$B$11)/Assumptions!$B$4/Assumptions!$B$5/Assumptions!$B$8/Assumptions!$B$12/Assumptions!$B$10 -> 11.664019 | H7: =(SISEPUEDE!H7*Assumptions!$B$11)/Assumptions!$B$4/Assumptions!$B$6/Assumptions!$B$8/Assumptions!$B$12/Assumptions!$B$10 -> 44.454793 | I7: =(SISEPUEDE!I7*Assumptions!$B$11)/Assumptions!$B$9/Assumptions!$B$12/Assumptions!$B$10 -> 451.47395 | J7: =(B7+C7+D7)-(G7+H7+I7) -> 315.28393 | L7: 2026 | M7: =(SISEPUEDE!M7*Assumptions!$B$11)/Assumptions!$B$4/Assumptions!$B$5/Assumptions!$B$8/Assumptions!$B$12/Assumptions!$B$10 -> 11.640045 | N7: =(SISEPUEDE!N7*Assumptions!$B$11)/Assumptions!$B$4/Assumptions!$B$6/Assumptions!$B$8/Assumptions!$B$12/Assumptions!$B$10 -> 37.093065 | O7: =(SISEPUEDE!O7*Assumptions!$B$11)/Assumptions!$B$9/Assumptions!$B$12/Assumptions!$B$10 -> 480.46099 | P7: =(B7+C7+D7)-(M7+N7+O7) -> 293.68259
A8: 2027 | B8: =(SISEPUEDE!B8*Assumptions!$B$11)/Assumptions!$B$4/Assumptions!$B$5/Assumptions!$B$8/Assumptions!$B$12/Assumptions!$B$10 -> 12.150937 | C8: =(SISEPUEDE!C8*Assumptions!$B$11)/Assumptions!$B$4/Assumptions!$B$6/Assumptions!$B$8/Assumptions!$B$12/Assumptions!$B$10 -> 37.587121 | D8: =(SISEPUEDE!D8*Assumptions!$B$11)/Assumptions!$B$9/Assumptions!$B$12/Assumptions!$B$10 -> 848.8053 | F8: 2027 | G8: =(SISEPUEDE!G8*Assumptions!$B$11)/Assumptions!$B$4/Assumptions!$B$5/Assumptions!$B$8/Assumptions!$B$12/Assumptions!$B$10 -> 11.348665 | H8: =(SISEPUEDE!H8*Assumptions!$B$11)/Assumptions!$B$4/Assumptions!$B$6/Assumptions!$B$8/Assumptions!$B$12/Assumptions!$B$10 -> 46.265194 | I8: =(SISEPUEDE!I8*Assumptions!$B$11)/Assumptions!$B$9/Assumptions!$B$12/Assumptions!$B$10 -> 420.36693 | J8: =(B8+C8+D8)-(G8+H8+I8) -> 420.56257 | L8: 2027 | M8: =(SISEPUEDE!M8*Assumptions!$B$11)/Assumptions!$B$4/Assumptions!$B$5/Assumptions!$B$8/Assumptions!$B$12/Assumptions!$B$10 -> 11.057855 | N8: =(SISEPUEDE!N8*Assumptions!$B$11)/Assumptions!$B$4/Assumptions!$B$6/Assumptions!$B$8/Assumptions!$B$12/Assumptions!$B$10 -> 37.014143 | O8: =(SISEPUEDE!O8*Assumptions!$B$11)/Assumptions!$B$9/Assumptions!$B$12/Assumptions!$B$10 -> 447.76661 | P8: =(B8+C8+D8)-(M8+N8+O8) -> 402.70475
A9: 2028 | B9: =(SISEPUEDE!B9*Assumptions!$B$11)/Assumptions!$B$4/Assumptions!$B$5/Assumptions!$B$8/Assumptions!$B$12/Assumptions!$B$10 -> 12.019417 | C9: =(SISEPUEDE!C9*Assumptions!$B$11)/Assumptions!$B$4/Assumptions!$B$6/Assumptions!$B$8/Assumptions!$B$12/Assumptions!$B$10 -> 37.179001 | D9: =(SISEPUEDE!D9*Assumptions!$B$11)/Assumptions!$B$9/Assumptions!$B$12/Assumptions!$B$10 -> 925.18284 | F9: 2028 | G9: =(SISEPUEDE!G9*Assumptions!$B$11)/Assumptions!$B$4/Assumptions!$B$5/Assumptions!$B$8/Assumptions!$B$12/Assumptions!$B$10 -> 11.019767 | H9: =(SISEPUEDE!H9*Assumptions!$B$11)/Assumptions!$B$4/Assumptions!$B$6/Assumptions!$B$8/Assumptions!$B$12/Assumptions!$B$10 -> 48.006966 | I9: =(SISEPUEDE!I9*Assumptions!$B$11)/Assumptions!$B$9/Assumptions!$B$12/Assumptions!$B$10 -> 389.43645 | J9: =(B9+C9+D9)-(G9+H9+I9) -> 525.91807 | L9: 2028 | M9: =(SISEPUEDE!M9*Assumptions!$B$11)/Assumptions!$B$4/Assumptions!$B$5/Assumptions!$B$8/Assumptions!$B$12/Assumptions!$B$10 -> 10.463027 | N9: =(SISEPUEDE!N9*Assumptions!$B$11)/Assumptions!$B$4/Assumptions!$B$6/Assumptions!$B$8/Assumptions!$B$12/Assumptions!$B$10 -> 36.852799 | O9: =(SISEPUEDE!O9*Assumptions!$B$11)/Assumptions!$B$9/Assumptions!$B$12/Assumptions!$B$10 -> 415.2641 | P9: =(B9+C9+D9)-(M9+N9+O9) -> 511.80133
A10: 2029 | B10: =(SISEPUEDE!B10*Assumptions!$B$11)/Assumptions!$B$4/Assumptions!$B$5/Assumptions!$B$8/Assumptions!$B$12/Assumptions!$B$10 -> 11.867428 | C10: =(SISEPUEDE!C10*Assumptions!$B$11)/Assumptions!$B$4/Assumptions!$B$6/Assumptions!$B$8/Assumptions!$B$12/Assumptions!$B$10 -> 36.697955 | D10: =(SISEPUEDE!D10*Assumptions!$B$11)/Assumptions!$B$9/Assumptions!$B$12/Assumptions!$B$10 -> 1001.8362 | F10: 2029 | G10: =(SISEPUEDE!G10*Assumptions!$B$11)/Assumptions!$B$4/Assumptions!$B$5/Assumptions!$B$8/Assumptions!$B$12/Assumptions!$B$10 -> 10.673724 | H10: =(SISEPUEDE!H10*Assumptions!$B$11)/Assumptions!$B$4/Assumptions!$B$6/Assumptions!$B$8/Assumptions!$B$12/Assumptions!$B$10 -> 49.655319 | I10: =(SISEPUEDE!I10*Assumptions!$B$11)/Assumptions!$B$9/Assumptions!$B$12/Assumptions!$B$10 -> 358.82422 | J10: =(B10+C10+D10)-(G10+H10+I10) -> 631.24836 | L10: 2029 | M10: =(SISEPUEDE!M10*Assumptions!$B$11)/Assumptions!$B$4/Assumptions!$B$5/Assumptions!$B$8/Assumptions!$B$12/Assumptions!$B$10 -> 9.8532972 | N10: =(SISEPUEDE!N10*Assumptions!$B$11)/Assumptions!$B$4/Assumptions!$B$6/Assumptions!$B$8/Assumptions!$B$12/Assumptions!$B$10 -> 36.579778 | O10: =(SISEPUEDE!O10*Assumptions!$B$11)/Assumptions!$B$9/Assumptions!$B$12/Assumptions!$B$10 -> 383.12825 | P10: =(B10+C10+D10)-(M10+N10+O10) -> 620.8403
A11: 2030 | B11: =(SISEPUEDE!B11*Assumptions!$B$11)/Assumptions!$B$4/Assumptions!$B$5/Assumptions!$B$8/Assumptions!$B$12/Assumptions!$B$10 -> 11.690689 | C11: =(SISEPUEDE!C11*Assumptions!$B$11)/Assumptions!$B$4/Assumptions!$B$6/Assumptions!$B$8/Assumptions!$B$12/Assumptions!$B$10 -> 36.129424 | D11: =(SISEPUEDE!D11*Assumptions!$B$11)/Assumptions!$B$9/Assumptions!$B$12/Assumptions!$B$10 -> 1078.7822 | F11: 2030 | G11: =(SISEPUEDE!G11*Assumptions!$B$11)/Assumptions!$B$4/Assumptions!$B$5/Assumptions!$B$8/Assumptions!$B$12/Assumptions!$B$10 -> 10.30762 | H11: =(SISEPUEDE!H11*Assumptions!$B$11)/Assumptions!$B$4/Assumptions!$B$6/Assumptions!$B$8/Assumptions!$B$12/Assumptions!$B$10 -> 51.18594 | I11: =(SISEPUEDE!I11*Assumptions!$B$11)/Assumptions!$B$9/Assumptions!$B$12/Assumptions!$B$10 -> 328.71316 | J11: =(B11+C11+D11)-(G11+H11+I11) -> 736.3956 | L11: 2030 | M11: =(SISEPUEDE!M11*Assumptions!$B$11)/Assumptions!$B$4/Assumptions!$B$5/Assumptions!$B$8/Assumptions!$B$12/Assumptions!$B$10 -> 9.227354 | N11: =(SISEPUEDE!N11*Assumptions!$B$11)/Assumptions!$B$4/Assumptions!$B$6/Assumptions!$B$8/Assumptions!$B$12/Assumptions!$B$10 -> 36.166795 | O11: =(SISEPUEDE!O11*Assumptions!$B$11)/Assumptions!$B$9/Assumptions!$B$12/Assumptions!$B$10 -> 351.57354 | P11: =(B11+C11+D11)-(M11+N11+O11) -> 729.63463
A12: 2031 | B12: =(SISEPUEDE!B12*Assumptions!$B$11)/Assumptions!$B$4/Assumptions!$B$5/Assumptions!$B$8/Assumptions!$B$12/Assumptions!$B$10 -> 11.485772 | C12: =(SISEPUEDE!C12*Assumptions!$B$11)/Assumptions!$B$4/Assumptions!$B$6/Assumptions!$B$8/Assumptions!$B$12/Assumptions!$B$10 -> 35.461997 | D12: =(SISEPUEDE!D12*Assumptions!$B$11)/Assumptions!$B$9/Assumptions!$B$12/Assumptions!$B$10 -> 1156.0359 | F12: 2031 | G12: =(SISEPUEDE!G12*Assumptions!$B$11)/Assumptions!$B$4/Assumptions!$B$5/Assumptions!$B$8/Assumptions!$B$12/Assumptions!$B$10 -> 9.9194542 | H12: =(SISEPUEDE!H12*Assumptions!$B$11)/Assumptions!$B$4/Assumptions!$B$6/Assumptions!$B$8/Assumptions!$B$12/Assumptions!$B$10 -> 52.576736 | I12: =(SISEPUEDE!I12*Assumptions!$B$11)/Assumptions!$B$9/Assumptions!$B$12/Assumptions!$B$10 -> 299.32029 | J12: =(B12+C12+D12)-(G12+H12+I12) -> 841.16717 | L12: 2031 | M12: =(SISEPUEDE!M12*Assumptions!$B$11)/Assumptions!$B$4/Assumptions!$B$5/Assumptions!$B$8/Assumptions!$B$12/Assumptions!$B$10 -> 8.5849711 | N12: =(SISEPUEDE!N12*Assumptions!$B$11)/Assumptions!$B$4/Assumptions!$B$6/Assumptions!$B$8/Assumptions!$B$12/Assumptions!$B$10 -> 35.588385 | O12: =(SISEPUEDE!O12*Assumptions!$B$11)/Assumptions!$B$9/Assumptions!$B$12/Assumptions!$B$10 -> 320.84334 | P12: =(B12+C12+D12)-(M12+N12+O12) -> 837.96695
A13: 2032 | B13: =(SISEPUEDE!B13*Assumptions!$B$11)/Assumptions!$B$4/Assumptions!$B$5/Assumptions!$B$8/Assumptions!$B$12/Assumptions!$B$10 -> 11.25042 | C13: =(SISEPUEDE!C13*Assumptions!$B$11)/Assumptions!$B$4/Assumptions!$B$6/Assumptions!$B$8/Assumptions!$B$12/Assumptions!$B$10 -> 34.68824 | D13: =(SISEPUEDE!D13*Assumptions!$B$11)/Assumptions!$B$9/Assumptions!$B$12/Assumptions!$B$10 -> 1233.6293 | F13: 2032 | G13: =(SISEPUEDE!G13*Assumptions!$B$11)/Assumptions!$B$4/Assumptions!$B$5/Assumptions!$B$8/Assumptions!$B$12/Assumptions!$B$10 -> 9.5083555 | H13: =(SISEPUEDE!H13*Assumptions!$B$11)/Assumptions!$B$4/Assumptions!$B$6/Assumptions!$B$8/Assumptions!$B$12/Assumptions!$B$10 -> 53.809653 | I13: =(SISEPUEDE!I13*Assumptions!$B$11)/Assumptions!$B$9/Assumptions!$B$12/Assumptions!$B$10 -> 270.88658 | J13: =(B13+C13+D13)-(G13+H13+I13) -> 945.36335 | L13: 2032 | M13: =(SISEPUEDE!M13*Assumptions!$B$11)/Assumptions!$B$4/Assumptions!$B$5/Assumptions!$B$8/Assumptions!$B$12/Assumptions!$B$10 -> 7.9271124 | N13: =(SISEPUEDE!N13*Assumptions!$B$11)/Assumptions!$B$4/Assumptions!$B$6/Assumptions!$B$8/Assumptions!$B$12/Assumptions!$B$10 -> 34.82368 | O13: =(SISEPUEDE!O13*Assumptions!$B$11)/Assumptions!$B$9/Assumptions!$B$12/Assumptions!$B$10 -> 291.19685 | P13: =(B13+C13+D13)-(M13+N13+O13) -> 945.62029
A14: 2033 | B14: =(SISEPUEDE!B14*Assumptions!$B$11)/Assumptions!$B$4/Assumptions!$B$5/Assumptions!$B$8/Assumptions!$B$12/Assumptions!$B$10 -> 10.983387 | C14: =(SISEPUEDE!C14*Assumptions!$B$11)/Assumptions!$B$4/Assumptions!$B$6/Assumptions!$B$8/Assumptions!$B$12/Assumptions!$B$10 -> 33.804154 | D14: =(SISEPUEDE!D14*Assumptions!$B$11)/Assumptions!$B$9/Assumptions!$B$12/Assumptions!$B$10 -> 1311.6052 | F14: 2033 | G14: =(SISEPUEDE!G14*Assumptions!$B$11)/Assumptions!$B$4/Assumptions!$B$5/Assumptions!$B$8/Assumptions!$B$12/Assumptions!$B$10 -> 9.0743729 | H14: =(SISEPUEDE!H14*Assumptions!$B$11)/Assumptions!$B$4/Assumptions!$B$6/Assumptions!$B$8/Assumptions!$B$12/Assumptions!$B$10 -> 54.870767 | I14: =(SISEPUEDE!I14*Assumptions!$B$11)/Assumptions!$B$9/Assumptions!$B$12/Assumptions!$B$10 -> 243.65591 | J14: =(B14+C14+D14)-(G14+H14+I14) -> 1048.7917 | L14: 2033 | M14: =(SISEPUEDE!M14*Assumptions!$B$11)/Assumptions!$B$4/Assumptions!$B$5/Assumptions!$B$8/Assumptions!$B$12/Assumptions!$B$10 -> 7.2556323 | N14: =(SISEPUEDE!N14*Assumptions!$B$11)/Assumptions!$B$4/Assumptions!$B$6/Assumptions!$B$8/Assumptions!$B$12/Assumptions!$B$10 -> 33.856612 | O14: =(SISEPUEDE!O14*Assumptions!$B$11)/Assumptions!$B$9/Assumptions!$B$12/Assumptions!$B$10 -> 262.88668 | P14: =(B14+C14+D14)-(M14+N14+O14) -> 1052.3938
A15: 2034 | B15: =(SISEPUEDE!B15*Assumptions!$B$11)/Assumptions!$B$4/Assumptions!$B$5/Assumptions!$B$8/Assumptions!$B$12/Assumptions!$B$10 -> 10.684291 | C15: =(SISEPUEDE!C15*Assumptions!$B$11)/Assumptions!$B$4/Assumptions!$B$6/Assumptions!$B$8/Assumptions!$B$12/Assumptions!$B$10 -> 32.80867 | D15: =(SISEPUEDE!D15*Assumptions!$B$11)/Assumptions!$B$9/Assumptions!$B$12/Assumptions!$B$10 -> 1390.012 | F15: 2034 | G15: =(SISEPUEDE!G15*Assumptions!$B$11)/Assumptions!$B$4/Assumptions!$B$5/Assumptions!$B$8/Assumptions!$B$12/Assumptions!$B$10 -> 8.6182791 | H15: =(SISEPUEDE!H15*Assumptions!$B$11)/Assumptions!$B$4/Assumptions!$B$6/Assumptions!$B$8/Assumptions!$B$12/Assumptions!$B$10 -> 55.75043 | I15: =(SISEPUEDE!I15*Assumptions!$B$11)/Assumptions!$B$9/Assumptions!$B$12/Assumptions!$B$10 -> 217.85421 | J15: =(B15+C15+D15)-(G15+H15+I15) -> 1151.282 | L15: 2034 | M15: =(SISEPUEDE!M15*Assumptions!$B$11)/Assumptions!$B$4/Assumptions!$B$5/Assumptions!$B$8/Assumptions!$B$12/Assumptions!$B$10 -> 6.5730037 | N15: =(SISEPUEDE!N15*Assumptions!$B$11)/Assumptions!$B$4/Assumptions!$B$6/Assumptions!$B$8/Assumptions!$B$12/Assumptions!$B$10 -> 32.676088 | O15: =(SISEPUEDE!O15*Assumptions!$B$11)/Assumptions!$B$9/Assumptions!$B$12/Assumptions!$B$10 -> 236.138 | P15: =(B15+C15+D15)-(M15+N15+O15) -> 1158.1179
... A31: 2050 | B31: =(SISEPUEDE!B31*Assumptions!$B$11)/Assumptions!$B$4/Assumptions!$B$5/Assumptions!$B$8/Assumptions!$B$12/Assumptions!$B$10 -> 3.4638823 | C31: =(SISEPUEDE!C31*Assumptions!$B$11)/Assumptions!$B$4/Assumptions!$B$6/Assumptions!$B$8/Assumptions!$B$12/Assumptions!$B$10 -> 8.4183078 | D31: =(SISEPUEDE!D31*Assumptions!$B$11)/Assumptions!$B$9/Assumptions!$B$12/Assumptions!$B$10 -> 2627.6805 | F31: 2050 | G31: =(SISEPUEDE!G31*Assumptions!$B$11)/Assumptions!$B$4/Assumptions!$B$5/Assumptions!$B$8/Assumptions!$B$12/Assumptions!$B$10 -> 0.31867833 | H31: =(SISEPUEDE!H31*Assumptions!$B$11)/Assumptions!$B$4/Assumptions!$B$6/Assumptions!$B$8/Assumptions!$B$12/Assumptions!$B$10 -> 49.61741 | I31: =(SISEPUEDE!I31*Assumptions!$B$11)/Assumptions!$B$9/Assumptions!$B$12/Assumptions!$B$10 -> 24.795532 | J31: =(B31+C31+D31)-(G31+H31+I31) -> 2564.8311 | L31: 2050 | M31: =(SISEPUEDE!M31*Assumptions!$B$11)/Assumptions!$B$4/Assumptions!$B$5/Assumptions!$B$8/Assumptions!$B$12/Assumptions!$B$10 -> 0 | N31: =(SISEPUEDE!N31*Assumptions!$B$11)/Assumptions!$B$4/Assumptions!$B$6/Assumptions!$B$8/Assumptions!$B$12/Assumptions!$B$10 -> 0 | O31: =(SISEPUEDE!O31*Assumptions!$B$11)/Assumptions!$B$9/Assumptions!$B$12/Assumptions!$B$10 -> 1.7348026 | P31: =(B31+C31+D31)-(M31+N31+O31) -> 2637.8279
A33: Units: MMcfd (million standard cubic feet per day). See Assumptions sheet for parameters and methodology.

Sheet SISEPUEDE
A1: MTCO2
A2: BAU | F2: Unconditional | L2: Conditional
A3: Metric | B3: Fugitive | C3: Venting | D3: Flaring | G3: Fugitive | H3: Venting | I3: Flaring | J3: Gas Recovery | M3: Fugitive | N3: Venting | O3: Flaring | P3: Gas Recovery
A4: 2023 | B4: 5.0764074 | C4: 15.684255 | D4: 6.2673373 | F4: 2023 | G4: 5.0764074 | H4: 15.684255 | I4: 6.2673373 | J4: 0 | L4: 2023 | M4: 5.0764074 | N4: 15.684255 | O4: 6.2673373 | P4: 0
A5: 2024 | B5: 5.0370762 | C5: 15.568561 | D5: 7.1385925 | E5: 27.74423 | F5: 2024 | G5: 4.9558359 | H5: 16.446488 | I5: 5.90827 | J5: 0 | K5: 27.310594 | L5: 2024 | M5: 5.1613834 | N5: 14.990183 | O5: 6.2772757 | P5: 0 | Q5: 26.428842
A6: 2025 | B6: 4.9969835 | C6: 15.450191 | D6: 8.0105268 | E6: 28.457701 | F6: 2025 | G6: 4.8345444 | H6: 17.205647 | I6: 5.5493889 | J6: =+SUM(B6:D6)-SUM(G6:I6) -> 0.86812081 | K6: 27.589581 | L6: 2025 | M6: 4.932606 | N6: 14.991711 | O6: 5.9007475 | P6: =+SUM(B6:D6)-SUM(M6:O6) -> 2.6326371 | Q6: 25.825064
A7: 2026 | B7: 4.9544942 | C7: 15.323396 | D7: 8.8837822 | E7: 29.161672 | F7: 2026 | G7: 4.7110318 | H7: 17.955042 | I7: 5.1908217 | J7: =+SUM(B7:D7)-SUM(G7:I7) -> 1.3047768 | K7: 27.856896 | L7: 2026 | M7: 4.7013491 | N7: 14.981681 | O7: 5.5241003 | P7: =+SUM(B7:D7)-SUM(M7:O7) -> 3.9545417 | Q7: 25.207131
A8: 2027 | B8: 4.9076953 | C8: 15.181228 | D8: 9.7591389 | E8: 29.848062 | F8: 2027 | G8: 4.5836623 | H8: 18.686253 | I8: 4.8331688 | J8: =+SUM(B8:D8)-SUM(G8:I8) -> 1.7449783 | K8: 28.103084 | L8: 2027 | M8: 4.4662056 | N8: 14.949805 | O8: 5.1481966 | P8: =+SUM(B8:D8)-SUM(M8:O8) -> 5.2838549 | Q8: 24.564207
A9: 2028 | B9: 4.8545752 | C9: 15.01639 | D9: 10.63729 | E9: 30.508255 | F9: 2028 | G9: 4.4508221 | H9: 19.389745 | I9: 4.4775456 | J9: =+SUM(B9:D9)-SUM(G9:I9) -> 2.1901427 | K9: 28.318113 | L9: 2028 | M9: 4.225958 | N9: 14.884639 | O9: 4.774499 | P9: =+SUM(B9:D9)-SUM(M9:O9) -> 6.6231591 | Q9: 23.885096
A10: 2029 | B10: 4.7931879 | C10: 14.822098 | D10: 11.518612 | E10: 31.133898 | F10: 2029 | G10: 4.3110573 | H10: 20.055505 | I10: 4.1255815 | J10: =+SUM(B10:D10)-SUM(G10:I10) -> 2.6417543 | K10: 28.492144 | L10: 2029 | M10: 3.9796915 | N10: 14.774367 | O10: 4.4050171 | P10: =+SUM(B10:D10)-SUM(M10:O10) -> 7.9748226 | Q10: 23.159076
A11: 2030 | B11: 4.7218037 | C11: 14.592472 | D11: 12.403298 | E11: 31.717574 | F11: 2030 | G11: 4.1631901 | H11: 20.673715 | I11: 3.7793796 | J11: =+SUM(B11:D11)-SUM(G11:I11) -> 3.1012899 | K11: 28.616284 | L11: 2030 | M11: 3.7268766 | N11: 14.607566 | O11: 4.0422168 | P11: =+SUM(B11:D11)-SUM(M11:O11) -> 9.3409149 | Q11: 22.376659
A12: 2031 | B12: 4.639039 | C12: 14.322902 | D12: 13.291523 | E12: 32.253464 | F12: 2031 | G12: 4.006412 | H12: 21.235449 | I12: 3.441435 | J12: =+SUM(B12:D12)-SUM(G12:I12) -> 3.5701673 | K12: 28.683296 | L12: 2031 | M12: 3.4674217 | N12: 14.373949 | O12: 3.6888963 | P12: =+SUM(B12:D12)-SUM(M12:O12) -> 10.723196 | Q12: 21.530267
A13: 2032 | B13: 4.5439818 | C13: 14.010386 | D13: 14.183653 | E13: 32.73802 | F13: 2032 | G13: 3.8403716 | H13: 21.733417 | I13: 3.1145184 | J13: =+SUM(B13:D13)-SUM(G13:I13) -> 4.0497131 | K13: 28.688307 | L13: 2032 | M13: 3.2017163 | N13: 14.065089 | O13: 3.3480358 | P13: =+SUM(B13:D13)-SUM(M13:O13) -> 12.123179 | Q13: 20.614841
A14: 2033 | B14: 4.4361287 | C14: 13.653309 | D14: 15.080181 | E14: 33.169618 | F14: 2033 | G14: 3.6650884 | H14: 22.161996 | I14: 2.8014338 | J14: =+SUM(B14:D14)-SUM(G14:I14) -> 4.5411004 | K14: 28.628518 | L14: 2033 | M14: 2.9305093 | N14: 13.674496 | O14: 3.0225396 | P14: =+SUM(B14:D14)-SUM(M14:O14) -> 13.542073 | Q14: 19.627545
A15: 2034 | B15: 4.3153252 | C15: 13.251238 | D15: 15.981663 | E15: 33.548226 | F15: 2034 | G15: 3.4808747 | H15: 22.517286 | I15: 2.5047788 | J15: =+SUM(B15:D15)-SUM(G15:I15) -> 5.0452865 | K15: 28.50294 | L15: 2034 | M15: 2.6547994 | N15: 13.197689 | O15: 2.7149967 | P15: =+SUM(B15:D15)-SUM(M15:O15) -> 14.980741 | Q15: 18.567485
A16: 2035 | B16: 4.1817119 | C16: 12.804742 | D16: 16.888661 | E16: 33.875114 | F16: 2035 | G16: 3.2882648 | H16: 22.797194 | I16: 2.2267052 | J16: =+SUM(B16:D16)-SUM(G16:I16) -> 5.5629504 | K16: 28.312164 | L16: 2035 | M16: 2.3757375 | N16: 12.632258 | O16: 2.4274621 | P16: =+SUM(B16:D16)-SUM(M16:O16) -> 16.439657 | Q16: 17.435457
A17: 2036 | B17: 4.0356748 | C17: 12.315215 | D17: 17.801697 | E17: 34.152587 | F17: 2036 | G17: 3.0879527 | H17: 23.001525 | I17: 1.9686789 | J17: =+SUM(B17:D17)-SUM(G17:I17) -> 6.0944299 | K17: 28.058157 | L17: 2036 | M17: 2.0945395 | N17: 11.977918 | O17: 2.1612577 | P17: =+SUM(B17:D17)-SUM(M17:O17) -> 17.918871 | Q17: 16.233715
... A30: 2049 | B30: 1.3996045 | C30: 3.4014728 | D30: 30.22389 | E30: 35.024967 | F30: 2049 | G30: 0.13278569 | H30: 20.674397 | I30: 0.29410863 | J30: =+SUM(B30:D30)-SUM(G30:I30) -> 13.923676 | K30: 21.101291 | L30: 2049 | M30: 0 | N30: 0 | O30: 0.019945893 | P30: =+SUM(B30:D30)-SUM(M30:O30) -> 35.005021 | Q30: 0.019945893
A31: 2050 | B31: 1.3990427 | C31: 3.4001074 | D31: 30.211757 | E31: 35.010907 | F31: 2050 | G31: 0.12871239 | H31: 20.040194 | I31: 0.28508663 | J31: =+SUM(B30:D30)-SUM(G30:I30) -> 13.923676 | K31: 20.453993 | L31: 2050 | M31: 0 | N31: 0 | O31: 0.019945893 | P31: =+SUM(B30:D30)-SUM(M30:O30) -> 35.005021 | Q31: 0.019945893

Sheet Summary
A1: Long-format summary: emissions and volumetric estimates
A3: Year | B3: Strategy | C3: Category | D3: Value | E3: Unit | F3: Source | H3: BAU - MtCO2e
A4: 2023 | B4: BAU | C4: Fugitive | D4: =SISEPUEDE!B4 -> 5.0764074 | E4: MtCO2e | F4: SISEPUEDE | H4: Year | I4: Fugitive | J4: Venting | K4: Flaring
A5: 2024 | B5: BAU | C5: Fugitive | D5: =SISEPUEDE!B5 -> 5.0370762 | E5: MtCO2e | F5: SISEPUEDE | H5: 2023 | I5: =SISEPUEDE!B4 -> 5.0764074 | J5: =SISEPUEDE!C4 -> 15.684255 | K5: =SISEPUEDE!D4 -> 6.2673373
A6: 2025 | B6: BAU | C6: Fugitive | D6: =SISEPUEDE!B6 -> 4.9969835 | E6: MtCO2e | F6: SISEPUEDE | H6: 2024 | I6: =SISEPUEDE!B5 -> 5.0370762 | J6: =SISEPUEDE!C5 -> 15.568561 | K6: =SISEPUEDE!D5 -> 7.1385925
A7: 2026 | B7: BAU | C7: Fugitive | D7: =SISEPUEDE!B7 -> 4.9544942 | E7: MtCO2e | F7: SISEPUEDE | H7: 2025 | I7: =SISEPUEDE!B6 -> 4.9969835 | J7: =SISEPUEDE!C6 -> 15.450191 | K7: =SISEPUEDE!D6 -> 8.0105268
A8: 2027 | B8: BAU | C8: Fugitive | D8: =SISEPUEDE!B8 -> 4.9076953 | E8: MtCO2e | F8: SISEPUEDE | H8: 2026 | I8: =SISEPUEDE!B7 -> 4.9544942 | J8: =SISEPUEDE!C7 -> 15.323396 | K8: =SISEPUEDE!D7 -> 8.8837822
A9: 2028 | B9: BAU | C9: Fugitive | D9: =SISEPUEDE!B9 -> 4.8545752 | E9: MtCO2e | F9: SISEPUEDE | H9: 2027 | I9: =SISEPUEDE!B8 -> 4.9076953 | J9: =SISEPUEDE!C8 -> 15.181228 | K9: =SISEPUEDE!D8 -> 9.7591389
A10: 2029 | B10: BAU | C10: Fugitive | D10: =SISEPUEDE!B10 -> 4.7931879 | E10: MtCO2e | F10: SISEPUEDE | H10: 2028 | I10: =SISEPUEDE!B9 -> 4.8545752 | J10: =SISEPUEDE!C9 -> 15.01639 | K10: =SISEPUEDE!D9 -> 10.63729
A11: 2030 | B11: BAU | C11: Fugitive | D11: =SISEPUEDE!B11 -> 4.7218037 | E11: MtCO2e | F11: SISEPUEDE | H11: 2029 | I11: =SISEPUEDE!B10 -> 4.7931879 | J11: =SISEPUEDE!C10 -> 14.822098 | K11: =SISEPUEDE!D10 -> 11.518612
A12: 2031 | B12: BAU | C12: Fugitive | D12: =SISEPUEDE!B12 -> 4.639039 | E12: MtCO2e | F12: SISEPUEDE | H12: 2030 | I12: =SISEPUEDE!B11 -> 4.7218037 | J12: =SISEPUEDE!C11 -> 14.592472 | K12: =SISEPUEDE!D11 -> 12.403298
A13: 2032 | B13: BAU | C13: Fugitive | D13: =SISEPUEDE!B13 -> 4.5439818 | E13: MtCO2e | F13: SISEPUEDE | H13: 2031 | I13: =SISEPUEDE!B12 -> 4.639039 | J13: =SISEPUEDE!C12 -> 14.322902 | K13: =SISEPUEDE!D12 -> 13.291523
A14: 2033 | B14: BAU | C14: Fugitive | D14: =SISEPUEDE!B14 -> 4.4361287 | E14: MtCO2e | F14: SISEPUEDE | H14: 2032 | I14: =SISEPUEDE!B13 -> 4.5439818 | J14: =SISEPUEDE!C13 -> 14.010386 | K14: =SISEPUEDE!D13 -> 14.183653
A15: 2034 | B15: BAU | C15: Fugitive | D15: =SISEPUEDE!B15 -> 4.3153252 | E15: MtCO2e | F15: SISEPUEDE | H15: 2033 | I15: =SISEPUEDE!B14 -> 4.4361287 | J15: =SISEPUEDE!C14 -> 13.653309 | K15: =SISEPUEDE!D14 -> 15.080181
A16: 2035 | B16: BAU | C16: Fugitive | D16: =SISEPUEDE!B16 -> 4.1817119 | E16: MtCO2e | F16: SISEPUEDE | H16: 2034 | I16: =SISEPUEDE!B15 -> 4.3153252 | J16: =SISEPUEDE!C15 -> 13.251238 | K16: =SISEPUEDE!D15 -> 15.981663
... A31: 2050 | B31: BAU | C31: Fugitive | D31: =SISEPUEDE!B31 -> 1.3990427 | E31: MtCO2e | F31: SISEPUEDE | H31: 2049 | I31: =SISEPUEDE!B30 -> 1.3996045 | J31: =SISEPUEDE!C30 -> 3.4014728 | K31: =SISEPUEDE!D30 -> 30.22389
A32: 2023 | B32: BAU | C32: Venting | D32: =SISEPUEDE!C4 -> 15.684255 | E32: MtCO2e | F32: SISEPUEDE | H32: 2050 | I32: =SISEPUEDE!B31 -> 1.3990427 | J32: =SISEPUEDE!C31 -> 3.4001074 | K32: =SISEPUEDE!D31 -> 30.211757
A33: 2024 | B33: BAU | C33: Venting | D33: =SISEPUEDE!C5 -> 15.568561 | E33: MtCO2e | F33: SISEPUEDE
A34: 2025 | B34: BAU | C34: Venting | D34: =SISEPUEDE!C6 -> 15.450191 | E34: MtCO2e | F34: SISEPUEDE
A35: 2026 | B35: BAU | C35: Venting | D35: =SISEPUEDE!C7 -> 15.323396 | E35: MtCO2e | F35: SISEPUEDE | H35: Unconditional - MtCO2e
A36: 2027 | B36: BAU | C36: Venting | D36: =SISEPUEDE!C8 -> 15.181228 | E36: MtCO2e | F36: SISEPUEDE | H36: Year | I36: Fugitive | J36: Venting | K36: Flaring | L36: Gas Recovery
A37: 2028 | B37: BAU | C37: Venting | D37: =SISEPUEDE!C9 -> 15.01639 | E37: MtCO2e | F37: SISEPUEDE | H37: 2023 | I37: =SISEPUEDE!G4 -> 5.0764074 | J37: =SISEPUEDE!H4 -> 15.684255 | K37: =SISEPUEDE!I4 -> 6.2673373 | L37: =SISEPUEDE!J4 -> 0
A38: 2029 | B38: BAU | C38: Venting | D38: =SISEPUEDE!C10 -> 14.822098 | E38: MtCO2e | F38: SISEPUEDE | H38: 2024 | I38: =SISEPUEDE!G5 -> 4.9558359 | J38: =SISEPUEDE!H5 -> 16.446488 | K38: =SISEPUEDE!I5 -> 5.90827 | L38: =SISEPUEDE!J5 -> 0
A39: 2030 | B39: BAU | C39: Venting | D39: =SISEPUEDE!C11 -> 14.592472 | E39: MtCO2e | F39: SISEPUEDE | H39: 2025 | I39: =SISEPUEDE!G6 -> 4.8345444 | J39: =SISEPUEDE!H6 -> 17.205647 | K39: =SISEPUEDE!I6 -> 5.5493889 | L39: =SISEPUEDE!J6 -> 0.86812081
A40: 2031 | B40: BAU | C40: Venting | D40: =SISEPUEDE!C12 -> 14.322902 | E40: MtCO2e | F40: SISEPUEDE | H40: 2026 | I40: =SISEPUEDE!G7 -> 4.7110318 | J40: =SISEPUEDE!H7 -> 17.955042 | K40: =SISEPUEDE!I7 -> 5.1908217 | L40: =SISEPUEDE!J7 -> 1.3047768
A41: 2032 | B41: BAU | C41: Venting | D41: =SISEPUEDE!C13 -> 14.010386 | E41: MtCO2e | F41: SISEPUEDE | H41: 2027 | I41: =SISEPUEDE!G8 -> 4.5836623 | J41: =SISEPUEDE!H8 -> 18.686253 | K41: =SISEPUEDE!I8 -> 4.8331688 | L41: =SISEPUEDE!J8 -> 1.7449783
A42: 2033 | B42: BAU | C42: Venting | D42: =SISEPUEDE!C14 -> 13.653309 | E42: MtCO2e | F42: SISEPUEDE | H42: 2028 | I42: =SISEPUEDE!G9 -> 4.4508221 | J42: =SISEPUEDE!H9 -> 19.389745 | K42: =SISEPUEDE!I9 -> 4.4775456 | L42: =SISEPUEDE!J9 -> 2.1901427
A43: 2034 | B43: BAU | C43: Venting | D43: =SISEPUEDE!C15 -> 13.251238 | E43: MtCO2e | F43: SISEPUEDE | H43: 2029 | I43: =SISEPUEDE!G10 -> 4.3110573 | J43: =SISEPUEDE!H10 -> 20.055505 | K43: =SISEPUEDE!I10 -> 4.1255815 | L43: =SISEPUEDE!J10 -> 2.6417543
A44: 2035 | B44: BAU | C44: Venting | D44: =SISEPUEDE!C16 -> 12.804742 | E44: MtCO2e | F44: SISEPUEDE | H44: 2030 | I44: =SISEPUEDE!G11 -> 4.1631901 | J44: =SISEPUEDE!H11 -> 20.673715 | K44: =SISEPUEDE!I11 -> 3.7793796 | L44: =SISEPUEDE!J11 -> 3.1012899
A45: 2036 | B45: BAU | C45: Venting | D45: =SISEPUEDE!C17 -> 12.315215 | E45: MtCO2e | F45: SISEPUEDE | H45: 2031 | I45: =SISEPUEDE!G12 -> 4.006412 | J45: =SISEPUEDE!H12 -> 21.235449 | K45: =SISEPUEDE!I12 -> 3.441435 | L45: =SISEPUEDE!J12 -> 3.5701673
A46: 2037 | B46: BAU | C46: Venting | D46: =SISEPUEDE!C18 -> 11.784731 | E46: MtCO2e | F46: SISEPUEDE | H46: 2032 | I46: =SISEPUEDE!G13 -> 3.8403716 | J46: =SISEPUEDE!H13 -> 21.733417 | K46: =SISEPUEDE!I13 -> 3.1145184 | L46: =SISEPUEDE!J13 -> 4.0497131
A47: 2038 | B47: BAU | C47: Venting | D47: =SISEPUEDE!C19 -> 11.215906 | E47: MtCO2e | F47: SISEPUEDE | H47: 2033 | I47: =SISEPUEDE!G14 -> 3.6650884 | J47: =SISEPUEDE!H14 -> 22.161996 | K47: =SISEPUEDE!I14 -> 2.8014338 | L47: =SISEPUEDE!J14 -> 4.5411004
A48: 2039 | B48: BAU | C48: Venting | D48: =SISEPUEDE!C20 -> 10.611775 | E48: MtCO2e | F48: SISEPUEDE | H48: 2034 | I48: =SISEPUEDE!G15 -> 3.4808747 | J48: =SISEPUEDE!H15 -> 22.517286 | K48: =SISEPUEDE!I15 -> 2.5047788 | L48: =SISEPUEDE!J15 -> 5.0452865
... A59: 2050 | B59: BAU | C59: Venting | D59: =SISEPUEDE!C31 -> 3.4001074 | E59: MtCO2e | F59: SISEPUEDE | H59: 2045 | I59: =SISEPUEDE!G26 -> 1.0735195 | J59: =SISEPUEDE!H26 -> 22.134476 | K59: =SISEPUEDE!I26 -> 0.44732051 | L59: =SISEPUEDE!J26 -> 11.401398
A60: 2023 | B60: BAU | C60: Flaring | D60: =SISEPUEDE!D4 -> 6.2673373 | E60: MtCO2e | F60: SISEPUEDE | H60: 2046 | I60: =SISEPUEDE!G27 -> 0.83916916 | J60: =SISEPUEDE!H27 -> 21.85244 | K60: =SISEPUEDE!I27 -> 0.33615918 | L60: =SISEPUEDE!J27 -> 12.028674
A61: 2024 | B61: BAU | C61: Flaring | D61: =SISEPUEDE!D5 -> 7.1385925 | E61: MtCO2e | F61: SISEPUEDE | H61: 2047 | I61: =SISEPUEDE!G28 -> 0.6025893 | J61: =SISEPUEDE!H28 -> 21.491008 | K61: =SISEPUEDE!I28 -> 0.29703438 | L61: =SISEPUEDE!J28 -> 12.658817
A62: 2025 | B62: BAU | C62: Flaring | D62: =SISEPUEDE!D6 -> 8.0105268 | E62: MtCO2e | F62: SISEPUEDE | H62: 2048 | I62: =SISEPUEDE!G29 -> 0.36660198 | J62: =SISEPUEDE!H29 -> 21.085314 | K62: =SISEPUEDE!I29 -> 0.29559823 | L62: =SISEPUEDE!J29 -> 13.290771
A63: 2026 | B63: BAU | C63: Flaring | D63: =SISEPUEDE!D7 -> 8.8837822 | E63: MtCO2e | F63: SISEPUEDE | H63: 2049 | I63: =SISEPUEDE!G30 -> 0.13278569 | J63: =SISEPUEDE!H30 -> 20.674397 | K63: =SISEPUEDE!I30 -> 0.29410863 | L63: =SISEPUEDE!J30 -> 13.923676
A64: 2027 | B64: BAU | C64: Flaring | D64: =SISEPUEDE!D8 -> 9.7591389 | E64: MtCO2e | F64: SISEPUEDE | H64: 2050 | I64: =SISEPUEDE!G31 -> 0.12871239 | J64: =SISEPUEDE!H31 -> 20.040194 | K64: =SISEPUEDE!I31 -> 0.28508663 | L64: =SISEPUEDE!J31 -> 13.923676
A65: 2028 | B65: BAU | C65: Flaring | D65: =SISEPUEDE!D9 -> 10.63729 | E65: MtCO2e | F65: SISEPUEDE
...

Sheet tableau
A1: Year | B1: Strategy | C1: Category | D1: Value | E1: Unit
A2: =Summary!A4 -> 2023 | B2: =Summary!B4 -> BAU | C2: =Summary!C4 -> Fugitive | D2: =Summary!D4 -> 5.0764074 | E2: =Summary!E4 -> MtCO2e
A3: =Summary!A5 -> 2024 | B3: =Summary!B5 -> BAU | C3: =Summary!C5 -> Fugitive | D3: =Summary!D5 -> 5.0370762 | E3: =Summary!E5 -> MtCO2e
A4: =Summary!A6 -> 2025 | B4: =Summary!B6 -> BAU | C4: =Summary!C6 -> Fugitive | D4: =Summary!D6 -> 4.9969835 | E4: =Summary!E6 -> MtCO2e
A5: =Summary!A7 -> 2026 | B5: =Summary!B7 -> BAU | C5: =Summary!C7 -> Fugitive | D5: =Summary!D7 -> 4.9544942 | E5: =Summary!E7 -> MtCO2e
A6: =Summary!A8 -> 2027 | B6: =Summary!B8 -> BAU | C6: =Summary!C8 -> Fugitive | D6: =Summary!D8 -> 4.9076953 | E6: =Summary!E8 -> MtCO2e
A7: =Summary!A9 -> 2028 | B7: =Summary!B9 -> BAU | C7: =Summary!C9 -> Fugitive | D7: =Summary!D9 -> 4.8545752 | E7: =Summary!E9 -> MtCO2e
A8: =Summary!A10 -> 2029 | B8: =Summary!B10 -> BAU | C8: =Summary!C10 -> Fugitive | D8: =Summary!D10 -> 4.7931879 | E8: =Summary!E10 -> MtCO2e
A9: =Summary!A11 -> 2030 | B9: =Summary!B11 -> BAU | C9: =Summary!C11 -> Fugitive | D9: =Summary!D11 -> 4.7218037 | E9: =Summary!E11 -> MtCO2e
A10: =Summary!A12 -> 2031 | B10: =Summary!B12 -> BAU | C10: =Summary!C12 -> Fugitive | D10: =Summary!D12 -> 4.639039 | E10: =Summary!E12 -> MtCO2e
A11: =Summary!A13 -> 2032 | B11: =Summary!B13 -> BAU | C11: =Summary!C13 -> Fugitive | D11: =Summary!D13 -> 4.5439818 | E11: =Summary!E13 -> MtCO2e
A12: =Summary!A14 -> 2033 | B12: =Summary!B14 -> BAU | C12: =Summary!C14 -> Fugitive | D12: =Summary!D14 -> 4.4361287 | E12: =Summary!E14 -> MtCO2e
A13: =Summary!A15 -> 2034 | B13: =Summary!B15 -> BAU | C13: =Summary!C15 -> Fugitive | D13: =Summary!D15 -> 4.3153252 | E13: =Summary!E15 -> MtCO2e
... A617: =Summary!A619 -> 2050 | B617: =Summary!B619 -> Conditional | C617: =Summary!C619 -> Gas Recovery | D617: =Summary!D619 -> 2637.8279 | E617: =Summary!E619 -> MMcfd
