Workbook

Sheet README
A1: Libya Water–Energy Nexus Model (2020–2050)
A3: Purpose
A4: A simple annual-timestep model that translates population, GDP and a 100-million-tree afforestation programme into sector water demand, allocates demand across three supplies (local groundwater, pipeline transfers from southern fossil aquifers via the Great Man-Made River, and seawater desalination), and computes the associated electricity demand.
A6: Country context
A7: Libya is one of the most water-stressed countries in the world. Agriculture accounts for ~83% of withdrawals, municipal ~12%, industrial ~5% (FAO AQUASTAT via UNICEF 2022). Total renewable water resources are ~105 m³/cap/yr; >90% of supply comes from non-renewable fossil groundwater. The Great Man-Made River (GMMR) conveys water ~1,000–2,000 km from the Nubian Sandstone Aquifer in the south to coastal demand centres. It is modelled here under "pipeline imports" and is assumed to DECLINE over the model horizon — reflecting aquifer drawdown (estimated depletion within ~60 yr per Lonergan / Columbia State of the Planet 2011), infrastructure damage (by 2019, 101 of 479 western wells dismantled, MEI 2024) and stalled Phase III/IV works.
A9: Model logic
A10: 1. Population: linear interpolation between UN WPP 2024 medium-variant 2020 (6.735M) and 2050 (9.261M).
A11: 2. GDP per capita: user-specified CAGR (default 2.5%/yr).
A12: 3. Sector demand:
A13: • Domestic = L/cap/day × Population × 365 (with efficiency trend)
A14: • Industrial = (m³ / $1000 GDP) × Total GDP (with efficiency trend)
A15: • Agricultural = L/cap/day × Population × 365 (with efficiency trend)
... A71: UPDATE v4 (April 2026): Recalibrated to Libya National Water Security Strategy — Situation Analysis report (MoP/UNDP/Hydroconseil, Aug 2025). Demand intensities calibrated to hit reported 2025 figures (municipal 836, agricultural 6,098, industrial mid-465 Mm³/y). Added Surface water as a new supply source (~60 Mm³/y, declining). Capped desalination at the realistic ceiling implied by the report (70 → 750 Mm³/y by 2050, per Table 18 planned SWRO buildout). Added explicit 'Agriculture from groundwater (overdraft)' row to capture the unsustainable private-well withdrawals the report identifies as up to 5,900 Mm³/y (p.119). GW available baseline raised to 6,000 Mm³/y (was 3,500) to reflect total non-MMR groundwater incl. private wells. Both BAU and Conditional scenarios preserved; all charts and cross-references intact.

Sheet Reviewer_Notes
A1: Libya Water-Energy Model — Full Reviewer Audit
A2: Reviewer: World Bank water-modelling specialist (independent peer review). Date: May 2026. Source file: Libya_Water_Energy_Model_2026_04_30.xlsx.
A4: # | B4: Severity | C4: Sheet / Cell | D4: Issue | E4: Recommendation | F4: Reference / source
A5: I-01 | B5: CRITICAL | C5: Inputs!B26 + B60 | D5: EI groundwater hard-codes ×0.5 grid factor inside the EI value (0.7×0.5=0.35), while B60 separately defines the grid share as 0.53. The two are inconsistent and B60 is never referenced by any formula. | E5: Set B26 = 0.7 (physical EI). Wire B60 explicitly into Energy!D9. Add a parallel row reporting total energy (incl. diesel) as well as grid-only. | F5: Plappally & Lienhard 2012; FAO/WB Libya note.
A6: I-02 | B6: CRITICAL | C6: Inputs!B61–B63 + Energy!D11 | D6: Thermal-desalination share (0.95→0.10) and EI_thermal (15 kWh-eq/m³) are defined but NEVER WIRED into Energy formulas. Energy!D11 treats all desal as 100% SWRO. 2020 desal energy under-counted by ~218 GWh (~3-4×). | E6: Energy!D11 = (thermal_share_t × Inputs!$B$63 + (1−thermal_share_t)×D7) × Supply!D29, with thermal_share_t linearly interpolated from B61 (2020) to B62 (2050). | F6: Brika 2018 (Libya fleet 95% thermal); Hamed 2005; LCA 2006.
A7: I-03 | B7: CRITICAL | C7: Demand!row 15 + Inputs!B16 | D7: Agricultural demand expressed as L/cap/day (2,386). Agriculture is driven by irrigated area × ET, not by population. Causes ag demand to grow +22% by 2050 (5,866 → 7,191 Mm³) purely as a population artefact, contradicting NWSS reform pathway. | E7: Replace with m³/ha × ha_irrigated, or fix Mm³/yr trajectory directly from NWSS Table 26. At minimum, add scenario aligned with NWSS "Sustained Reform" (~5,200 Mm³ by 2050). | F7: NWSS-LY 2025 Hydroconseil/UNDP Table 26.
A8: I-04 | B8: CRITICAL | C8: Inputs!B43–B44 | D8: Duplicate dead inputs: B43/B44 (Recycled water split to trees) repeat B50/B51 and are never referenced. | E8: Delete B43–B44 to remove confusion. | F8: Internal model audit.
A9: I-05 | B9: CRITICAL | C9: Energy!D8 | D9: Surface-water EI (0.2 kWh/m³) is hard-coded inside the formula, not in Inputs. | E9: Move to a new Inputs row "EI surface water" so it can be edited and audited. | F9: Modeling best practice.
A10: I-06 | B10: CRITICAL | C10: Supply!row 39 (overdraft) | D10: Agricultural deficit is silently absorbed by an "overdraft" residual that is added back to GW use. Supply ≡ Demand by construction even when the system is physically infeasible. | E10: Surface the overdraft as a top-line indicator ("non-renewable groundwater mining, Mm³/yr") in Summary; add a caps-and-balances scenario where ag demand is curtailed if total renewable + sustainable-mining < demand. | F10: NWSS-LY 2025 sustainable yield concept; FAO AQUASTAT.
A11: II-07 | B11: HIGH | C11: Inputs!B14 | D11: Industrial intensity 9.1 m³/$1000 GDP gives 2050 industrial demand of 1,030 Mm³ (2.6× growth) driven mostly by GDP CAGR. Libya industrial demand is structurally tied to oil & petrochemicals throughput, not GDP. | E11: Cap industrial growth at refinery/petrochem capacity expansion or switch to physical intensity (m³/Mt refined throughput). | F11: IEA Libya Country Report; IMF Article IV Jun-2025.
A12: II-08 | B12: HIGH | C12: Inputs!B7 | D12: Population 2050 = 10.51 M, ~13% above UN WPP 2024 medium variant (9.26 M). Note says "Matched to SISEPUEDE". | E12: Document the divergence; run sensitivity at UN baseline. Disclose the assumption in Summary. | F12: UN DESA WPP 2024.
A13: II-09 | B13: HIGH | C13: Inputs!B20 | D13: Local GW yield 6,000 Mm³/yr is essentially all non-renewable. Renewable GW for Libya is ~600-700 Mm³/yr. | E13: Split into "renewable GW" and "non-renewable GW abstraction" rows to make the mining flow explicit. | F13: FAO AQUASTAT; NWSS-LY 2025 p.119.
A14: II-10 | B14: HIGH | C14: Inputs!B28 | D14: EI GMMR 1.8 kWh/m³ is at low end of plausible range for 500 m lift + 600 km conveyance. | E14: Raise to 2.0-2.2 kWh/m³ baseline. Document the lift + conveyance + booster breakdown. | F14: Brika 2018; MEI 2024 review.
A15: II-11 | B15: HIGH | C15: Inputs!B52–B55 | D15: Urban and Industrial allocation priorities default to 100% local GW. Tripoli/Benghazi/Misrata are coastal and historically GMMR + desal supplied. Refineries (Zawiya, Ras Lanuf, Brega) primarily run on desal/GMMR. | E15: Set urban GW priority to ~0.4 and industrial GW priority to ~0.3 to reflect actual supply mix; rebalance. | F15: NWSS-LY 2025 Tables 12 & 18.
... A21: III-17 | B21: LOW | C21: Inputs!B17 | D21: Ag efficiency trend −0.8%/yr is optimistic; combined with population growth still gives +22% ag demand by 2050. | E21: Add scenario at −2.0%/yr (aggressive irrigation modernisation, drip retrofit). | F21: FAO Libya Irrigation Modernisation programme.

Sheet EI_Benchmark
A1: Energy Intensity Benchmark — Libya Water-Energy Model Review
A2: Each parameter compared with current literature. Verdict colour: green=defensible, amber=tighten, red=fix required.
A4: # | B4: Parameter (Inputs cell) | C4: Model value | D4: Units | E4: Literature range / benchmark | F4: Reference | G4: Verdict | H4: Recommended action
A5: 1 | B5: EI local groundwater (B26) | C5: 0.35 (=0.7×0.5) | D5: kWh/m³ | E5: Shallow <100 m: 0.2-0.5 Mid 100-200 m: 0.4-0.8 Deep >300 m: 0.8-1.5 Libya coastal typ.: 0.5-0.8 | F5: Plappally & Lienhard 2012, RSER 16(7), p.4818-4848 (0.004 kWh/m³ per m of head). Wada et al. 2014 (global GW pumping). World Bank GCC W-E Nexus 2024. | G5: FIX (red) | H5: Set B26 = 0.7 (physical EI). Wire B60 (grid share, 0.53) into Energy!D9 explicitly. Add parallel total-energy row.
A6: 2 | B6: EI groundwater rise rate (B27) | C6: 0.015 | D6: per year | E6: 1-2%/yr drawdown effect on lift head over 30 yr | F6: Brika 2018 MDPI (Libya); Lonergan 1996 (Nubian aquifer) | G6: OK (green) | H6: Keep, recheck after B26 fix.
A7: 3 | B7: EI pipeline GMMR (B28) | C7: 1.8 | D7: kWh/m³ | E7: Theoretical lift only (500 m): 2.7 Lift + 600 km conveyance + boosters: 2.0-3.0 | F7: Brika 2018 MDPI; MEI 2024 GMMR review; energy bill from GMMR Authority | G7: TIGHTEN (amber) | H7: Increase to 2.0-2.2 baseline. Document the lift+conveyance breakdown.
A8: 4 | B8: EI pipeline rise rate (B29) | C8: 0.01 | D8: per year | E8: 0.5-1.5%/yr (Nubian drawdown) | F8: Lonergan 1996; MEI 2024 | G8: OK (green) | H8: Keep.
A9: 5 | B9: EI desalination 2020 (B30) | C9: 3.5 | D9: kWh/m³ | E9: SWRO with ERDs: 2.5-4.0 State-of-art: 2.8 World record (2025): 1.79 MSF: 19.6-27.25 MED: 14.45-21.35 | F9: IRENA-ETSAP 2015; Qasem, Mittal & Arafat 2021 ScienceDirect; Cell Joule 2024; Hamed 2005; Voutchkov 2018 | G9: FIX (red) | H9: Currently treats 100% as SWRO. Wire thermal share (B61/B62) and EI_thermal (B63) into Energy!D11. 2020 desal energy under-counted by ~218 GWh.
A10: 6 | B10: EI desalination 2050 (B31) | C10: 3.0 | D10: kWh/m³ | E10: XL plants 2.8 by 2030; 2.5 practical floor (thermo limit ~1.0) | F10: Cell Joule 2024 ("Practical minimum energy use of SWRO"); Danfoss 2024 record; IEA 2024 | G10: OK (green) | H10: Keep. Possibly even 2.8 if all new builds are Gen-IV ERDs.
A11: 7 | B11: EI recycled water 2020 (B45) | C11: 0.8 | D11: kWh/m³ | E11: Urban WW reuse: 0.27-3.8 Secondary + disinfection (no RO): 0.5-1.0 With RO polish: 1.5-3.0 | F11: Plappally & Lienhard 2012; Wakeel et al. 2016 RSER | G11: OK (green) | H11: Keep at 0.8. Add scenario at 1.2 if higher-quality (RO polish) is needed for tree drip irrigation.
A12: 8 | B12: EI recycled water 2050 (B46) | C12: 0.65 | D12: kWh/m³ | E12: 0.5-0.8 (membrane bio-reactor + UV; post-2030 BAU) | F12: IWA 2022 Energy efficient water utilities | G12: OK (green) | H12: Keep.
A13: 9 | B13: EI thermal desal — equiv. (B63) | C13: 15 | D13: kWh-eq/m³ | E13: MSF: 19.6-27.25 MED-TVC: 14.45-21.35 Libya fleet (MSF-heavy): 18-22 typical | F13: Hamed 2005; ScienceDirect LCA 2006; Fadiel et al. 2025 | G13: TIGHTEN + WIRE (red) | H13: Raise to 18 to match MSF-heavy fleet, AND wire into Energy!D11 (currently unused).
A14: 10 | B14: GW grid-electrified share (B60) | C14: 0.53 | D14: 0-1 | E14: FAO/WB Libya: ~47% private-farm pumping unmetered/diesel → 0.53 grid share is plausible | F14: FAO AQUASTAT; World Bank Libya Water Sector Note 2018 | G14: WIRE-IN (red) | H14: B60 is defined but unused. Wire into Energy!D9 and remove the duplicate ×0.5 factor inside B26.
A15: 11 | B15: Surface-water EI (Energy!D8 hardcode 0.2) | C15: 0.2 | D15: kWh/m³ | E15: 0.1-0.3 for surface water treatment + distribution | F15: Plappally & Lienhard 2012 | G15: PARAMETERISE (amber) | H15: Move 0.2 from hardcode in Energy!D8 to a new Inputs row for transparency.
... A17: 13 | B17: Total system avg EI (Energy R23) | C17: 0.55 (2020) → 0.83 (2050) | D17: kWh/m³ | E17: MENA average: 0.5-1.2 (incl. desal weight) | F17: World Bank Beyond Scarcity 2017; UNESCWA W-E Nexus 2018 | G17: PLAUSIBLE (amber) | H17: Will rise to 1.0-1.1 once thermal-desal blending is wired in correctly for early years.

Sheet Recommended_Fixes
A1: Recommended Formula Fixes — copy/paste into the corresponding cells
A3: Cell | B3: Current value/formula | C3: Recommended replacement | D3: Rationale
A4: Inputs!B26 | B4: =0.7*0.5 (= 0.35) | C4: 0.7 | D4: Make B26 the physical EI. Apply grid-share factor in Energy formula instead.
A5: Energy!D9 (and copy across cols) | B5: =D5*(Supply!D18+Supply!D21+Supply!D24+Supply!D39) | C5: =D5*Inputs!$B$60*(Supply!D18+Supply!D21+Supply!D24+Supply!D39) | D5: Apply grid-electrified share so we report grid demand. Add a parallel row "Total energy GW" without the *B60 for nexus reporting.
A6: Energy!D11 (and copy across cols) | B6: =D7*Supply!D29 | C6: =((Inputs!$B$61+(Inputs!$B$62-Inputs!$B$61)*(D$3-2020)/30)*Inputs!$B$63 + (1-(Inputs!$B$61+(Inputs!$B$62-Inputs!$B$61)*(D$3-2020)/30))*D7)*Supply!D29 | D6: Blend SWRO + thermal MSF/MED EI by their fleet shares (linearly transitioning 2020→2050). Wires in Inputs B61/B62/B63.
A7: Inputs (new row) | B7: — (currently 0.2 hardcoded inside Energy!D8) | C7: EI surface water = 0.20 kWh/m³, then change Energy!D8 to =Inputs!$B$NEW * Supply!D7 | D7: Move hardcode to inputs for transparency.
A8: Energy (new row, e.g. R26) | B8: — (does not exist) | C8: "Water sector share of national grid (%)" = =D15/(Inputs!$B$65*1000) | D8: Cross-check vs Libya total grid 35 TWh. Currently we report ~11% (2020) → 23% (2050).
A9: Inputs (delete) | B9: B43, B44 dead values | C9: Delete rows / clear values | D9: Duplicate of B50/B51 and unreferenced.
A10: Inputs!B14 | B10: 9.1 | C10: Sensitivity: 6.0 (low) | 9.1 (mid) | 12.0 (high) | D10: Industrial water intensity is highly uncertain post-conflict. Provide a range.
A11: Inputs!B16 | B11: 2,386 L/cap/day | C11: Replace driver: ag_demand_t (Mm³/yr) = m³/ha × ha_irrigated_t | D11: Decouple agriculture from population. Use FAO/NWSS area projections.
A12: Inputs!B28 | B12: 1.8 | C12: 2.0 | D12: Better aligned with 500 m lift + 600 km conveyance physics.
A13: Inputs!B63 | B13: 15 | C13: 18 | D13: Libya legacy fleet is MSF-heavy; midpoint 18 kWh-eq/m³ is more representative.
A14: Inputs!B52, B53, B54, B55 | B14: 1, 1, 1, 1 | C14: Urban GW: 0.4; Urban GMMR: 0.6; Industrial GW: 0.3; Industrial GMMR: 0.7 | D14: Match real allocation: coastal cities & refineries use GMMR/desal, not local GW first.

Sheet Inputs
A1: Libya Water-Energy Model — Inputs & Assumptions
A3: Parameter | B3: Value | C3: Units | D3: Source / Note
A5: DEMOGRAPHICS & ECONOMY
A6: Population 2020 | B6: 6735277 | C6: persons | D6: UN WPP 2024 medium variant | E6: *
A7: Population 2050 | B7: 10506952 | C7: persons | D7: Matched to SISEPUEDE | E7: *
A8: GDP per capita 2020 | B8: 6357 | C8: USD (current) | D8: World Bank WDI 2020 (volatile) | E8: *
A9: GDP per capita CAGR | B9: 0.028 | C9: per year | D9: Matched to SISEPUEDE | E9: *
A11: WATER DEMAND INTENSITIES
A12: Domestic water use 2020 | B12: 319 | C12: L/cap/day | D12: Calibrated to report (p.115): municipal demand 836 Mm³/y in 2025
A13: Domestic efficiency trend | B13: -0.005 | C13: per year | D13: Assumption: leak reduction, metering
A14: Industrial water intensity 2020 | B14: 9.1 | C14: m³ per $1000 GDP | D14: Calibrated to report (p.117): industrial demand 273-656 Mm³/y in 2025; midpoint ~465
A15: Industrial efficiency trend | B15: -0.01 | C15: per year | D15: Assumption: process efficiency
A16: Agricultural water use 2020 | B16: 2386 | C16: L/cap/day | D16: Calibrated to report (p.111, Table 26): agricultural demand 6,098 Mm³/y in 2025
A17: Agricultural efficiency trend | B17: -0.008 | C17: per year | D17: Assumption: irrigation modernization
A18: Surface water decline rate | B18: -0.01 | C18: per year | D18: Report p.61-69: rising evap & climate change
A19: SUPPLY CAPACITY & TRENDS
A20: Local groundwater yield 2020 | B20: 6000 | C20: M m³/yr | D20: Report p.119: ~5,900 Mm³/y from private wells + GCWW wells; mostly unsustainable. Excl. MMR.
A21: Groundwater decline rate | B21: -0.015 | C21: per year | D21: Overdraft & coastal salinization
A22: GMMR pipeline delivery 2020 | B22: 912 | C22: M m³/yr | D22: 2.5 Mm³/day × 365 (MEI 2024) | E22: Great Man Made River
A23: GMMR decline rate | B23: -0.02 | C23: per year | D23: Aquifer depletion (Lonergan ~60 yr) + infra decay
A24: Surface water 2020 | B24: 60 | C24: M m³/yr | D24: Report p.24-25: very limited; few small dams; high evap (1,700-6,000 mm/y)
A25: ENERGY INTENSITIES
A26: EI local groundwater 2020 | B26: =0.7*0.5 -> 0.35 | C26: kWh/m³ | D26: USGS/Denver 1.2-1.8 deep; 0.7 shallow/coastal We assumed that the majoriry of private-farm groundwater runs on diesel gensets and is not billed through the grid, given that FAO/World Bank water-sector assessments for the countrt, we can assume that private-farm pumping is largely unmetered and off-grid (approx 50%). Thus the energy intensity of this is scaled to what it is actually being demanded by the electricity grid.
A27: EI groundwater rise rate | B27: 0.015 | C27: per year | D27: Water-table drawdown raises lift
A28: EI pipeline (GMMR) 2020 | B28: 1.8 | C28: kWh/m³ | D28: Deep-well (500 m) + long conveyance; lit. 1.5-2.0
A29: EI pipeline rise rate | B29: 0.01 | C29: per year | D29: Rising lift as Nubian aquifer draws down
A30: EI desalination 2020 | B30: 3.5 | C30: kWh/m³ | D30: SWRO with ERDs (IRENA; ScienceDirect)
A31: EI desalination 2050 | B31: 3 | C31: kWh/m³ | D31: Efficiency gains toward 2.8 state-of-art
A32: Desalination capacity 2020 | B32: 20 | C32: M m³/yr | D32: Report p.92: 70-76 Mm³/y in 2010-2013
A33: 100-MILLION TREE AFFORESTATION PROGRAMME
A34: Programme start year | B34: 2026 | C34: year | D34: Assumption — edit to shift timeline
A35: Planting ramp (years) | B35: 10 | C35: years | D35: Linear planting of target over this period
A36: Target trees | B36: 100000000 | C36: trees | D36: Programme ambition (100 million)
A37: Water per tree | B37: 15 | C37: L/tree/day | D37: Drip-irrigated drought-tolerant; Becker et al. 2022; USU ext. ~41 L/d for mature arid shade tree | G37: =+B36*B37 -> 1500000000 | H37: L/day | I37: =+G37*365/1000 -> 547500000 | J37: m3/year | K37: =+I37/1000000 -> 547.5 | L37: Mm3/year
A38: Desalination capacity 2050 | B38: 750 | C38: M m³/yr | D38: Report p.92, Table 18: existing rehab + 14-15 planned SWRO at 2 Mm³/d ≈ 850 max; conservative 750
A39: RECYCLED WATER & ALLOCATION
A40: Parameter | B40: Value | C40: Units | D40: Source / Note
A41: Urban wastewater recovery share 2020 | B41: 0.01 | C41: share of urban water demand met | D41: Assumption: recoverable municipal wastewater
A42: Urban wastewater recovery share 2050 | B42: =0.35*0.1 -> 0.035 | C42: share of urban water demand met | D42: Assumption: better sewerage, treatment, and reuse
A43: Recycled water split to trees 2020 | B43: 0.5 | C43: share of recycled water | D43: Allocation priority from recycled water
...

Sheet Demand
A1: Water Demand Projections — Libya (2020–2050)
A3: Metric | B3: Units | C3: Notes | D3: 2020 | E3: 2021 | F3: 2022 | G3: 2023 | H3: 2024 | I3: 2025 | J3: 2026 | K3: 2027 | L3: 2028 | M3: 2029 | N3: 2030 | O3: 2031 | P3: 2032 | Q3: 2033 | R3: 2034 | S3: 2035 | T3: 2036 | U3: 2037 | V3: 2038 | W3: 2039 | X3: 2040 | Y3: 2041 | Z3: 2042 | AA3: 2043 | AB3: 2044 | AC3: 2045 | AD3: 2046 | AE3: 2047 | AF3: 2048 | AG3: 2049 | AH3: 2050
A5: Population | B5: persons | C5: Linear interp UN WPP 2024 (2020 ↔ 2050) | D5: =Inputs!$B$6+(Inputs!$B$7-Inputs!$B$6)*(D$3-2020)/30 -> 6735277 | E5: =Inputs!$B$6+(Inputs!$B$7-Inputs!$B$6)*(E$3-2020)/30 -> 6860999.5 | F5: =Inputs!$B$6+(Inputs!$B$7-Inputs!$B$6)*(F$3-2020)/30 -> 6986722 | G5: =Inputs!$B$6+(Inputs!$B$7-Inputs!$B$6)*(G$3-2020)/30 -> 7112444.5 | H5: =Inputs!$B$6+(Inputs!$B$7-Inputs!$B$6)*(H$3-2020)/30 -> 7238167 | I5: =Inputs!$B$6+(Inputs!$B$7-Inputs!$B$6)*(I$3-2020)/30 -> 7363889.5 | J5: =Inputs!$B$6+(Inputs!$B$7-Inputs!$B$6)*(J$3-2020)/30 -> 7489612 | K5: =Inputs!$B$6+(Inputs!$B$7-Inputs!$B$6)*(K$3-2020)/30 -> 7615334.5 | ... AH5: =Inputs!$B$6+(Inputs!$B$7-Inputs!$B$6)*(AH$3-2020)/30 -> 10506952
A6: GDP per capita | B6: USD | C6: GDP_pc_2020 × (1+CAGR)^(year-2020) | D6: =Inputs!$B$8*(1+Inputs!$B$9)^(D$3-2020) -> 6357 | E6: =Inputs!$B$8*(1+Inputs!$B$9)^(E$3-2020) -> 6534.996 | F6: =Inputs!$B$8*(1+Inputs!$B$9)^(F$3-2020) -> 6717.9759 | G6: =Inputs!$B$8*(1+Inputs!$B$9)^(G$3-2020) -> 6906.0792 | H6: =Inputs!$B$8*(1+Inputs!$B$9)^(H$3-2020) -> 7099.4494 | I6: =Inputs!$B$8*(1+Inputs!$B$9)^(I$3-2020) -> 7298.234 | J6: =Inputs!$B$8*(1+Inputs!$B$9)^(J$3-2020) -> 7502.5846 | K6: =Inputs!$B$8*(1+Inputs!$B$9)^(K$3-2020) -> 7712.6569 | ... AH6: =Inputs!$B$8*(1+Inputs!$B$9)^(AH$3-2020) -> 14556.121
A7: Total GDP | B7: M USD | C7: Population × GDP per capita / 1e6 | D7: =D5*D6/1000000 -> 42816.156 | E7: =E5*E6/1000000 -> 44836.604 | F7: =F5*F6/1000000 -> 46936.63 | G7: =G5*G6/1000000 -> 49119.105 | H7: =H5*H6/1000000 -> 51387.001 | I7: =I5*I6/1000000 -> 53743.389 | J7: =J5*J6/1000000 -> 56191.447 | K7: =K5*K6/1000000 -> 58734.462 | ... AH7: =AH5*AH6/1000000 -> 152940.46
A9: Domestic intensity | B9: L/cap/day | C9: Base × (1+eff)^(year-2020) | D9: =Inputs!$B$12*(1+Inputs!$B$13)^(D$3-2020) -> 319 | E9: =Inputs!$B$12*(1+Inputs!$B$13)^(E$3-2020) -> 317.405 | F9: =Inputs!$B$12*(1+Inputs!$B$13)^(F$3-2020) -> 315.81797 | G9: =Inputs!$B$12*(1+Inputs!$B$13)^(G$3-2020) -> 314.23889 | H9: =Inputs!$B$12*(1+Inputs!$B$13)^(H$3-2020) -> 312.66769 | I9: =Inputs!$B$12*(1+Inputs!$B$13)^(I$3-2020) -> 311.10435 | J9: =Inputs!$B$12*(1+Inputs!$B$13)^(J$3-2020) -> 309.54883 | K9: =Inputs!$B$12*(1+Inputs!$B$13)^(K$3-2020) -> 308.00109 | ... AH9: =Inputs!$B$12*(1+Inputs!$B$13)^(AH$3-2020) -> 274.46256
A10: Industrial intensity | B10: m³/$1000 GDP | C10: Base × (1+eff)^(year-2020) | D10: =Inputs!$B$14*(1+Inputs!$B$15)^(D$3-2020) -> 9.1 | E10: =Inputs!$B$14*(1+Inputs!$B$15)^(E$3-2020) -> 9.009 | F10: =Inputs!$B$14*(1+Inputs!$B$15)^(F$3-2020) -> 8.91891 | G10: =Inputs!$B$14*(1+Inputs!$B$15)^(G$3-2020) -> 8.8297209 | H10: =Inputs!$B$14*(1+Inputs!$B$15)^(H$3-2020) -> 8.7414237 | I10: =Inputs!$B$14*(1+Inputs!$B$15)^(I$3-2020) -> 8.6540095 | J10: =Inputs!$B$14*(1+Inputs!$B$15)^(J$3-2020) -> 8.5674694 | K10: =Inputs!$B$14*(1+Inputs!$B$15)^(K$3-2020) -> 8.4817947 | ... AH10: =Inputs!$B$14*(1+Inputs!$B$15)^(AH$3-2020) -> 6.7312734
A11: Agricultural intensity | B11: L/cap/day | C11: Base × (1+eff)^(year-2020) | D11: =Inputs!$B$16*(1+Inputs!$B$17)^(D$3-2020) -> 2386 | E11: =Inputs!$B$16*(1+Inputs!$B$17)^(E$3-2020) -> 2366.912 | F11: =Inputs!$B$16*(1+Inputs!$B$17)^(F$3-2020) -> 2347.9767 | G11: =Inputs!$B$16*(1+Inputs!$B$17)^(G$3-2020) -> 2329.1929 | H11: =Inputs!$B$16*(1+Inputs!$B$17)^(H$3-2020) -> 2310.5593 | I11: =Inputs!$B$16*(1+Inputs!$B$17)^(I$3-2020) -> 2292.0749 | J11: =Inputs!$B$16*(1+Inputs!$B$17)^(J$3-2020) -> 2273.7383 | K11: =Inputs!$B$16*(1+Inputs!$B$17)^(K$3-2020) -> 2255.5484 | ... AH11: =Inputs!$B$16*(1+Inputs!$B$17)^(AH$3-2020) -> 1875.0835
A13: Domestic demand | B13: M m³/yr | C13: Pop × lpcd × 365 / 1e9 | D13: =D5*D9*365/1000000000 -> 784.22198 | E13: =E5*E9*365/1000000000 -> 794.86617 | F13: =F5*F9*365/1000000000 -> 805.38432 | G13: =G5*G9*365/1000000000 -> 815.77742 | H13: =H5*H9*365/1000000000 -> 826.04645 | I13: =I5*I9*365/1000000000 -> 836.1924 | J13: =J5*J9*365/1000000000 -> 846.21623 | K13: =K5*K9*365/1000000000 -> 856.11892 | ... AH13: =AH5*AH9*365/1000000000 -> 1052.5742
A14: Industrial demand | B14: M m³/yr | C14: GDP(M USD) × (m³/$1000) / 1000 | D14: =D7*D10/1000 -> 389.62702 | E14: =E7*E10/1000 -> 403.93297 | F14: =F7*F10/1000 -> 418.62358 | G14: =G7*G10/1000 -> 433.70799 | H14: =H7*H10/1000 -> 449.19554 | I14: =I7*I10/1000 -> 465.0958 | J14: =J7*J10/1000 -> 481.4185 | K14: =K7*K10/1000 -> 498.17365 | ... AH14: =AH7*AH10/1000 -> 1029.4841
A15: Agricultural demand | B15: M m³/yr | C15: Pop × lpcd × 365 / 1e9 | D15: =D5*D11*365/1000000000 -> 5865.6854 | E15: =E5*E11*365/1000000000 -> 5927.3744 | F15: =F5*F11*365/1000000000 -> 5987.7011 | G15: =G5*G11*365/1000000000 -> 6046.6831 | H15: =H5*H11*365/1000000000 -> 6104.3383 | I15: =I5*I11*365/1000000000 -> 6160.6839 | J15: =J5*J11*365/1000000000 -> 6215.7374 | K15: =K5*K11*365/1000000000 -> 6269.5157 | ... AH15: =AH5*AH11*365/1000000000 -> 7191.0154
A16: Active trees (100 M program) | B16: trees | C16: MIN(target, MAX(0, target×(year−start)/ramp)) | D16: =Inputs!$B$36*MIN(1,MAX(0,(D$3-Inputs!$B$34)/Inputs!$B$35)) -> 0 | E16: =Inputs!$B$36*MIN(1,MAX(0,(E$3-Inputs!$B$34)/Inputs!$B$35)) -> 0 | F16: =Inputs!$B$36*MIN(1,MAX(0,(F$3-Inputs!$B$34)/Inputs!$B$35)) -> 0 | G16: =Inputs!$B$36*MIN(1,MAX(0,(G$3-Inputs!$B$34)/Inputs!$B$35)) -> 0 | H16: =Inputs!$B$36*MIN(1,MAX(0,(H$3-Inputs!$B$34)/Inputs!$B$35)) -> 0 | I16: =Inputs!$B$36*MIN(1,MAX(0,(I$3-Inputs!$B$34)/Inputs!$B$35)) -> 0 | J16: =Inputs!$B$36*MIN(1,MAX(0,(J$3-Inputs!$B$34)/Inputs!$B$35)) -> 0 | K16: =Inputs!$B$36*MIN(1,MAX(0,(K$3-Inputs!$B$34)/Inputs!$B$35)) -> 10000000 | ... AH16: =Inputs!$B$36*MIN(1,MAX(0,(AH$3-Inputs!$B$34)/Inputs!$B$35)) -> 100000000
A17: Tree programme demand | B17: M m³/yr | C17: Active trees × L/tree/day × 365 / 1e9 | D17: =D16*Inputs!$B$37*365/1000000000 -> 0 | E17: =E16*Inputs!$B$37*365/1000000000 -> 0 | F17: =F16*Inputs!$B$37*365/1000000000 -> 0 | G17: =G16*Inputs!$B$37*365/1000000000 -> 0 | H17: =H16*Inputs!$B$37*365/1000000000 -> 0 | I17: =I16*Inputs!$B$37*365/1000000000 -> 0 | J17: =J16*Inputs!$B$37*365/1000000000 -> 0 | K17: =K16*Inputs!$B$37*365/1000000000 -> 54.75 | ... AH17: =AH16*Inputs!$B$37*365/1000000000 -> 547.5
A19: TOTAL water demand | B19: M m³/yr | C19: Sum of sectors + tree program | D19: =D13+D14+D15+D17 -> 7039.5344 | E19: =E13+E14+E15+E17 -> 7126.1736 | F19: =F13+F14+F15+F17 -> 7211.709 | G19: =G13+G14+G15+G17 -> 7296.1685 | H19: =H13+H14+H15+H17 -> 7379.5803 | I19: =I13+I14+I15+I17 -> 7461.9721 | J19: =J13+J14+J15+J17 -> 7543.3721 | K19: =K13+K14+K15+K17 -> 7678.5583 | ... AH19: =AH13+AH14+AH15+AH17 -> 9820.5736

Sheet Supply
A1: Water Supply Allocation — Libya (2020–2050)
A3: Metric | B3: Units | C3: Notes | D3: 2020 | E3: 2021 | F3: 2022 | G3: 2023 | H3: 2024 | I3: 2025 | J3: 2026 | K3: 2027 | L3: 2028 | M3: 2029 | N3: 2030 | O3: 2031 | P3: 2032 | Q3: 2033 | R3: 2034 | S3: 2035 | T3: 2036 | U3: 2037 | V3: 2038 | W3: 2039 | X3: 2040 | Y3: 2041 | Z3: 2042 | AA3: 2043 | AB3: 2044 | AC3: 2045 | AD3: 2046 | AE3: 2047 | AF3: 2048 | AG3: 2049 | AH3: 2050
A5: Total water demand | B5: M m³/yr | C5: link ← Demand row 19 | D5: =Demand!D19 -> 7039.5344 | E5: =Demand!E19 -> 7126.1736 | F5: =Demand!F19 -> 7211.709 | G5: =Demand!G19 -> 7296.1685 | H5: =Demand!H19 -> 7379.5803 | I5: =Demand!I19 -> 7461.9721 | J5: =Demand!J19 -> 7543.3721 | K5: =Demand!K19 -> 7678.5583 | ... AH5: =Demand!AH19 -> 9820.5736
A6: Of which tree programme | B6: M m³/yr | C6: link ← Demand row 17 | D6: =Demand!D17 -> 0 | E6: =Demand!E17 -> 0 | F6: =Demand!F17 -> 0 | G6: =Demand!G17 -> 0 | H6: =Demand!H17 -> 0 | I6: =Demand!I17 -> 0 | J6: =Demand!J17 -> 0 | K6: =Demand!K17 -> 54.75 | ... AH6: =Demand!AH17 -> 547.5
A7: Surface water to agriculture | B7: M m³/yr | C7: min(SW available, ag residual after recycled) | D7: =MIN(D11,MAX(D14-D17,0)) -> 60 | E7: =MIN(E11,MAX(E14-E17,0)) -> 59.4 | F7: =MIN(F11,MAX(F14-F17,0)) -> 58.806 | G7: =MIN(G11,MAX(G14-G17,0)) -> 58.21794 | H7: =MIN(H11,MAX(H14-H17,0)) -> 57.635761 | I7: =MIN(I11,MAX(I14-I17,0)) -> 57.059403 | J7: =MIN(J11,MAX(J14-J17,0)) -> 56.488809 | K7: =MIN(K11,MAX(K14-K17,0)) -> 55.923921 | ... AH7: =MIN(AH11,MAX(AH14-AH17,0)) -> 44.382022
A8: Local groundwater available | B8: M m³/yr | C8: GW_2020 × (1+decline)^(year-2020) | D8: =Inputs!$B$20*(1+Inputs!$B$21)^(D$3-2020) -> 6000 | E8: =Inputs!$B$20*(1+Inputs!$B$21)^(E$3-2020) -> 5910 | F8: =Inputs!$B$20*(1+Inputs!$B$21)^(F$3-2020) -> 5821.35 | G8: =Inputs!$B$20*(1+Inputs!$B$21)^(G$3-2020) -> 5734.0297 | H8: =Inputs!$B$20*(1+Inputs!$B$21)^(H$3-2020) -> 5648.0193 | I8: =Inputs!$B$20*(1+Inputs!$B$21)^(I$3-2020) -> 5563.299 | J8: =Inputs!$B$20*(1+Inputs!$B$21)^(J$3-2020) -> 5479.8495 | K8: =Inputs!$B$20*(1+Inputs!$B$21)^(K$3-2020) -> 5397.6518 | ... AH8: =Inputs!$B$20*(1+Inputs!$B$21)^(AH$3-2020) -> 3812.7486
A9: Pipeline (GMMR) available | B9: M m³/yr | C9: GMMR_2020 × (1+decline)^(year-2020) | D9: =Inputs!$B$22*(1+Inputs!$B$23)^(D$3-2020) -> 912 | E9: =Inputs!$B$22*(1+Inputs!$B$23)^(E$3-2020) -> 893.76 | F9: =Inputs!$B$22*(1+Inputs!$B$23)^(F$3-2020) -> 875.8848 | G9: =Inputs!$B$22*(1+Inputs!$B$23)^(G$3-2020) -> 858.3671 | H9: =Inputs!$B$22*(1+Inputs!$B$23)^(H$3-2020) -> 841.19976 | I9: =Inputs!$B$22*(1+Inputs!$B$23)^(I$3-2020) -> 824.37577 | J9: =Inputs!$B$22*(1+Inputs!$B$23)^(J$3-2020) -> 807.88825 | K9: =Inputs!$B$22*(1+Inputs!$B$23)^(K$3-2020) -> 791.73049 | ... AH9: =Inputs!$B$22*(1+Inputs!$B$23)^(AH$3-2020) -> 497.4817
A10: Groundwater + GMMR + Surface water | B10: M m³/yr | C10: GW + GMMR + SW | D10: =D8+D9+D11 -> 6972 | E10: =E8+E9+E11 -> 6863.16 | F10: =F8+F9+F11 -> 6756.0408 | G10: =G8+G9+G11 -> 6650.6148 | H10: =H8+H9+H11 -> 6546.8548 | I10: =I8+I9+I11 -> 6444.7342 | J10: =J8+J9+J11 -> 6344.2266 | K10: =K8+K9+K11 -> 6245.3062 | ... AH10: =AH8+AH9+AH11 -> 4354.6123
A11: Surface water available | B11: M m³/yr | C11: SW_2020 × (1+decline)^(year-2020) | D11: =Inputs!$B$24*(1+Inputs!$B$18)^(D$3-2020) -> 60 | E11: =Inputs!$B$24*(1+Inputs!$B$18)^(E$3-2020) -> 59.4 | F11: =Inputs!$B$24*(1+Inputs!$B$18)^(F$3-2020) -> 58.806 | G11: =Inputs!$B$24*(1+Inputs!$B$18)^(G$3-2020) -> 58.21794 | H11: =Inputs!$B$24*(1+Inputs!$B$18)^(H$3-2020) -> 57.635761 | I11: =Inputs!$B$24*(1+Inputs!$B$18)^(I$3-2020) -> 57.059403 | J11: =Inputs!$B$24*(1+Inputs!$B$18)^(J$3-2020) -> 56.488809 | K11: =Inputs!$B$24*(1+Inputs!$B$18)^(K$3-2020) -> 55.923921 | ... AH11: =Inputs!$B$24*(1+Inputs!$B$18)^(AH$3-2020) -> 44.382022
A12: Domestic demand | B12: M m³/yr | C12: link ← Demand domestic | D12: =Demand!D13 -> 784.22198 | E12: =Demand!E13 -> 794.86617 | F12: =Demand!F13 -> 805.38432 | G12: =Demand!G13 -> 815.77742 | H12: =Demand!H13 -> 826.04645 | I12: =Demand!I13 -> 836.1924 | J12: =Demand!J13 -> 846.21623 | K12: =Demand!K13 -> 856.11892 | ... AH12: =Demand!AH13 -> 1052.5742
A13: Industrial demand | B13: M m³/yr | C13: link ← Demand industrial | D13: =Demand!D14 -> 389.62702 | E13: =Demand!E14 -> 403.93297 | F13: =Demand!F14 -> 418.62358 | G13: =Demand!G14 -> 433.70799 | H13: =Demand!H14 -> 449.19554 | I13: =Demand!I14 -> 465.0958 | J13: =Demand!J14 -> 481.4185 | K13: =Demand!K14 -> 498.17365 | ... AH13: =Demand!AH14 -> 1029.4841
A14: Agricultural demand | B14: M m³/yr | C14: link ← Demand agriculture | D14: =Demand!D15 -> 5865.6854 | E14: =Demand!E15 -> 5927.3744 | F14: =Demand!F15 -> 5987.7011 | G14: =Demand!G15 -> 6046.6831 | H14: =Demand!H15 -> 6104.3383 | I14: =Demand!I15 -> 6160.6839 | J14: =Demand!J15 -> 6215.7374 | K14: =Demand!K15 -> 6269.5157 | ... AH14: =Demand!AH15 -> 7191.0154
A15: Recycled water available | B15: M m³/yr | C15: Urban demand met × recovery share | D15: =Demand!D13*(Inputs!B41+(Inputs!B42-Inputs!B41)*(D3-2020)/30) -> 7.8422198 | E15: =Demand!E13*(Inputs!B41+(Inputs!B42-Inputs!B41)*(E3-2020)/30) -> 8.6110502 | F15: =Demand!F13*(Inputs!B41+(Inputs!B42-Inputs!B41)*(F3-2020)/30) -> 9.3961504 | G15: =Demand!G13*(Inputs!B41+(Inputs!B42-Inputs!B41)*(G3-2020)/30) -> 10.197218 | H15: =Demand!H13*(Inputs!B41+(Inputs!B42-Inputs!B41)*(H3-2020)/30) -> 11.013953 | I15: =Demand!I13*(Inputs!B41+(Inputs!B42-Inputs!B41)*(I3-2020)/30) -> 11.846059 | J15: =Demand!J13*(Inputs!B41+(Inputs!B42-Inputs!B41)*(J3-2020)/30) -> 12.693243 | K15: =Demand!K13*(Inputs!B41+(Inputs!B42-Inputs!B41)*(K3-2020)/30) -> 13.555216 | L15: =Demand!L13*(Inputs!B41+(Inputs!B42-Inputs!B41)*(L3-2020)/30) -> 14.431691 | M15: =Demand!M13*(Inputs!B41+(Inputs!B42-Inputs!B41)*(M3-2020)/30) -> 15.322383 | N15: =Demand!N13*(Inputs!B41+(Inputs!B42-Inputs!B41)*(N3-2020)/30) -> 16.227011 | O15: =Demand!O13*(Inputs!B41+(Inputs!B42-Inputs!B41)*(O3-2020)/30) -> 17.1453 | P15: =Demand!P13*(Inputs!B41+(Inputs!B42-Inputs!B41)*(P3-2020)/30) -> 18.076973 | Q15: =Demand!Q13*(Inputs!B41+(Inputs!B42-Inputs!B41)*(Q3-2020)/30) -> 19.021759 | R15: =Demand!R13*(Inputs!B41+(Inputs!B42-Inputs!B41)*(R3-2020)/30) -> 19.979389 | S15: =Demand!S13*(Inputs!B41+(Inputs!B42-Inputs!B41)*(S3-2020)/30) -> 20.949598 | T15: =Demand!T13*(Inputs!B41+(Inputs!B42-Inputs!B41)*(T3-2020)/30) -> 21.932122 | U15: =Demand!U13*(Inputs!B41+(Inputs!B42-Inputs!B41)*(U3-2020)/30) -> 22.926702 | V15: =Demand!V13*(Inputs!B41+(Inputs!B42-Inputs!B41)*(V3-2020)/30) -> 23.933081 | W15: =Demand!W13*(Inputs!B41+(Inputs!B42-Inputs!B41)*(W3-2020)/30) -> 24.951004 | X15: =Demand!X13*(Inputs!B41+(Inputs!B42-Inputs!B41)*(X3-2020)/30) -> 25.980219 | Y15: =Demand!Y13*(Inputs!B41+(Inputs!B42-Inputs!B41)*(Y3-2020)/30) -> 27.020479 | Z15: =Demand!Z13*(Inputs!B41+(Inputs!B42-Inputs!B41)*(Z3-2020)/30) -> 28.071536 | AA15: =Demand!AA13*(Inputs!B41+(Inputs!B42-Inputs!B41)*(AA3-2020)/30) -> 29.133148 | AB15: =Demand!AB13*(Inputs!B41+(Inputs!B42-Inputs!B41)*(AB3-2020)/30) -> 30.205074 | AC15: =Demand!AC13*(Inputs!B41+(Inputs!B42-Inputs!B41)*(AC3-2020)/30) -> 31.287077 | AD15: =Demand!AD13*(Inputs!B41+(Inputs!B42-Inputs!B41)*(AD3-2020)/30) -> 32.378921 | AE15: =Demand!AE13*(Inputs!B41+(Inputs!B42-Inputs!B41)*(AE3-2020)/30) -> 33.480374 | AF15: =Demand!AF13*(Inputs!B41+(Inputs!B42-Inputs!B41)*(AF3-2020)/30) -> 34.591205 | AG15: =Demand!AG13*(Inputs!B41+(Inputs!B42-Inputs!B41)*(AG3-2020)/30) -> 35.711188 | AH15: =Demand!AH13*(Inputs!B41+(Inputs!B42-Inputs!B41)*(AH3-2020)/30) -> 36.840097
A16: Recycled water to trees | B16: M m³/yr | C16: Allocated first from recycled water, capped by tree demand | D16: =MIN(Supply!D6,Supply!D15*(Inputs!B50+(Inputs!B51-Inputs!B50)*(D3-2020)/30)) -> 0 | E16: =MIN(Supply!E6,Supply!E15*(Inputs!B50+(Inputs!B51-Inputs!B50)*(E3-2020)/30)) -> 0 | F16: =MIN(Supply!F6,Supply!F15*(Inputs!B50+(Inputs!B51-Inputs!B50)*(F3-2020)/30)) -> 0 | G16: =MIN(Supply!G6,Supply!G15*(Inputs!B50+(Inputs!B51-Inputs!B50)*(G3-2020)/30)) -> 0 | H16: =MIN(Supply!H6,Supply!H15*(Inputs!B50+(Inputs!B51-Inputs!B50)*(H3-2020)/30)) -> 0 | I16: =MIN(Supply!I6,Supply!I15*(Inputs!B50+(Inputs!B51-Inputs!B50)*(I3-2020)/30)) -> 0 | J16: =MIN(Supply!J6,Supply!J15*(Inputs!B50+(Inputs!B51-Inputs!B50)*(J3-2020)/30)) -> 0 | K16: =MIN(Supply!K6,Supply!K15*(Inputs!B50+(Inputs!B51-Inputs!B50)*(K3-2020)/30)) -> 6.1450314 | L16: =MIN(Supply!L6,Supply!L15*(Inputs!B50+(Inputs!B51-Inputs!B50)*(L3-2020)/30)) -> 6.4461551 | M16: =MIN(Supply!M6,Supply!M15*(Inputs!B50+(Inputs!B51-Inputs!B50)*(M3-2020)/30)) -> 6.7418483 | N16: =MIN(Supply!N6,Supply!N15*(Inputs!B50+(Inputs!B51-Inputs!B50)*(N3-2020)/30)) -> 7.031705 | O16: =MIN(Supply!O6,Supply!O15*(Inputs!B50+(Inputs!B51-Inputs!B50)*(O3-2020)/30)) -> 7.3153279 | P16: =MIN(Supply!P6,Supply!P15*(Inputs!B50+(Inputs!B51-Inputs!B50)*(P3-2020)/30)) -> 7.5923286 | Q16: =MIN(Supply!Q6,Supply!Q15*(Inputs!B50+(Inputs!B51-Inputs!B50)*(Q3-2020)/30)) -> 7.8623269 | R16: =MIN(Supply!R6,Supply!R15*(Inputs!B50+(Inputs!B51-Inputs!B50)*(R3-2020)/30)) -> 8.1249515 | S16: =MIN(Supply!S6,Supply!S15*(Inputs!B50+(Inputs!B51-Inputs!B50)*(S3-2020)/30)) -> 8.3798391 | T16: =MIN(Supply!T6,Supply!T15*(Inputs!B50+(Inputs!B51-Inputs!B50)*(T3-2020)/30)) -> 8.6266348 | U16: =MIN(Supply!U6,Supply!U15*(Inputs!B50+(Inputs!B51-Inputs!B50)*(U3-2020)/30)) -> 8.8649916 | V16: =MIN(Supply!V6,Supply!V15*(Inputs!B50+(Inputs!B51-Inputs!B50)*(V3-2020)/30)) -> 9.0945707 | W16: =MIN(Supply!W6,Supply!W15*(Inputs!B50+(Inputs!B51-Inputs!B50)*(W3-2020)/30)) -> 9.3150414 | X16: =MIN(Supply!X6,Supply!X15*(Inputs!B50+(Inputs!B51-Inputs!B50)*(X3-2020)/30)) -> 9.5260803 | Y16: =MIN(Supply!Y6,Supply!Y15*(Inputs!B50+(Inputs!B51-Inputs!B50)*(Y3-2020)/30)) -> 9.7273723 | Z16: =MIN(Supply!Z6,Supply!Z15*(Inputs!B50+(Inputs!B51-Inputs!B50)*(Z3-2020)/30)) -> 9.9186094 | AA16: =MIN(Supply!AA6,Supply!AA15*(Inputs!B50+(Inputs!B51-Inputs!B50)*(AA3-2020)/30)) -> 10.099491 | AB16: =MIN(Supply!AB6,Supply!AB15*(Inputs!B50+(Inputs!B51-Inputs!B50)*(AB3-2020)/30)) -> 10.269725 | AC16: =MIN(Supply!AC6,Supply!AC15*(Inputs!B50+(Inputs!B51-Inputs!B50)*(AC3-2020)/30)) -> 10.429026 | AD16: =MIN(Supply!AD6,Supply!AD15*(Inputs!B50+(Inputs!B51-Inputs!B50)*(AD3-2020)/30)) -> 10.577114 | AE16: =MIN(Supply!AE6,Supply!AE15*(Inputs!B50+(Inputs!B51-Inputs!B50)*(AE3-2020)/30)) -> 10.71372 | AF16: =MIN(Supply!AF6,Supply!AF15*(Inputs!B50+(Inputs!B51-Inputs!B50)*(AF3-2020)/30)) -> 10.838578 | AG16: =MIN(Supply!AG6,Supply!AG15*(Inputs!B50+(Inputs!B51-Inputs!B50)*(AG3-2020)/30)) -> 10.951431 | AH16: =MIN(Supply!AH6,Supply!AH15*(Inputs!B50+(Inputs!B51-Inputs!B50)*(AH3-2020)/30)) -> 11.052029
A17: Recycled water to agriculture | B17: M m³/yr | C17: Residual recycled water after trees | D17: =MIN(Supply!D14,MAX(Supply!D15-Supply!D16,0)) -> 7.8422198 | E17: =MIN(Supply!E14,MAX(Supply!E15-Supply!E16,0)) -> 8.6110502 | F17: =MIN(Supply!F14,MAX(Supply!F15-Supply!F16,0)) -> 9.3961504 | G17: =MIN(Supply!G14,MAX(Supply!G15-Supply!G16,0)) -> 10.197218 | H17: =MIN(Supply!H14,MAX(Supply!H15-Supply!H16,0)) -> 11.013953 | I17: =MIN(Supply!I14,MAX(Supply!I15-Supply!I16,0)) -> 11.846059 | J17: =MIN(Supply!J14,MAX(Supply!J15-Supply!J16,0)) -> 12.693243 | K17: =MIN(Supply!K14,MAX(Supply!K15-Supply!K16,0)) -> 7.4101849 | ... AH17: =MIN(Supply!AH14,MAX(Supply!AH15-Supply!AH16,0)) -> 25.788068
A18: Urban from groundwater | B18: M m³/yr | C18: Urban first draw on GW | D18: =MIN(Supply!D12*Inputs!B52,Supply!D8) -> 784.22198 | E18: =MIN(Supply!E12*Inputs!B52,Supply!E8) -> 794.86617 | F18: =MIN(Supply!F12*Inputs!B52,Supply!F8) -> 805.38432 | G18: =MIN(Supply!G12*Inputs!B52,Supply!G8) -> 815.77742 | H18: =MIN(Supply!H12*Inputs!B52,Supply!H8) -> 826.04645 | I18: =MIN(Supply!I12*Inputs!B52,Supply!I8) -> 836.1924 | J18: =MIN(Supply!J12*Inputs!B52,Supply!J8) -> 846.21623 | K18: =MIN(Supply!K12*Inputs!B52,Supply!K8) -> 856.11892 | L18: =MIN(Supply!L12*Inputs!B52,Supply!L8) -> 865.90143 | M18: =MIN(Supply!M12*Inputs!B52,Supply!M8) -> 875.56472 | N18: =MIN(Supply!N12*Inputs!B52,Supply!N8) -> 885.10972 | O18: =MIN(Supply!O12*Inputs!B52,Supply!O8) -> 894.53738 | P18: =MIN(Supply!P12*Inputs!B52,Supply!P8) -> 903.84864 | Q18: =MIN(Supply!Q12*Inputs!B52,Supply!Q8) -> 913.04442 | R18: =MIN(Supply!R12*Inputs!B52,Supply!R8) -> 922.12565 | S18: =MIN(Supply!S12*Inputs!B52,Supply!S8) -> 931.09324 | T18: =MIN(Supply!T12*Inputs!B52,Supply!T8) -> 939.9481 | U18: =MIN(Supply!U12*Inputs!B52,Supply!U8) -> 948.69113 | V18: =MIN(Supply!V12*Inputs!B52,Supply!V8) -> 957.32324 | W18: =MIN(Supply!W12*Inputs!B52,Supply!W8) -> 965.8453 | X18: =MIN(Supply!X12*Inputs!B52,Supply!X8) -> 974.25822 | Y18: =MIN(Supply!Y12*Inputs!B52,Supply!Y8) -> 982.56286 | Z18: =MIN(Supply!Z12*Inputs!B52,Supply!Z8) -> 990.76009 | AA18: =MIN(Supply!AA12*Inputs!B52,Supply!AA8) -> 998.85079 | AB18: =MIN(Supply!AB12*Inputs!B52,Supply!AB8) -> 1006.8358 | AC18: =MIN(Supply!AC12*Inputs!B52,Supply!AC8) -> 1014.716 | AD18: =MIN(Supply!AD12*Inputs!B52,Supply!AD8) -> 1022.4922 | AE18: =MIN(Supply!AE12*Inputs!B52,Supply!AE8) -> 1030.1653 | AF18: =MIN(Supply!AF12*Inputs!B52,Supply!AF8) -> 1037.7361 | AG18: =MIN(Supply!AG12*Inputs!B52,Supply!AG8) -> 1045.2055 | AH18: =MIN(Supply!AH12*Inputs!B52,Supply!AH8) -> 1052.5742
A19: Urban from GMMR | B19: M m³/yr | C19: Urban then GMMR | D19: =MIN(MAX(Supply!D12-D18,0)*Inputs!B53,MAX(Supply!D9,0)) -> 0 | E19: =MIN(MAX(Supply!E12-E18,0)*Inputs!B53,MAX(Supply!E9,0)) -> 0 | F19: =MIN(MAX(Supply!F12-F18,0)*Inputs!B53,MAX(Supply!F9,0)) -> 0 | G19: =MIN(MAX(Supply!G12-G18,0)*Inputs!B53,MAX(Supply!G9,0)) -> 0 | H19: =MIN(MAX(Supply!H12-H18,0)*Inputs!B53,MAX(Supply!H9,0)) -> 0 | I19: =MIN(MAX(Supply!I12-I18,0)*Inputs!B53,MAX(Supply!I9,0)) -> 0 | J19: =MIN(MAX(Supply!J12-J18,0)*Inputs!B53,MAX(Supply!J9,0)) -> 0 | K19: =MIN(MAX(Supply!K12-K18,0)*Inputs!B53,MAX(Supply!K9,0)) -> 0 | L19: =MIN(MAX(Supply!L12-L18,0)*Inputs!B53,MAX(Supply!L9,0)) -> 0 | M19: =MIN(MAX(Supply!M12-M18,0)*Inputs!B53,MAX(Supply!M9,0)) -> 0 | N19: =MIN(MAX(Supply!N12-N18,0)*Inputs!B53,MAX(Supply!N9,0)) -> 0 | O19: =MIN(MAX(Supply!O12-O18,0)*Inputs!B53,MAX(Supply!O9,0)) -> 0 | P19: =MIN(MAX(Supply!P12-P18,0)*Inputs!B53,MAX(Supply!P9,0)) -> 0 | Q19: =MIN(MAX(Supply!Q12-Q18,0)*Inputs!B53,MAX(Supply!Q9,0)) -> 0 | R19: =MIN(MAX(Supply!R12-R18,0)*Inputs!B53,MAX(Supply!R9,0)) -> 0 | S19: =MIN(MAX(Supply!S12-S18,0)*Inputs!B53,MAX(Supply!S9,0)) -> 0 | T19: =MIN(MAX(Supply!T12-T18,0)*Inputs!B53,MAX(Supply!T9,0)) -> 0 | U19: =MIN(MAX(Supply!U12-U18,0)*Inputs!B53,MAX(Supply!U9,0)) -> 0 | V19: =MIN(MAX(Supply!V12-V18,0)*Inputs!B53,MAX(Supply!V9,0)) -> 0 | W19: =MIN(MAX(Supply!W12-W18,0)*Inputs!B53,MAX(Supply!W9,0)) -> 0 | X19: =MIN(MAX(Supply!X12-X18,0)*Inputs!B53,MAX(Supply!X9,0)) -> 0 | Y19: =MIN(MAX(Supply!Y12-Y18,0)*Inputs!B53,MAX(Supply!Y9,0)) -> 0 | Z19: =MIN(MAX(Supply!Z12-Z18,0)*Inputs!B53,MAX(Supply!Z9,0)) -> 0 | AA19: =MIN(MAX(Supply!AA12-AA18,0)*Inputs!B53,MAX(Supply!AA9,0)) -> 0 | AB19: =MIN(MAX(Supply!AB12-AB18,0)*Inputs!B53,MAX(Supply!AB9,0)) -> 0 | AC19: =MIN(MAX(Supply!AC12-AC18,0)*Inputs!B53,MAX(Supply!AC9,0)) -> 0 | AD19: =MIN(MAX(Supply!AD12-AD18,0)*Inputs!B53,MAX(Supply!AD9,0)) -> 0 | AE19: =MIN(MAX(Supply!AE12-AE18,0)*Inputs!B53,MAX(Supply!AE9,0)) -> 0 | AF19: =MIN(MAX(Supply!AF12-AF18,0)*Inputs!B53,MAX(Supply!AF9,0)) -> 0 | AG19: =MIN(MAX(Supply!AG12-AG18,0)*Inputs!B53,MAX(Supply!AG9,0)) -> 0 | AH19: =MIN(MAX(Supply!AH12-AH18,0)*Inputs!B53,MAX(Supply!AH9,0)) -> 0
A20: Urban from desalination | B20: M m³/yr | C20: Urban residual desal | D20: =MAX(Supply!D12-D18-D19,0) -> 0 | E20: =MAX(Supply!E12-E18-E19,0) -> 0 | F20: =MAX(Supply!F12-F18-F19,0) -> 0 | G20: =MAX(Supply!G12-G18-G19,0) -> 0 | H20: =MAX(Supply!H12-H18-H19,0) -> 0 | I20: =MAX(Supply!I12-I18-I19,0) -> 0 | J20: =MAX(Supply!J12-J18-J19,0) -> 0 | K20: =MAX(Supply!K12-K18-K19,0) -> 0 | ... AH20: =MAX(Supply!AH12-AH18-AH19,0) -> 0
A21: Industrial from groundwater | B21: M m³/yr | C21: Industrial second draw on GW | D21: =MIN(Supply!D13*Inputs!B54,MAX(Supply!D8-D18,0)) -> 389.62702 | E21: =MIN(Supply!E13*Inputs!B54,MAX(Supply!E8-E18,0)) -> 403.93297 | F21: =MIN(Supply!F13*Inputs!B54,MAX(Supply!F8-F18,0)) -> 418.62358 | G21: =MIN(Supply!G13*Inputs!B54,MAX(Supply!G8-G18,0)) -> 433.70799 | H21: =MIN(Supply!H13*Inputs!B54,MAX(Supply!H8-H18,0)) -> 449.19554 | I21: =MIN(Supply!I13*Inputs!B54,MAX(Supply!I8-I18,0)) -> 465.0958 | J21: =MIN(Supply!J13*Inputs!B54,MAX(Supply!J8-J18,0)) -> 481.4185 | K21: =MIN(Supply!K13*Inputs!B54,MAX(Supply!K8-K18,0)) -> 498.17365 | L21: =MIN(Supply!L13*Inputs!B54,MAX(Supply!L8-L18,0)) -> 515.37143 | M21: =MIN(Supply!M13*Inputs!B54,MAX(Supply!M8-M18,0)) -> 533.02228 | N21: =MIN(Supply!N13*Inputs!B54,MAX(Supply!N8-N18,0)) -> 551.13685 | O21: =MIN(Supply!O13*Inputs!B54,MAX(Supply!O8-O18,0)) -> 569.72603 | P21: =MIN(Supply!P13*Inputs!B54,MAX(Supply!P8-P18,0)) -> 588.80096 | Q21: =MIN(Supply!Q13*Inputs!B54,MAX(Supply!Q8-Q18,0)) -> 608.373 | R21: =MIN(Supply!R13*Inputs!B54,MAX(Supply!R8-R18,0)) -> 628.4538 | S21: =MIN(Supply!S13*Inputs!B54,MAX(Supply!S8-S18,0)) -> 649.05523 | T21: =MIN(Supply!T13*Inputs!B54,MAX(Supply!T8-T18,0)) -> 670.18945 | U21: =MIN(Supply!U13*Inputs!B54,MAX(Supply!U8-U18,0)) -> 691.86886 | V21: =MIN(Supply!V13*Inputs!B54,MAX(Supply!V8-V18,0)) -> 714.10614 | W21: =MIN(Supply!W13*Inputs!B54,MAX(Supply!W8-W18,0)) -> 736.91428 | X21: =MIN(Supply!X13*Inputs!B54,MAX(Supply!X8-X18,0)) -> 760.3065 | Y21: =MIN(Supply!Y13*Inputs!B54,MAX(Supply!Y8-Y18,0)) -> 784.29636 | Z21: =MIN(Supply!Z13*Inputs!B54,MAX(Supply!Z8-Z18,0)) -> 808.89768 | AA21: =MIN(Supply!AA13*Inputs!B54,MAX(Supply!AA8-AA18,0)) -> 834.1246 | AB21: =MIN(Supply!AB13*Inputs!B54,MAX(Supply!AB8-AB18,0)) -> 859.99157 | AC21: =MIN(Supply!AC13*Inputs!B54,MAX(Supply!AC8-AC18,0)) -> 886.51336 | AD21: =MIN(Supply!AD13*Inputs!B54,MAX(Supply!AD8-AD18,0)) -> 913.70504 | AE21: =MIN(Supply!AE13*Inputs!B54,MAX(Supply!AE8-AE18,0)) -> 941.58203 | AF21: =MIN(Supply!AF13*Inputs!B54,MAX(Supply!AF8-AF18,0)) -> 970.16008 | AG21: =MIN(Supply!AG13*Inputs!B54,MAX(Supply!AG8-AG18,0)) -> 999.45527 | AH21: =MIN(Supply!AH13*Inputs!B54,MAX(Supply!AH8-AH18,0)) -> 1029.4841
A22: Industrial from GMMR | B22: M m³/yr | C22: Industrial then GMMR | D22: =MIN(MAX(Supply!D13-D21,0)*Inputs!B55,MAX(Supply!D9-D19,0)) -> 0 | E22: =MIN(MAX(Supply!E13-E21,0)*Inputs!B55,MAX(Supply!E9-E19,0)) -> 0 | F22: =MIN(MAX(Supply!F13-F21,0)*Inputs!B55,MAX(Supply!F9-F19,0)) -> 0 | G22: =MIN(MAX(Supply!G13-G21,0)*Inputs!B55,MAX(Supply!G9-G19,0)) -> 0 | H22: =MIN(MAX(Supply!H13-H21,0)*Inputs!B55,MAX(Supply!H9-H19,0)) -> 0 | I22: =MIN(MAX(Supply!I13-I21,0)*Inputs!B55,MAX(Supply!I9-I19,0)) -> 0 | J22: =MIN(MAX(Supply!J13-J21,0)*Inputs!B55,MAX(Supply!J9-J19,0)) -> 0 | K22: =MIN(MAX(Supply!K13-K21,0)*Inputs!B55,MAX(Supply!K9-K19,0)) -> 0 | L22: =MIN(MAX(Supply!L13-L21,0)*Inputs!B55,MAX(Supply!L9-L19,0)) -> 0 | M22: =MIN(MAX(Supply!M13-M21,0)*Inputs!B55,MAX(Supply!M9-M19,0)) -> 0 | N22: =MIN(MAX(Supply!N13-N21,0)*Inputs!B55,MAX(Supply!N9-N19,0)) -> 0 | O22: =MIN(MAX(Supply!O13-O21,0)*Inputs!B55,MAX(Supply!O9-O19,0)) -> 0 | P22: =MIN(MAX(Supply!P13-P21,0)*Inputs!B55,MAX(Supply!P9-P19,0)) -> 0 | Q22: =MIN(MAX(Supply!Q13-Q21,0)*Inputs!B55,MAX(Supply!Q9-Q19,0)) -> 0 | R22: =MIN(MAX(Supply!R13-R21,0)*Inputs!B55,MAX(Supply!R9-R19,0)) -> 0 | S22: =MIN(MAX(Supply!S13-S21,0)*Inputs!B55,MAX(Supply!S9-S19,0)) -> 0 | T22: =MIN(MAX(Supply!T13-T21,0)*Inputs!B55,MAX(Supply!T9-T19,0)) -> 0 | U22: =MIN(MAX(Supply!U13-U21,0)*Inputs!B55,MAX(Supply!U9-U19,0)) -> 0 | V22: =MIN(MAX(Supply!V13-V21,0)*Inputs!B55,MAX(Supply!V9-V19,0)) -> 0 | W22: =MIN(MAX(Supply!W13-W21,0)*Inputs!B55,MAX(Supply!W9-W19,0)) -> 0 | X22: =MIN(MAX(Supply!X13-X21,0)*Inputs!B55,MAX(Supply!X9-X19,0)) -> 0 | Y22: =MIN(MAX(Supply!Y13-Y21,0)*Inputs!B55,MAX(Supply!Y9-Y19,0)) -> 0 | Z22: =MIN(MAX(Supply!Z13-Z21,0)*Inputs!B55,MAX(Supply!Z9-Z19,0)) -> 0 | AA22: =MIN(MAX(Supply!AA13-AA21,0)*Inputs!B55,MAX(Supply!AA9-AA19,0)) -> 0 | AB22: =MIN(MAX(Supply!AB13-AB21,0)*Inputs!B55,MAX(Supply!AB9-AB19,0)) -> 0 | AC22: =MIN(MAX(Supply!AC13-AC21,0)*Inputs!B55,MAX(Supply!AC9-AC19,0)) -> 0 | AD22: =MIN(MAX(Supply!AD13-AD21,0)*Inputs!B55,MAX(Supply!AD9-AD19,0)) -> 0 | AE22: =MIN(MAX(Supply!AE13-AE21,0)*Inputs!B55,MAX(Supply!AE9-AE19,0)) -> 0 | AF22: =MIN(MAX(Supply!AF13-AF21,0)*Inputs!B55,MAX(Supply!AF9-AF19,0)) -> 0 | AG22: =MIN(MAX(Supply!AG13-AG21,0)*Inputs!B55,MAX(Supply!AG9-AG19,0)) -> 0 | AH22: =MIN(MAX(Supply!AH13-AH21,0)*Inputs!B55,MAX(Supply!AH9-AH19,0)) -> 0
A23: Industrial from desalination | B23: M m³/yr | C23: Industrial residual desal | D23: =MAX(Supply!D13-D21-D22,0) -> 0 | E23: =MAX(Supply!E13-E21-E22,0) -> 0 | F23: =MAX(Supply!F13-F21-F22,0) -> 0 | G23: =MAX(Supply!G13-G21-G22,0) -> 0 | H23: =MAX(Supply!H13-H21-H22,0) -> 0 | I23: =MAX(Supply!I13-I21-I22,0) -> 0 | J23: =MAX(Supply!J13-J21-J22,0) -> 0 | K23: =MAX(Supply!K13-K21-K22,0) -> 0 | ... AH23: =MAX(Supply!AH13-AH21-AH22,0) -> 0
A24: Agriculture from groundwater | B24: M m³/yr | C24: Agriculture draw on GW after recycled | D24: =MIN(MAX(D14-D17-D7,0)*Inputs!$B$56,MAX(D8-D18-D21,0)) -> 4826.151 | E24: =MIN(MAX(E14-E17-E7,0)*Inputs!$B$56,MAX(E8-E18-E21,0)) -> 4711.2009 | F24: =MIN(MAX(F14-F17-F7,0)*Inputs!$B$56,MAX(F8-F18-F21,0)) -> 4597.3421 | G24: =MIN(MAX(G14-G17-G7,0)*Inputs!$B$56,MAX(G8-G18-G21,0)) -> 4484.5443 | H24: =MIN(MAX(H14-H17-H7,0)*Inputs!$B$56,MAX(H8-H18-H21,0)) -> 4372.7773 | I24: =MIN(MAX(I14-I17-I7,0)*Inputs!$B$56,MAX(I8-I18-I21,0)) -> 4262.0108 | J24: =MIN(MAX(J14-J17-J7,0)*Inputs!$B$56,MAX(J8-J18-J21,0)) -> 4152.2148 | K24: =MIN(MAX(K14-K17-K7,0)*Inputs!$B$56,MAX(K8-K18-K21,0)) -> 4043.3592 | ... AH24: =MIN(MAX(AH14-AH17-AH7,0)*Inputs!$B$56,MAX(AH8-AH18-AH21,0)) -> 1730.6903
A25: Agriculture from GMMR | B25: M m³/yr | C25: Agriculture then GMMR | D25: =MIN(MAX(MAX(D14-D17-D7,0)-D24,0)*Inputs!$B$57,MAX(D9-D19-D22,0)) -> 912 | E25: =MIN(MAX(MAX(E14-E17-E7,0)-E24,0)*Inputs!$B$57,MAX(E9-E19-E22,0)) -> 893.76 | F25: =MIN(MAX(MAX(F14-F17-F7,0)-F24,0)*Inputs!$B$57,MAX(F9-F19-F22,0)) -> 875.8848 | G25: =MIN(MAX(MAX(G14-G17-G7,0)-G24,0)*Inputs!$B$57,MAX(G9-G19-G22,0)) -> 858.3671 | H25: =MIN(MAX(MAX(H14-H17-H7,0)-H24,0)*Inputs!$B$57,MAX(H9-H19-H22,0)) -> 841.19976 | I25: =MIN(MAX(MAX(I14-I17-I7,0)-I24,0)*Inputs!$B$57,MAX(I9-I19-I22,0)) -> 824.37577 | J25: =MIN(MAX(MAX(J14-J17-J7,0)-J24,0)*Inputs!$B$57,MAX(J9-J19-J22,0)) -> 807.88825 | K25: =MIN(MAX(MAX(K14-K17-K7,0)-K24,0)*Inputs!$B$57,MAX(K9-K19-K22,0)) -> 791.73049 | ... AH25: =MIN(MAX(MAX(AH14-AH17-AH7,0)-AH24,0)*Inputs!$B$57,MAX(AH9-AH19-AH22,0)) -> 497.4817
A26: Agriculture from desalination | B26: M m³/yr | C26: Agriculture residual desal | D26: =MIN(MAX(D33-D20-D23-D27,0),MAX(MAX(D14-D17-D7,0)-D24-D25,0)) -> 20 | E26: =MIN(MAX(E33-E20-E23-E27,0),MAX(MAX(E14-E17-E7,0)-E24-E25,0)) -> 44.333333 | F26: =MIN(MAX(F33-F20-F23-F27,0),MAX(MAX(F14-F17-F7,0)-F24-F25,0)) -> 68.666667 | G26: =MIN(MAX(G33-G20-G23-G27,0),MAX(MAX(G14-G17-G7,0)-G24-G25,0)) -> 93 | H26: =MIN(MAX(H33-H20-H23-H27,0),MAX(MAX(H14-H17-H7,0)-H24-H25,0)) -> 117.33333 | I26: =MIN(MAX(I33-I20-I23-I27,0),MAX(MAX(I14-I17-I7,0)-I24-I25,0)) -> 141.66667 | J26: =MIN(MAX(J33-J20-J23-J27,0),MAX(MAX(J14-J17-J7,0)-J24-J25,0)) -> 166 | K26: =MIN(MAX(K33-K20-K23-K27,0),MAX(MAX(K14-K17-K7,0)-K24-K25,0)) -> 141.72836 | ... AH26: =MIN(MAX(AH33-AH20-AH23-AH27,0),MAX(MAX(AH14-AH17-AH7,0)-AH24-AH25,0)) -> 213.55203
A27: Trees from desalination | B27: M m³/yr | C27: Tree residual after recycled | D27: =MAX(Supply!D6-Supply!D16,0) -> 0 | E27: =MAX(Supply!E6-Supply!E16,0) -> 0 | F27: =MAX(Supply!F6-Supply!F16,0) -> 0 | G27: =MAX(Supply!G6-Supply!G16,0) -> 0 | H27: =MAX(Supply!H6-Supply!H16,0) -> 0 | I27: =MAX(Supply!I6-Supply!I16,0) -> 0 | J27: =MAX(Supply!J6-Supply!J16,0) -> 0 | K27: =MAX(Supply!K6-Supply!K16,0) -> 48.604969 | ... AH27: =MAX(Supply!AH6-Supply!AH16,0) -> 536.44797
A28: CHECK: allocated demand incl recycled | B28: M m³/yr | C28: Should equal total demand | D28: =D18+D19+D20+D21+D22+D23+D17+D24+D25+D26+D16+D27+D7+D39 -> 7039.5344 | E28: =E18+E19+E20+E21+E22+E23+E17+E24+E25+E26+E16+E27+E7+E39 -> 7126.1736 | F28: =F18+F19+F20+F21+F22+F23+F17+F24+F25+F26+F16+F27+F7+F39 -> 7211.709 | G28: =G18+G19+G20+G21+G22+G23+G17+G24+G25+G26+G16+G27+G7+G39 -> 7296.1685 | H28: =H18+H19+H20+H21+H22+H23+H17+H24+H25+H26+H16+H27+H7+H39 -> 7379.5803 | I28: =I18+I19+I20+I21+I22+I23+I17+I24+I25+I26+I16+I27+I7+I39 -> 7461.9721 | J28: =J18+J19+J20+J21+J22+J23+J17+J24+J25+J26+J16+J27+J7+J39 -> 7543.3721 | K28: =K18+K19+K20+K21+K22+K23+K17+K24+K25+K26+K16+K27+K7+K39 -> 7678.5583 | ... AH28: =AH18+AH19+AH20+AH21+AH22+AH23+AH17+AH24+AH25+AH26+AH16+AH27+AH7+AH39 -> 9820.5736
A29: Desalination required (total) | B29: M m³/yr | C29: MAX(0, Total demand − GW − GMMR) | D29: =D20+D23+D26+D27 -> 20 | E29: =Supply!E20+Supply!E23+Supply!E26+Supply!E27 -> 44.333333 | F29: =Supply!F20+Supply!F23+Supply!F26+Supply!F27 -> 68.666667 | G29: =Supply!G20+Supply!G23+Supply!G26+Supply!G27 -> 93 | H29: =Supply!H20+Supply!H23+Supply!H26+Supply!H27 -> 117.33333 | I29: =Supply!I20+Supply!I23+Supply!I26+Supply!I27 -> 141.66667 | J29: =Supply!J20+Supply!J23+Supply!J26+Supply!J27 -> 166 | K29: =Supply!K20+Supply!K23+Supply!K26+Supply!K27 -> 190.33333 | L29: =Supply!L20+Supply!L23+Supply!L26+Supply!L27 -> 214.66667 | ... AH29: =Supply!AH20+Supply!AH23+Supply!AH26+Supply!AH27 -> 750
A30: Desalination if NO tree programme | B30: M m³/yr | C30: MAX(0, (Demand−Tree) − GW − GMMR) | D30: =D20+D23+MIN(MAX(D33-D20-D23,0),D26+D39) -> 20 | E30: =E20+E23+MIN(MAX(E33-E20-E23,0),E26+E39) -> 44.333333 | F30: =F20+F23+MIN(MAX(F33-F20-F23,0),F26+F39) -> 68.666667 | G30: =G20+G23+MIN(MAX(G33-G20-G23,0),G26+G39) -> 93 | H30: =H20+H23+MIN(MAX(H33-H20-H23,0),H26+H39) -> 117.33333 | I30: =I20+I23+MIN(MAX(I33-I20-I23,0),I26+I39) -> 141.66667 | J30: =J20+J23+MIN(MAX(J33-J20-J23,0),J26+J39) -> 166 | K30: =K20+K23+MIN(MAX(K33-K20-K23,0),K26+K39) -> 190.33333 | ... AH30: =AH20+AH23+MIN(MAX(AH33-AH20-AH23,0),AH26+AH39) -> 750
A31: Incremental desal for tree programme | B31: M m³/yr | C31: Row 12 − Row 13 | D31: =D29-D30 -> 0 | E31: =Supply!E29-Supply!E30 -> 0 | F31: =Supply!F29-Supply!F30 -> 0 | G31: =Supply!G29-Supply!G30 -> 0 | H31: =Supply!H29-Supply!H30 -> 0 | I31: =Supply!I29-Supply!I30 -> 0 | J31: =Supply!J29-Supply!J30 -> 0 | K31: =Supply!K29-Supply!K30 -> 0 | L31: =Supply!L29-Supply!L30 -> 0 | ... AH31: =Supply!AH29-Supply!AH30 -> 0
A32: → equivalent SWRO capacity | B32: m³/day | C32: Row 14 × 1e6 / 365 | D32: =D31*1000000/365 -> 0 | E32: =Supply!E31*1000000/365 -> 0 | F32: =Supply!F31*1000000/365 -> 0 | G32: =Supply!G31*1000000/365 -> 0 | H32: =Supply!H31*1000000/365 -> 0 | I32: =Supply!I31*1000000/365 -> 0 | J32: =Supply!J31*1000000/365 -> 0 | K32: =Supply!K31*1000000/365 -> 0 | L32: =Supply!L31*1000000/365 -> 0 | ... AH32: =Supply!AH31*1000000/365 -> 0
A33: Desalination capacity (max) | B33: M m³/yr | C33: Linear from 2020 baseline to 2050 max (per report p.92) | D33: =Inputs!$B$32+(Inputs!$B$38-Inputs!$B$32)*(D$3-2020)/30 -> 20 | E33: =Inputs!$B$32+(Inputs!$B$38-Inputs!$B$32)*(E$3-2020)/30 -> 44.333333 | F33: =Inputs!$B$32+(Inputs!$B$38-Inputs!$B$32)*(F$3-2020)/30 -> 68.666667 | G33: =Inputs!$B$32+(Inputs!$B$38-Inputs!$B$32)*(G$3-2020)/30 -> 93 | H33: =Inputs!$B$32+(Inputs!$B$38-Inputs!$B$32)*(H$3-2020)/30 -> 117.33333 | I33: =Inputs!$B$32+(Inputs!$B$38-Inputs!$B$32)*(I$3-2020)/30 -> 141.66667 | J33: =Inputs!$B$32+(Inputs!$B$38-Inputs!$B$32)*(J$3-2020)/30 -> 166 | K33: =Inputs!$B$32+(Inputs!$B$38-Inputs!$B$32)*(K$3-2020)/30 -> 190.33333 | ... AH33: =Inputs!$B$32+(Inputs!$B$38-Inputs!$B$32)*(AH$3-2020)/30 -> 750
A34: Recycled water used (total) | B34: M m³/yr | C34: Recycled water to trees + agriculture | D34: =Supply!D16+Supply!D17 -> 7.8422198 | E34: =Supply!E16+Supply!E17 -> 8.6110502 | F34: =Supply!F16+Supply!F17 -> 9.3961504 | G34: =Supply!G16+Supply!G17 -> 10.197218 | H34: =Supply!H16+Supply!H17 -> 11.013953 | I34: =Supply!I16+Supply!I17 -> 11.846059 | J34: =Supply!J16+Supply!J17 -> 12.693243 | K34: =Supply!K16+Supply!K17 -> 13.555216 | ... AH34: =Supply!AH16+Supply!AH17 -> 36.840097
A35: Total water supply (incl. recycled) | B35: M m³/yr | C35: GW + GMMR + desal + recycled | D35: =D18+D21+D24+D39+D19+D22+D25+D7+D29+D34 -> 7039.5344 | E35: =E18+E21+E24+E39+E19+E22+E25+E7+E29+E34 -> 7126.1736 | F35: =F18+F21+F24+F39+F19+F22+F25+F7+F29+F34 -> 7211.709 | G35: =G18+G21+G24+G39+G19+G22+G25+G7+G29+G34 -> 7296.1685 | H35: =H18+H21+H24+H39+H19+H22+H25+H7+H29+H34 -> 7379.5803 | I35: =I18+I21+I24+I39+I19+I22+I25+I7+I29+I34 -> 7461.9721 | J35: =J18+J21+J24+J39+J19+J22+J25+J7+J29+J34 -> 7543.3721 | K35: =K18+K21+K24+K39+K19+K22+K25+K7+K29+K34 -> 7678.5583 | ... AH35: =AH18+AH21+AH24+AH39+AH19+AH22+AH25+AH7+AH29+AH34 -> 9820.5736
A36: Share: Local groundwater | B36: % | D36: =(D18+D21+D24+D39)/D5 -> 0.85796756 | E36: =(E18+E21+E24+E39)/E5 -> 0.85881562 | F36: =(F18+F21+F24+F39)/F5 -> 0.85956815 | G36: =(G18+G21+G24+G39)/G5 -> 0.86023044 | H36: =(H18+H21+H24+H39)/H5 -> 0.86080742 | I36: =(I18+I21+I24+I39)/I5 -> 0.8613037 | J36: =(J18+J21+J24+J39)/J5 -> 0.8617236 | K36: =(K18+K21+K24+K39)/K5 -> 0.86305464 | ... AH36: =(AH18+AH21+AH24+AH39)/AH5 -> 0.86470202
A37: Share: GMMR pipeline | B37: % | D37: =(D19+D22+D25)/D5 -> 0.12955402 | E37: =(E19+E22+E25)/E5 -> 0.12541934 | F37: =(F19+F22+F25)/F5 -> 0.12145315 | G37: =(G19+G22+G25)/G5 -> 0.11764628 | H37: =(H19+H22+H25)/H5 -> 0.11399019 | I37: =(I19+I22+I25)/I5 -> 0.11047693 | J37: =(J19+J22+J25)/J5 -> 0.10709909 | K37: =(K19+K22+K25)/K5 -> 0.10310926 | ... AH37: =(AH19+AH22+AH25)/AH5 -> 0.050657092
A38: Share: Desalination | B38: % | D38: =Supply!D29/Supply!D5 -> 0.002841097 | E38: =Supply!E29/Supply!E5 -> 0.0062211975 | F38: =Supply!F29/Supply!F5 -> 0.0095215526 | G38: =Supply!G29/Supply!G5 -> 0.012746416 | H38: =Supply!H29/Supply!H5 -> 0.01589973 | I38: =Supply!I29/Supply!I5 -> 0.018985151 | J38: =Supply!J29/Supply!J5 -> 0.022006073 | K38: =Supply!K29/Supply!K5 -> 0.024787639 | ... AH38: =Supply!AH29/Supply!AH5 -> 0.076370284
A39: Ag from groundwater (overdraft) | B39: M m³/yr | C39: Residual ag demand absorbed by unsustainable private wells when desal hits cap | D39: =MAX(MAX(D14-D17-D7,0)-D24-D25-D26,0) -> 39.692163 | E39: =MAX(MAX(E14-E17-E7,0)-E24-E25-E26,0) -> 210.06921 | F39: =MAX(MAX(F14-F17-F7,0)-F24-F25-F26,0) -> 377.60536 | G39: =MAX(MAX(G14-G17-G7,0)-G24-G25-G26,0) -> 542.35653 | H39: =MAX(MAX(H14-H17-H7,0)-H24-H25-H26,0) -> 704.37815 | I39: =MAX(MAX(I14-I17-I7,0)-I24-I25-I26,0) -> 863.7252 | J39: =MAX(MAX(J14-J17-J7,0)-J24-J25-J26,0) -> 1020.4523 | K39: =MAX(MAX(K14-K17-K7,0)-K24-K25-K26,0) -> 1229.3635 | ... AH39: =MAX(MAX(AH14-AH17-AH7,0)-AH24-AH25-AH26,0) -> 4679.1213
A40: CHECK: Supply − Demand | B40: M m³/yr | C40: Should equal zero | D40: =Supply!D35-Supply!D5 -> 0 | E40: =Supply!E35-Supply!E5 -> 0 | F40: =Supply!F35-Supply!F5 -> 0 | G40: =Supply!G35-Supply!G5 -> 0 | H40: =Supply!H35-Supply!H5 -> 0 | I40: =Supply!I35-Supply!I5 -> 0 | J40: =Supply!J35-Supply!J5 -> 0 | K40: =Supply!K35-Supply!K5 -> 0 | ... AH40: =Supply!AH35-Supply!AH5 -> 0
A41: Share: Surface water | B41: % | C41: Surface water used / total demand | D41: =D7/D5 -> 0.008523291 | E41: =E7/E5 -> 0.0083354691 | F41: =F7/F5 -> 0.0081542392 | G41: =G7/G5 -> 0.0079792482 | H41: =H7/H5 -> 0.0078101679 | I41: =I7/I5 -> 0.0076466921 | J41: =J7/J5 -> 0.0074885354 | K41: =K7/K5 -> 0.0072831278 | ... AH41: =AH7/AH5 -> 0.0045192902
A42: CONDITIONAL SCENARIO — higher treated wastewater recovery
...

Sheet Energy
A1: Electricity Demand for Water Supply — Libya (2020–2050)
A3: Metric | B3: Units | C3: Notes | D3: 2020 | E3: 2021 | F3: 2022 | G3: 2023 | H3: 2024 | I3: 2025 | J3: 2026 | K3: 2027 | L3: 2028 | M3: 2029 | N3: 2030 | O3: 2031 | P3: 2032 | Q3: 2033 | R3: 2034 | S3: 2035 | T3: 2036 | U3: 2037 | V3: 2038 | W3: 2039 | X3: 2040 | Y3: 2041 | Z3: 2042 | AA3: 2043 | AB3: 2044 | AC3: 2045 | AD3: 2046 | AE3: 2047 | AF3: 2048 | AG3: 2049 | AH3: 2050
A5: EI local groundwater | B5: kWh/m³ | C5: EI_GW_2020 × (1+rise)^(year-2020) | D5: =Inputs!$B$26*(1+Inputs!$B$27)^(D$3-2020) -> 0.35 | E5: =Inputs!$B$26*(1+Inputs!$B$27)^(E$3-2020) -> 0.35525 | F5: =Inputs!$B$26*(1+Inputs!$B$27)^(F$3-2020) -> 0.36057875 | G5: =Inputs!$B$26*(1+Inputs!$B$27)^(G$3-2020) -> 0.36598743 | H5: =Inputs!$B$26*(1+Inputs!$B$27)^(H$3-2020) -> 0.37147724 | I5: =Inputs!$B$26*(1+Inputs!$B$27)^(I$3-2020) -> 0.3770494 | J5: =Inputs!$B$26*(1+Inputs!$B$27)^(J$3-2020) -> 0.38270514 | K5: =Inputs!$B$26*(1+Inputs!$B$27)^(K$3-2020) -> 0.38844572 | ... AH5: =Inputs!$B$26*(1+Inputs!$B$27)^(AH$3-2020) -> 0.54707808
A6: EI pipeline (GMMR) | B6: kWh/m³ | C6: EI_pipe × (1+rise)^(year-2020) | D6: =Inputs!$B$28*(1+Inputs!$B$29)^(D$3-2020) -> 1.8 | E6: =Inputs!$B$28*(1+Inputs!$B$29)^(E$3-2020) -> 1.818 | F6: =Inputs!$B$28*(1+Inputs!$B$29)^(F$3-2020) -> 1.83618 | G6: =Inputs!$B$28*(1+Inputs!$B$29)^(G$3-2020) -> 1.8545418 | H6: =Inputs!$B$28*(1+Inputs!$B$29)^(H$3-2020) -> 1.8730872 | I6: =Inputs!$B$28*(1+Inputs!$B$29)^(I$3-2020) -> 1.8918181 | J6: =Inputs!$B$28*(1+Inputs!$B$29)^(J$3-2020) -> 1.9107363 | K6: =Inputs!$B$28*(1+Inputs!$B$29)^(K$3-2020) -> 1.9298436 | ... AH6: =Inputs!$B$28*(1+Inputs!$B$29)^(AH$3-2020) -> 2.426128
A7: EI desalination (SWRO) | B7: kWh/m³ | C7: Linear from EI_2020 to EI_2050 | D7: =Inputs!$B$30+(Inputs!$B$31-Inputs!$B$30)*(D$3-2020)/30 -> 3.5 | E7: =Inputs!$B$30+(Inputs!$B$31-Inputs!$B$30)*(E$3-2020)/30 -> 3.4833333 | F7: =Inputs!$B$30+(Inputs!$B$31-Inputs!$B$30)*(F$3-2020)/30 -> 3.4666667 | G7: =Inputs!$B$30+(Inputs!$B$31-Inputs!$B$30)*(G$3-2020)/30 -> 3.45 | H7: =Inputs!$B$30+(Inputs!$B$31-Inputs!$B$30)*(H$3-2020)/30 -> 3.4333333 | I7: =Inputs!$B$30+(Inputs!$B$31-Inputs!$B$30)*(I$3-2020)/30 -> 3.4166667 | J7: =Inputs!$B$30+(Inputs!$B$31-Inputs!$B$30)*(J$3-2020)/30 -> 3.4 | K7: =Inputs!$B$30+(Inputs!$B$31-Inputs!$B$30)*(K$3-2020)/30 -> 3.3833333 | ... AH7: =Inputs!$B$30+(Inputs!$B$31-Inputs!$B$30)*(AH$3-2020)/30 -> 3
A8: Energy: Surface water | B8: GWh/yr | C8: EI × volume (low) | D8: =0.2*Supply!D7 -> 12 | E8: =0.2*Supply!E7 -> 11.88 | F8: =0.2*Supply!F7 -> 11.7612 | G8: =0.2*Supply!G7 -> 11.643588 | H8: =0.2*Supply!H7 -> 11.527152 | I8: =0.2*Supply!I7 -> 11.411881 | J8: =0.2*Supply!J7 -> 11.297762 | K8: =0.2*Supply!K7 -> 11.184784 | ... AH8: =0.2*Supply!AH7 -> 8.8764045
