Workbook

Sheet README
A1: Libya Water–Energy Nexus Model (2020–2050)
A3: Purpose
A4: A simple annual-timestep model that translates population, GDP and a 100-million-tree afforestation programme into sector water demand, allocates demand across three supplies (local groundwater, pipeline transfers from southern fossil aquifers via the Great Man-Made River, and seawater desalination), and computes the associated electricity demand.
A6: Country context
A7: Libya is one of the most water-stressed countries in the world. Agriculture accounts for ~83% of withdrawals, municipal ~12%, industrial ~5% (FAO AQUASTAT via UNICEF 2022). Total renewable water resources are ~105 m³/cap/yr; >90% of supply comes from non-renewable fossil groundwater. The Great Man-Made River (GMMR) conveys water ~1,000–2,000 km from the Nubian Sandstone Aquifer in the south to coastal demand centres. It is modelled here under "pipeline imports" and is assumed to DECLINE over the model horizon — reflecting aquifer drawdown (estimated depletion within ~60 yr per Lonergan / Columbia State of the Planet 2011), infrastructure damage (by 2019, 101 of 479 western wells dismantled, MEI 2024) and stalled Phase III/IV works.
A9: Model logic
A10: 1. Population: linear interpolation between UN WPP 2024 medium-variant 2020 (6.735M) and 2050 (9.261M).
A11: 2. GDP per capita: user-specified CAGR (default 2.5%/yr).
A12: 3. Sector demand:
A13: • Domestic = L/cap/day × Population × 365 (with efficiency trend)
A14: • Industrial = (m³ / $1000 GDP) × Total GDP (with efficiency trend)
A15: • Agricultural = L/cap/day × Population × 365 (with efficiency trend)
... A70: UPDATE v3: allocation logic made more user-editable through new Inputs rows for recycled-water split and source-priority shares by sector.

Sheet Inputs
A1: Libya Water-Energy Model — Inputs & Assumptions
A3: Parameter | B3: Value | C3: Units | D3: Source / Note
A5: DEMOGRAPHICS & ECONOMY
A6: Population 2020 | B6: 6735277 | C6: persons | D6: UN WPP 2024 medium variant | E6: *
A7: Population 2050 | B7: 10506952 | C7: persons | D7: Matched to SISEPUEDE | E7: *
A8: GDP per capita 2020 | B8: 6357 | C8: USD (current) | D8: World Bank WDI 2020 (volatile) | E8: *
A9: GDP per capita CAGR | B9: 0.028 | C9: per year | D9: Matched to SISEPUEDE | E9: *
A11: WATER DEMAND INTENSITIES
A12: Domestic water use 2020 | B12: 415 | C12: L/cap/day | D12: UNICEF 2022 citing Libya VNR 2020
A13: Domestic efficiency trend | B13: -0.005 | C13: per year | D13: Assumption: leak reduction, metering
A14: Industrial water intensity 2020 | B14: 5.8 | C14: m³ per $1000 GDP | D14: Derived: AQUASTAT industrial share ÷ WB GDP 2020
A15: Industrial efficiency trend | B15: -0.01 | C15: per year | D15: Assumption: process efficiency
A16: Agricultural water use 2020 | B16: =1990*0.75 -> 1492.5 | C16: L/cap/day | D16: UNICEF 2022 citing AQUASTAT (~83% of total)
A17: Agricultural efficiency trend | B17: -0.008 | C17: per year | D17: Assumption: irrigation modernization
A19: SUPPLY CAPACITY & TRENDS
A20: Local groundwater yield 2020 | B20: 3500 | C20: M m³/yr | D20: Residual estimate: total use ~5.5 Gm³ − GMMR − desal
A21: Groundwater decline rate | B21: -0.015 | C21: per year | D21: Overdraft & coastal salinization
A22: GMMR pipeline delivery 2020 | B22: 912 | C22: M m³/yr | D22: 2.5 Mm³/day × 365 (MEI 2024) | E22: Great Man Made River
A23: GMMR decline rate | B23: -0.02 | C23: per year | D23: Aquifer depletion (Lonergan ~60 yr) + infra decay
A25: ENERGY INTENSITIES
A26: EI local groundwater 2020 | B26: =0.7*0.5 -> 0.35 | C26: kWh/m³ | D26: USGS/Denver 1.2-1.8 deep; 0.7 shallow/coastal We assumed that the majoriry of private-farm groundwater runs on diesel gensets and is not billed through the grid, given that FAO/World Bank water-sector assessments for the countrt, we can assume that private-farm pumping is largely unmetered and off-grid (approx 50%). Thus the energy intensity of this is scaled to what it is actually being demanded by the electricity grid.
A27: EI groundwater rise rate | B27: 0.015 | C27: per year | D27: Water-table drawdown raises lift
A28: EI pipeline (GMMR) 2020 | B28: 1.8 | C28: kWh/m³ | D28: Deep-well (500 m) + long conveyance; lit. 1.5-2.0
A29: EI pipeline rise rate | B29: 0.01 | C29: per year | D29: Rising lift as Nubian aquifer draws down
A30: EI desalination 2020 | B30: 3.5 | C30: kWh/m³ | D30: SWRO with ERDs (IRENA; ScienceDirect)
A31: EI desalination 2050 | B31: 3 | C31: kWh/m³ | D31: Efficiency gains toward 2.8 state-of-art
A33: 100-MILLION TREE AFFORESTATION PROGRAMME
A34: Programme start year | B34: 2026 | C34: year | D34: Assumption — edit to shift timeline
A35: Planting ramp (years) | B35: 10 | C35: years | D35: Linear planting of target over this period
A36: Target trees | B36: 100000000 | C36: trees | D36: Programme ambition (100 million)
A37: Water per tree | B37: 15 | C37: L/tree/day | D37: Drip-irrigated drought-tolerant; Becker et al. 2022; USU ext. ~41 L/d for mature arid shade tree
A39: RECYCLED WATER & ALLOCATION
A40: Parameter | B40: Value | C40: Units | D40: Source / Note
A41: Urban wastewater recovery share 2020 | B41: 0.15 | C41: share of urban water demand met | D41: Assumption: recoverable municipal wastewater
A42: Urban wastewater recovery share 2050 | B42: 0.35 | C42: share of urban water demand met | D42: Assumption: better sewerage, treatment, and reuse
A43: Recycled water split to trees 2020 | B43: 0.5 | C43: share of recycled water | D43: Allocation priority from recycled water
A44: Recycled water split to trees 2050 | B44: 0.3 | C44: share of recycled water | D44: Less tree priority over time as ag reuse scales
A45: EI recycled water 2020 | B45: 0.8 | C45: kWh/m³ | D45: Assumption: treatment + pumping for non-potable reuse
A46: EI recycled water 2050 | B46: 0.65 | C46: kWh/m³ | D46: Efficiency improvement assumption
A48: EDITABLE ALLOCATION SHARES
...

Sheet Demand
A1: Water Demand Projections — Libya (2020–2050)
A3: Metric | B3: Units | C3: Notes | D3: 2020 | E3: 2021 | F3: 2022 | G3: 2023 | H3: 2024 | I3: 2025 | J3: 2026 | K3: 2027 | L3: 2028 | M3: 2029 | N3: 2030 | O3: 2031 | P3: 2032 | Q3: 2033 | R3: 2034 | S3: 2035 | T3: 2036 | U3: 2037 | V3: 2038 | W3: 2039 | X3: 2040 | Y3: 2041 | Z3: 2042 | AA3: 2043 | AB3: 2044 | AC3: 2045 | AD3: 2046 | AE3: 2047 | AF3: 2048 | AG3: 2049 | AH3: 2050
A5: Population | B5: persons | C5: Linear interp UN WPP 2024 (2020 ↔ 2050) | D5: =Inputs!$B$6+(Inputs!$B$7-Inputs!$B$6)*(D$3-2020)/30 -> 6735277 | E5: =Inputs!$B$6+(Inputs!$B$7-Inputs!$B$6)*(E$3-2020)/30 -> 6860999.5 | F5: =Inputs!$B$6+(Inputs!$B$7-Inputs!$B$6)*(F$3-2020)/30 -> 6986722 | G5: =Inputs!$B$6+(Inputs!$B$7-Inputs!$B$6)*(G$3-2020)/30 -> 7112444.5 | H5: =Inputs!$B$6+(Inputs!$B$7-Inputs!$B$6)*(H$3-2020)/30 -> 7238167 | I5: =Inputs!$B$6+(Inputs!$B$7-Inputs!$B$6)*(I$3-2020)/30 -> 7363889.5 | J5: =Inputs!$B$6+(Inputs!$B$7-Inputs!$B$6)*(J$3-2020)/30 -> 7489612 | K5: =Inputs!$B$6+(Inputs!$B$7-Inputs!$B$6)*(K$3-2020)/30 -> 7615334.5 | ... AH5: =Inputs!$B$6+(Inputs!$B$7-Inputs!$B$6)*(AH$3-2020)/30 -> 10506952
A6: GDP per capita | B6: USD | C6: GDP_pc_2020 × (1+CAGR)^(year-2020) | D6: =Inputs!$B$8*(1+Inputs!$B$9)^(D$3-2020) -> 6357 | E6: =Inputs!$B$8*(1+Inputs!$B$9)^(E$3-2020) -> 6534.996 | F6: =Inputs!$B$8*(1+Inputs!$B$9)^(F$3-2020) -> 6717.9759 | G6: =Inputs!$B$8*(1+Inputs!$B$9)^(G$3-2020) -> 6906.0792 | H6: =Inputs!$B$8*(1+Inputs!$B$9)^(H$3-2020) -> 7099.4494 | I6: =Inputs!$B$8*(1+Inputs!$B$9)^(I$3-2020) -> 7298.234 | J6: =Inputs!$B$8*(1+Inputs!$B$9)^(J$3-2020) -> 7502.5846 | K6: =Inputs!$B$8*(1+Inputs!$B$9)^(K$3-2020) -> 7712.6569 | ... AH6: =Inputs!$B$8*(1+Inputs!$B$9)^(AH$3-2020) -> 14556.121
A7: Total GDP | B7: M USD | C7: Population × GDP per capita / 1e6 | D7: =D5*D6/1000000 -> 42816.156 | E7: =E5*E6/1000000 -> 44836.604 | F7: =F5*F6/1000000 -> 46936.63 | G7: =G5*G6/1000000 -> 49119.105 | H7: =H5*H6/1000000 -> 51387.001 | I7: =I5*I6/1000000 -> 53743.389 | J7: =J5*J6/1000000 -> 56191.447 | K7: =K5*K6/1000000 -> 58734.462 | ... AH7: =AH5*AH6/1000000 -> 152940.46
A9: Domestic intensity | B9: L/cap/day | C9: Base × (1+eff)^(year-2020) | D9: =Inputs!$B$12*(1+Inputs!$B$13)^(D$3-2020) -> 415 | E9: =Inputs!$B$12*(1+Inputs!$B$13)^(E$3-2020) -> 412.925 | F9: =Inputs!$B$12*(1+Inputs!$B$13)^(F$3-2020) -> 410.86038 | G9: =Inputs!$B$12*(1+Inputs!$B$13)^(G$3-2020) -> 408.80607 | H9: =Inputs!$B$12*(1+Inputs!$B$13)^(H$3-2020) -> 406.76204 | I9: =Inputs!$B$12*(1+Inputs!$B$13)^(I$3-2020) -> 404.72823 | J9: =Inputs!$B$12*(1+Inputs!$B$13)^(J$3-2020) -> 402.70459 | K9: =Inputs!$B$12*(1+Inputs!$B$13)^(K$3-2020) -> 400.69107 | ... AH9: =Inputs!$B$12*(1+Inputs!$B$13)^(AH$3-2020) -> 357.05944
A10: Industrial intensity | B10: m³/$1000 GDP | C10: Base × (1+eff)^(year-2020) | D10: =Inputs!$B$14*(1+Inputs!$B$15)^(D$3-2020) -> 5.8 | E10: =Inputs!$B$14*(1+Inputs!$B$15)^(E$3-2020) -> 5.742 | F10: =Inputs!$B$14*(1+Inputs!$B$15)^(F$3-2020) -> 5.68458 | G10: =Inputs!$B$14*(1+Inputs!$B$15)^(G$3-2020) -> 5.6277342 | H10: =Inputs!$B$14*(1+Inputs!$B$15)^(H$3-2020) -> 5.5714569 | I10: =Inputs!$B$14*(1+Inputs!$B$15)^(I$3-2020) -> 5.5157423 | J10: =Inputs!$B$14*(1+Inputs!$B$15)^(J$3-2020) -> 5.4605849 | K10: =Inputs!$B$14*(1+Inputs!$B$15)^(K$3-2020) -> 5.405979 | ... AH10: =Inputs!$B$14*(1+Inputs!$B$15)^(AH$3-2020) -> 4.2902622
A11: Agricultural intensity | B11: L/cap/day | C11: Base × (1+eff)^(year-2020) | D11: =Inputs!$B$16*(1+Inputs!$B$17)^(D$3-2020) -> 1492.5 | E11: =Inputs!$B$16*(1+Inputs!$B$17)^(E$3-2020) -> 1480.56 | F11: =Inputs!$B$16*(1+Inputs!$B$17)^(F$3-2020) -> 1468.7155 | G11: =Inputs!$B$16*(1+Inputs!$B$17)^(G$3-2020) -> 1456.9658 | H11: =Inputs!$B$16*(1+Inputs!$B$17)^(H$3-2020) -> 1445.3101 | I11: =Inputs!$B$16*(1+Inputs!$B$17)^(I$3-2020) -> 1433.7476 | J11: =Inputs!$B$16*(1+Inputs!$B$17)^(J$3-2020) -> 1422.2776 | K11: =Inputs!$B$16*(1+Inputs!$B$17)^(K$3-2020) -> 1410.8994 | ... AH11: =Inputs!$B$16*(1+Inputs!$B$17)^(AH$3-2020) -> 1172.9095
A13: Domestic demand | B13: M m³/yr | C13: Pop × lpcd × 365 / 1e9 | D13: =D5*D9*365/1000000000 -> 1020.2261 | E13: =E5*E9*365/1000000000 -> 1034.0735 | F13: =F5*F9*365/1000000000 -> 1047.757 | G13: =G5*G9*365/1000000000 -> 1061.2778 | H13: =H5*H9*365/1000000000 -> 1074.6372 | I13: =I5*I9*365/1000000000 -> 1087.8365 | J13: =J5*J9*365/1000000000 -> 1100.8769 | K13: =K5*K9*365/1000000000 -> 1113.7597 | ... AH13: =AH5*AH9*365/1000000000 -> 1369.3363
A14: Industrial demand | B14: M m³/yr | C14: GDP(M USD) × (m³/$1000) / 1000 | D14: =D7*D10/1000 -> 248.3337 | E14: =E7*E10/1000 -> 257.45178 | F14: =F7*F10/1000 -> 266.81503 | G14: =G7*G10/1000 -> 276.42927 | H14: =H7*H10/1000 -> 286.30046 | I14: =I7*I10/1000 -> 296.43468 | J14: =J7*J10/1000 -> 306.83817 | K14: =K7*K10/1000 -> 317.51727 | ... AH14: =AH7*AH10/1000 -> 656.15468
A15: Agricultural demand | B15: M m³/yr | C15: Pop × lpcd × 365 / 1e9 | D15: =D5*D11*365/1000000000 -> 3669.1263 | E15: =E5*E11*365/1000000000 -> 3707.7143 | F15: =F5*F11*365/1000000000 -> 3745.4501 | G15: =G5*G11*365/1000000000 -> 3782.3448 | H15: =H5*H11*365/1000000000 -> 3818.4094 | I15: =I5*I11*365/1000000000 -> 3853.655 | J15: =J5*J11*365/1000000000 -> 3888.0922 | K15: =K5*K11*365/1000000000 -> 3921.7318 | ... AH15: =AH5*AH11*365/1000000000 -> 4498.1519
A16: Active trees (100 M program) | B16: trees | C16: MIN(target, MAX(0, target×(year−start)/ramp)) | D16: =Inputs!$B$36*MIN(1,MAX(0,(D$3-Inputs!$B$34)/Inputs!$B$35)) -> 0 | E16: =Inputs!$B$36*MIN(1,MAX(0,(E$3-Inputs!$B$34)/Inputs!$B$35)) -> 0 | F16: =Inputs!$B$36*MIN(1,MAX(0,(F$3-Inputs!$B$34)/Inputs!$B$35)) -> 0 | G16: =Inputs!$B$36*MIN(1,MAX(0,(G$3-Inputs!$B$34)/Inputs!$B$35)) -> 0 | H16: =Inputs!$B$36*MIN(1,MAX(0,(H$3-Inputs!$B$34)/Inputs!$B$35)) -> 0 | I16: =Inputs!$B$36*MIN(1,MAX(0,(I$3-Inputs!$B$34)/Inputs!$B$35)) -> 0 | J16: =Inputs!$B$36*MIN(1,MAX(0,(J$3-Inputs!$B$34)/Inputs!$B$35)) -> 0 | K16: =Inputs!$B$36*MIN(1,MAX(0,(K$3-Inputs!$B$34)/Inputs!$B$35)) -> 10000000 | ... AH16: =Inputs!$B$36*MIN(1,MAX(0,(AH$3-Inputs!$B$34)/Inputs!$B$35)) -> 100000000
A17: Tree programme demand | B17: M m³/yr | C17: Active trees × L/tree/day × 365 / 1e9 | D17: =D16*Inputs!$B$37*365/1000000000 -> 0 | E17: =E16*Inputs!$B$37*365/1000000000 -> 0 | F17: =F16*Inputs!$B$37*365/1000000000 -> 0 | G17: =G16*Inputs!$B$37*365/1000000000 -> 0 | H17: =H16*Inputs!$B$37*365/1000000000 -> 0 | I17: =I16*Inputs!$B$37*365/1000000000 -> 0 | J17: =J16*Inputs!$B$37*365/1000000000 -> 0 | K17: =K16*Inputs!$B$37*365/1000000000 -> 54.75 | ... AH17: =AH16*Inputs!$B$37*365/1000000000 -> 547.5
A19: TOTAL water demand | B19: M m³/yr | C19: Sum of sectors + tree program | D19: =D13+D14+D15+D17 -> 4937.6861 | E19: =E13+E14+E15+E17 -> 4999.2396 | F19: =F13+F14+F15+F17 -> 5060.0221 | G19: =G13+G14+G15+G17 -> 5120.0519 | H19: =H13+H14+H15+H17 -> 5179.3471 | I19: =I13+I14+I15+I17 -> 5237.9262 | J19: =J13+J14+J15+J17 -> 5295.8073 | K19: =K13+K14+K15+K17 -> 5407.7588 | ... AH19: =AH13+AH14+AH15+AH17 -> 7071.1429

Sheet Supply
A1: Water Supply Allocation — Libya (2020–2050)
A3: Metric | B3: Units | C3: Notes | D3: 2020 | E3: 2021 | F3: 2022 | G3: 2023 | H3: 2024 | I3: 2025 | J3: 2026 | K3: 2027 | L3: 2028 | M3: 2029 | N3: 2030 | O3: 2031 | P3: 2032 | Q3: 2033 | R3: 2034 | S3: 2035 | T3: 2036 | U3: 2037 | V3: 2038 | W3: 2039 | X3: 2040 | Y3: 2041 | Z3: 2042 | AA3: 2043 | AB3: 2044 | AC3: 2045 | AD3: 2046 | AE3: 2047 | AF3: 2048 | AG3: 2049 | AH3: 2050
A5: Total water demand | B5: M m³/yr | C5: link ← Demand row 19 | D5: =Demand!D19 -> 4937.6861 | E5: =Demand!E19 -> 4999.2396 | F5: =Demand!F19 -> 5060.0221 | G5: =Demand!G19 -> 5120.0519 | H5: =Demand!H19 -> 5179.3471 | I5: =Demand!I19 -> 5237.9262 | J5: =Demand!J19 -> 5295.8073 | K5: =Demand!K19 -> 5407.7588 | ... AH5: =Demand!AH19 -> 7071.1429
A6: Of which tree programme | B6: M m³/yr | C6: link ← Demand row 17 | D6: =Demand!D17 -> 0 | E6: =Demand!E17 -> 0 | F6: =Demand!F17 -> 0 | G6: =Demand!G17 -> 0 | H6: =Demand!H17 -> 0 | I6: =Demand!I17 -> 0 | J6: =Demand!J17 -> 0 | K6: =Demand!K17 -> 54.75 | ... AH6: =Demand!AH17 -> 547.5
A8: Local groundwater available | B8: M m³/yr | C8: GW_2020 × (1+decline)^(year-2020) | D8: =Inputs!$B$20*(1+Inputs!$B$21)^(D$3-2020) -> 3500 | E8: =Inputs!$B$20*(1+Inputs!$B$21)^(E$3-2020) -> 3447.5 | F8: =Inputs!$B$20*(1+Inputs!$B$21)^(F$3-2020) -> 3395.7875 | G8: =Inputs!$B$20*(1+Inputs!$B$21)^(G$3-2020) -> 3344.8507 | H8: =Inputs!$B$20*(1+Inputs!$B$21)^(H$3-2020) -> 3294.6779 | I8: =Inputs!$B$20*(1+Inputs!$B$21)^(I$3-2020) -> 3245.2578 | J8: =Inputs!$B$20*(1+Inputs!$B$21)^(J$3-2020) -> 3196.5789 | K8: =Inputs!$B$20*(1+Inputs!$B$21)^(K$3-2020) -> 3148.6302 | ... AH8: =Inputs!$B$20*(1+Inputs!$B$21)^(AH$3-2020) -> 2224.1033
A9: Pipeline (GMMR) available | B9: M m³/yr | C9: GMMR_2020 × (1+decline)^(year-2020) | D9: =Inputs!$B$22*(1+Inputs!$B$23)^(D$3-2020) -> 912 | E9: =Inputs!$B$22*(1+Inputs!$B$23)^(E$3-2020) -> 893.76 | F9: =Inputs!$B$22*(1+Inputs!$B$23)^(F$3-2020) -> 875.8848 | G9: =Inputs!$B$22*(1+Inputs!$B$23)^(G$3-2020) -> 858.3671 | H9: =Inputs!$B$22*(1+Inputs!$B$23)^(H$3-2020) -> 841.19976 | I9: =Inputs!$B$22*(1+Inputs!$B$23)^(I$3-2020) -> 824.37577 | J9: =Inputs!$B$22*(1+Inputs!$B$23)^(J$3-2020) -> 807.88825 | K9: =Inputs!$B$22*(1+Inputs!$B$23)^(K$3-2020) -> 791.73049 | ... AH9: =Inputs!$B$22*(1+Inputs!$B$23)^(AH$3-2020) -> 497.4817
A10: Groundwater + Pipeline | B10: M m³/yr | C10: GW + GMMR | D10: =D8+D9 -> 4412 | E10: =E8+E9 -> 4341.26 | F10: =F8+F9 -> 4271.6723 | G10: =G8+G9 -> 4203.2178 | H10: =H8+H9 -> 4135.8777 | I10: =I8+I9 -> 4069.6335 | J10: =J8+J9 -> 4004.4671 | K10: =K8+K9 -> 3940.3607 | ... AH10: =AH8+AH9 -> 2721.585
A12: Domestic demand | B12: M m³/yr | C12: link ← Demand domestic | D12: =Demand!D13 -> 1020.2261 | E12: =Demand!E13 -> 1034.0735 | F12: =Demand!F13 -> 1047.757 | G12: =Demand!G13 -> 1061.2778 | H12: =Demand!H13 -> 1074.6372 | I12: =Demand!I13 -> 1087.8365 | J12: =Demand!J13 -> 1100.8769 | K12: =Demand!K13 -> 1113.7597 | ... AH12: =Demand!AH13 -> 1369.3363
A13: Industrial demand | B13: M m³/yr | C13: link ← Demand industrial | D13: =Demand!D14 -> 248.3337 | E13: =Demand!E14 -> 257.45178 | F13: =Demand!F14 -> 266.81503 | G13: =Demand!G14 -> 276.42927 | H13: =Demand!H14 -> 286.30046 | I13: =Demand!I14 -> 296.43468 | J13: =Demand!J14 -> 306.83817 | K13: =Demand!K14 -> 317.51727 | ... AH13: =Demand!AH14 -> 656.15468
A14: Agricultural demand | B14: M m³/yr | C14: link ← Demand agriculture | D14: =Demand!D15 -> 3669.1263 | E14: =Demand!E15 -> 3707.7143 | F14: =Demand!F15 -> 3745.4501 | G14: =Demand!G15 -> 3782.3448 | H14: =Demand!H15 -> 3818.4094 | I14: =Demand!I15 -> 3853.655 | J14: =Demand!J15 -> 3888.0922 | K14: =Demand!K15 -> 3921.7318 | ... AH14: =Demand!AH15 -> 4498.1519
A15: Recycled water available | B15: M m³/yr | C15: Urban demand met × recovery share | D15: =Demand!D13*(Inputs!B41+(Inputs!B42-Inputs!B41)*(D3-2020)/30) -> 153.03391 | E15: =Demand!E13*(Inputs!B41+(Inputs!B42-Inputs!B41)*(E3-2020)/30) -> 162.00486 | F15: =Demand!F13*(Inputs!B41+(Inputs!B42-Inputs!B41)*(F3-2020)/30) -> 171.13365 | G15: =Demand!G13*(Inputs!B41+(Inputs!B42-Inputs!B41)*(G3-2020)/30) -> 180.41723 | H15: =Demand!H13*(Inputs!B41+(Inputs!B42-Inputs!B41)*(H3-2020)/30) -> 189.85258 | I15: =Demand!I13*(Inputs!B41+(Inputs!B42-Inputs!B41)*(I3-2020)/30) -> 199.43669 | J15: =Demand!J13*(Inputs!B41+(Inputs!B42-Inputs!B41)*(J3-2020)/30) -> 209.16661 | K15: =Demand!K13*(Inputs!B41+(Inputs!B42-Inputs!B41)*(K3-2020)/30) -> 219.03941 | L15: =Demand!L13*(Inputs!B41+(Inputs!B42-Inputs!B41)*(L3-2020)/30) -> 229.05219 | M15: =Demand!M13*(Inputs!B41+(Inputs!B42-Inputs!B41)*(M3-2020)/30) -> 239.20208 | N15: =Demand!N13*(Inputs!B41+(Inputs!B42-Inputs!B41)*(N3-2020)/30) -> 249.48626 | O15: =Demand!O13*(Inputs!B41+(Inputs!B42-Inputs!B41)*(O3-2020)/30) -> 259.9019 | P15: =Demand!P13*(Inputs!B41+(Inputs!B42-Inputs!B41)*(P3-2020)/30) -> 270.44625 | Q15: =Demand!Q13*(Inputs!B41+(Inputs!B42-Inputs!B41)*(Q3-2020)/30) -> 281.11655 | R15: =Demand!R13*(Inputs!B41+(Inputs!B42-Inputs!B41)*(R3-2020)/30) -> 291.9101 | S15: =Demand!S13*(Inputs!B41+(Inputs!B42-Inputs!B41)*(S3-2020)/30) -> 302.82421 | T15: =Demand!T13*(Inputs!B41+(Inputs!B42-Inputs!B41)*(T3-2020)/30) -> 313.85623 | U15: =Demand!U13*(Inputs!B41+(Inputs!B42-Inputs!B41)*(U3-2020)/30) -> 325.00354 | V15: =Demand!V13*(Inputs!B41+(Inputs!B42-Inputs!B41)*(V3-2020)/30) -> 336.26354 | W15: =Demand!W13*(Inputs!B41+(Inputs!B42-Inputs!B41)*(W3-2020)/30) -> 347.63366 | X15: =Demand!X13*(Inputs!B41+(Inputs!B42-Inputs!B41)*(X3-2020)/30) -> 359.11138 | Y15: =Demand!Y13*(Inputs!B41+(Inputs!B42-Inputs!B41)*(Y3-2020)/30) -> 370.69417 | Z15: =Demand!Z13*(Inputs!B41+(Inputs!B42-Inputs!B41)*(Z3-2020)/30) -> 382.37956 | AA15: =Demand!AA13*(Inputs!B41+(Inputs!B42-Inputs!B41)*(AA3-2020)/30) -> 394.1651 | AB15: =Demand!AB13*(Inputs!B41+(Inputs!B42-Inputs!B41)*(AB3-2020)/30) -> 406.04836 | AC15: =Demand!AC13*(Inputs!B41+(Inputs!B42-Inputs!B41)*(AC3-2020)/30) -> 418.02695 | AD15: =Demand!AD13*(Inputs!B41+(Inputs!B42-Inputs!B41)*(AD3-2020)/30) -> 430.09849 | AE15: =Demand!AE13*(Inputs!B41+(Inputs!B42-Inputs!B41)*(AE3-2020)/30) -> 442.26064 | AF15: =Demand!AF13*(Inputs!B41+(Inputs!B42-Inputs!B41)*(AF3-2020)/30) -> 454.51108 | AG15: =Demand!AG13*(Inputs!B41+(Inputs!B42-Inputs!B41)*(AG3-2020)/30) -> 466.84753 | AH15: =Demand!AH13*(Inputs!B41+(Inputs!B42-Inputs!B41)*(AH3-2020)/30) -> 479.26772
A16: Recycled water to trees | B16: M m³/yr | C16: Allocated first from recycled water, capped by tree demand | D16: =MIN(Supply!D6,Supply!D15*(Inputs!B50+(Inputs!B51-Inputs!B50)*(D3-2020)/30)) -> 0 | E16: =MIN(Supply!E6,Supply!E15*(Inputs!B50+(Inputs!B51-Inputs!B50)*(E3-2020)/30)) -> 0 | F16: =MIN(Supply!F6,Supply!F15*(Inputs!B50+(Inputs!B51-Inputs!B50)*(F3-2020)/30)) -> 0 | G16: =MIN(Supply!G6,Supply!G15*(Inputs!B50+(Inputs!B51-Inputs!B50)*(G3-2020)/30)) -> 0 | H16: =MIN(Supply!H6,Supply!H15*(Inputs!B50+(Inputs!B51-Inputs!B50)*(H3-2020)/30)) -> 0 | I16: =MIN(Supply!I6,Supply!I15*(Inputs!B50+(Inputs!B51-Inputs!B50)*(I3-2020)/30)) -> 0 | J16: =MIN(Supply!J6,Supply!J15*(Inputs!B50+(Inputs!B51-Inputs!B50)*(J3-2020)/30)) -> 0 | K16: =MIN(Supply!K6,Supply!K15*(Inputs!B50+(Inputs!B51-Inputs!B50)*(K3-2020)/30)) -> 54.75 | L16: =MIN(Supply!L6,Supply!L15*(Inputs!B50+(Inputs!B51-Inputs!B50)*(L3-2020)/30)) -> 102.30998 | M16: =MIN(Supply!M6,Supply!M15*(Inputs!B50+(Inputs!B51-Inputs!B50)*(M3-2020)/30)) -> 105.24892 | N16: =MIN(Supply!N6,Supply!N15*(Inputs!B50+(Inputs!B51-Inputs!B50)*(N3-2020)/30)) -> 108.11071 | O16: =MIN(Supply!O6,Supply!O15*(Inputs!B50+(Inputs!B51-Inputs!B50)*(O3-2020)/30)) -> 110.89148 | P16: =MIN(Supply!P6,Supply!P15*(Inputs!B50+(Inputs!B51-Inputs!B50)*(P3-2020)/30)) -> 113.58742 | Q16: =MIN(Supply!Q6,Supply!Q15*(Inputs!B50+(Inputs!B51-Inputs!B50)*(Q3-2020)/30)) -> 116.19484 | R16: =MIN(Supply!R6,Supply!R15*(Inputs!B50+(Inputs!B51-Inputs!B50)*(R3-2020)/30)) -> 118.71011 | S16: =MIN(Supply!S6,Supply!S15*(Inputs!B50+(Inputs!B51-Inputs!B50)*(S3-2020)/30)) -> 121.12968 | T16: =MIN(Supply!T6,Supply!T15*(Inputs!B50+(Inputs!B51-Inputs!B50)*(T3-2020)/30)) -> 123.45012 | U16: =MIN(Supply!U6,Supply!U15*(Inputs!B50+(Inputs!B51-Inputs!B50)*(U3-2020)/30)) -> 125.66804 | V16: =MIN(Supply!V6,Supply!V15*(Inputs!B50+(Inputs!B51-Inputs!B50)*(V3-2020)/30)) -> 127.78014 | W16: =MIN(Supply!W6,Supply!W15*(Inputs!B50+(Inputs!B51-Inputs!B50)*(W3-2020)/30)) -> 129.78323 | X16: =MIN(Supply!X6,Supply!X15*(Inputs!B50+(Inputs!B51-Inputs!B50)*(X3-2020)/30)) -> 131.67417 | Y16: =MIN(Supply!Y6,Supply!Y15*(Inputs!B50+(Inputs!B51-Inputs!B50)*(Y3-2020)/30)) -> 133.4499 | Z16: =MIN(Supply!Z6,Supply!Z15*(Inputs!B50+(Inputs!B51-Inputs!B50)*(Z3-2020)/30)) -> 135.10744 | AA16: =MIN(Supply!AA6,Supply!AA15*(Inputs!B50+(Inputs!B51-Inputs!B50)*(AA3-2020)/30)) -> 136.6439 | AB16: =MIN(Supply!AB6,Supply!AB15*(Inputs!B50+(Inputs!B51-Inputs!B50)*(AB3-2020)/30)) -> 138.05644 | AC16: =MIN(Supply!AC6,Supply!AC15*(Inputs!B50+(Inputs!B51-Inputs!B50)*(AC3-2020)/30)) -> 139.34232 | AD16: =MIN(Supply!AD6,Supply!AD15*(Inputs!B50+(Inputs!B51-Inputs!B50)*(AD3-2020)/30)) -> 140.49884 | AE16: =MIN(Supply!AE6,Supply!AE15*(Inputs!B50+(Inputs!B51-Inputs!B50)*(AE3-2020)/30)) -> 141.5234 | AF16: =MIN(Supply!AF6,Supply!AF15*(Inputs!B50+(Inputs!B51-Inputs!B50)*(AF3-2020)/30)) -> 142.41347 | AG16: =MIN(Supply!AG6,Supply!AG15*(Inputs!B50+(Inputs!B51-Inputs!B50)*(AG3-2020)/30)) -> 143.16658 | AH16: =MIN(Supply!AH6,Supply!AH15*(Inputs!B50+(Inputs!B51-Inputs!B50)*(AH3-2020)/30)) -> 143.78032
A17: Recycled water to agriculture | B17: M m³/yr | C17: Residual recycled water after trees | D17: =MIN(Supply!D14,MAX(Supply!D15-Supply!D16,0)) -> 153.03391 | E17: =MIN(Supply!E14,MAX(Supply!E15-Supply!E16,0)) -> 162.00486 | F17: =MIN(Supply!F14,MAX(Supply!F15-Supply!F16,0)) -> 171.13365 | G17: =MIN(Supply!G14,MAX(Supply!G15-Supply!G16,0)) -> 180.41723 | H17: =MIN(Supply!H14,MAX(Supply!H15-Supply!H16,0)) -> 189.85258 | I17: =MIN(Supply!I14,MAX(Supply!I15-Supply!I16,0)) -> 199.43669 | J17: =MIN(Supply!J14,MAX(Supply!J15-Supply!J16,0)) -> 209.16661 | K17: =MIN(Supply!K14,MAX(Supply!K15-Supply!K16,0)) -> 164.28941 | ... AH17: =MIN(Supply!AH14,MAX(Supply!AH15-Supply!AH16,0)) -> 335.4874
A18: Urban from groundwater | B18: M m³/yr | C18: Urban first draw on GW | D18: =MIN(Supply!D12*Inputs!B52,Supply!D8) -> 1020.2261 | E18: =MIN(Supply!E12*Inputs!B52,Supply!E8) -> 1034.0735 | F18: =MIN(Supply!F12*Inputs!B52,Supply!F8) -> 1047.757 | G18: =MIN(Supply!G12*Inputs!B52,Supply!G8) -> 1061.2778 | H18: =MIN(Supply!H12*Inputs!B52,Supply!H8) -> 1074.6372 | I18: =MIN(Supply!I12*Inputs!B52,Supply!I8) -> 1087.8365 | J18: =MIN(Supply!J12*Inputs!B52,Supply!J8) -> 1100.8769 | K18: =MIN(Supply!K12*Inputs!B52,Supply!K8) -> 1113.7597 | L18: =MIN(Supply!L12*Inputs!B52,Supply!L8) -> 1126.4862 | M18: =MIN(Supply!M12*Inputs!B52,Supply!M8) -> 1139.0575 | N18: =MIN(Supply!N12*Inputs!B52,Supply!N8) -> 1151.475 | O18: =MIN(Supply!O12*Inputs!B52,Supply!O8) -> 1163.7399 | P18: =MIN(Supply!P12*Inputs!B52,Supply!P8) -> 1175.8532 | Q18: =MIN(Supply!Q12*Inputs!B52,Supply!Q8) -> 1187.8164 | R18: =MIN(Supply!R12*Inputs!B52,Supply!R8) -> 1199.6305 | S18: =MIN(Supply!S12*Inputs!B52,Supply!S8) -> 1211.2968 | T18: =MIN(Supply!T12*Inputs!B52,Supply!T8) -> 1222.8165 | U18: =MIN(Supply!U12*Inputs!B52,Supply!U8) -> 1234.1907 | V18: =MIN(Supply!V12*Inputs!B52,Supply!V8) -> 1245.4205 | W18: =MIN(Supply!W12*Inputs!B52,Supply!W8) -> 1256.5072 | X18: =MIN(Supply!X12*Inputs!B52,Supply!X8) -> 1267.4519 | Y18: =MIN(Supply!Y12*Inputs!B52,Supply!Y8) -> 1278.2558 | Z18: =MIN(Supply!Z12*Inputs!B52,Supply!Z8) -> 1288.9199 | AA18: =MIN(Supply!AA12*Inputs!B52,Supply!AA8) -> 1299.4454 | AB18: =MIN(Supply!AB12*Inputs!B52,Supply!AB8) -> 1309.8334 | AC18: =MIN(Supply!AC12*Inputs!B52,Supply!AC8) -> 1320.0851 | AD18: =MIN(Supply!AD12*Inputs!B52,Supply!AD8) -> 1330.2015 | AE18: =MIN(Supply!AE12*Inputs!B52,Supply!AE8) -> 1340.1837 | AF18: =MIN(Supply!AF12*Inputs!B52,Supply!AF8) -> 1350.0329 | AG18: =MIN(Supply!AG12*Inputs!B52,Supply!AG8) -> 1359.7501 | AH18: =MIN(Supply!AH12*Inputs!B52,Supply!AH8) -> 1369.3363
A19: Urban from GMMR | B19: M m³/yr | C19: Urban then GMMR | D19: =MIN(MAX(Supply!D12-D18,0)*Inputs!B53,MAX(Supply!D9,0)) -> 0 | E19: =MIN(MAX(Supply!E12-E18,0)*Inputs!B53,MAX(Supply!E9,0)) -> 0 | F19: =MIN(MAX(Supply!F12-F18,0)*Inputs!B53,MAX(Supply!F9,0)) -> 0 | G19: =MIN(MAX(Supply!G12-G18,0)*Inputs!B53,MAX(Supply!G9,0)) -> 0 | H19: =MIN(MAX(Supply!H12-H18,0)*Inputs!B53,MAX(Supply!H9,0)) -> 0 | I19: =MIN(MAX(Supply!I12-I18,0)*Inputs!B53,MAX(Supply!I9,0)) -> 0 | J19: =MIN(MAX(Supply!J12-J18,0)*Inputs!B53,MAX(Supply!J9,0)) -> 0 | K19: =MIN(MAX(Supply!K12-K18,0)*Inputs!B53,MAX(Supply!K9,0)) -> 0 | L19: =MIN(MAX(Supply!L12-L18,0)*Inputs!B53,MAX(Supply!L9,0)) -> 0 | M19: =MIN(MAX(Supply!M12-M18,0)*Inputs!B53,MAX(Supply!M9,0)) -> 0 | N19: =MIN(MAX(Supply!N12-N18,0)*Inputs!B53,MAX(Supply!N9,0)) -> 0 | O19: =MIN(MAX(Supply!O12-O18,0)*Inputs!B53,MAX(Supply!O9,0)) -> 0 | P19: =MIN(MAX(Supply!P12-P18,0)*Inputs!B53,MAX(Supply!P9,0)) -> 0 | Q19: =MIN(MAX(Supply!Q12-Q18,0)*Inputs!B53,MAX(Supply!Q9,0)) -> 0 | R19: =MIN(MAX(Supply!R12-R18,0)*Inputs!B53,MAX(Supply!R9,0)) -> 0 | S19: =MIN(MAX(Supply!S12-S18,0)*Inputs!B53,MAX(Supply!S9,0)) -> 0 | T19: =MIN(MAX(Supply!T12-T18,0)*Inputs!B53,MAX(Supply!T9,0)) -> 0 | U19: =MIN(MAX(Supply!U12-U18,0)*Inputs!B53,MAX(Supply!U9,0)) -> 0 | V19: =MIN(MAX(Supply!V12-V18,0)*Inputs!B53,MAX(Supply!V9,0)) -> 0 | W19: =MIN(MAX(Supply!W12-W18,0)*Inputs!B53,MAX(Supply!W9,0)) -> 0 | X19: =MIN(MAX(Supply!X12-X18,0)*Inputs!B53,MAX(Supply!X9,0)) -> 0 | Y19: =MIN(MAX(Supply!Y12-Y18,0)*Inputs!B53,MAX(Supply!Y9,0)) -> 0 | Z19: =MIN(MAX(Supply!Z12-Z18,0)*Inputs!B53,MAX(Supply!Z9,0)) -> 0 | AA19: =MIN(MAX(Supply!AA12-AA18,0)*Inputs!B53,MAX(Supply!AA9,0)) -> 0 | AB19: =MIN(MAX(Supply!AB12-AB18,0)*Inputs!B53,MAX(Supply!AB9,0)) -> 0 | AC19: =MIN(MAX(Supply!AC12-AC18,0)*Inputs!B53,MAX(Supply!AC9,0)) -> 0 | AD19: =MIN(MAX(Supply!AD12-AD18,0)*Inputs!B53,MAX(Supply!AD9,0)) -> 0 | AE19: =MIN(MAX(Supply!AE12-AE18,0)*Inputs!B53,MAX(Supply!AE9,0)) -> 0 | AF19: =MIN(MAX(Supply!AF12-AF18,0)*Inputs!B53,MAX(Supply!AF9,0)) -> 0 | AG19: =MIN(MAX(Supply!AG12-AG18,0)*Inputs!B53,MAX(Supply!AG9,0)) -> 0 | AH19: =MIN(MAX(Supply!AH12-AH18,0)*Inputs!B53,MAX(Supply!AH9,0)) -> 0
A20: Urban from desalination | B20: M m³/yr | C20: Urban residual desal | D20: =MAX(Supply!D12-D18-D19,0) -> 0 | E20: =MAX(Supply!E12-E18-E19,0) -> 0 | F20: =MAX(Supply!F12-F18-F19,0) -> 0 | G20: =MAX(Supply!G12-G18-G19,0) -> 0 | H20: =MAX(Supply!H12-H18-H19,0) -> 0 | I20: =MAX(Supply!I12-I18-I19,0) -> 0 | J20: =MAX(Supply!J12-J18-J19,0) -> 0 | K20: =MAX(Supply!K12-K18-K19,0) -> 0 | ... AH20: =MAX(Supply!AH12-AH18-AH19,0) -> 0
A21: Industrial from groundwater | B21: M m³/yr | C21: Industrial second draw on GW | D21: =MIN(Supply!D13*Inputs!B54,MAX(Supply!D8-D18,0)) -> 248.3337 | E21: =MIN(Supply!E13*Inputs!B54,MAX(Supply!E8-E18,0)) -> 257.45178 | F21: =MIN(Supply!F13*Inputs!B54,MAX(Supply!F8-F18,0)) -> 266.81503 | G21: =MIN(Supply!G13*Inputs!B54,MAX(Supply!G8-G18,0)) -> 276.42927 | H21: =MIN(Supply!H13*Inputs!B54,MAX(Supply!H8-H18,0)) -> 286.30046 | I21: =MIN(Supply!I13*Inputs!B54,MAX(Supply!I8-I18,0)) -> 296.43468 | J21: =MIN(Supply!J13*Inputs!B54,MAX(Supply!J8-J18,0)) -> 306.83817 | K21: =MIN(Supply!K13*Inputs!B54,MAX(Supply!K8-K18,0)) -> 317.51727 | L21: =MIN(Supply!L13*Inputs!B54,MAX(Supply!L8-L18,0)) -> 328.4785 | M21: =MIN(Supply!M13*Inputs!B54,MAX(Supply!M8-M18,0)) -> 339.72849 | N21: =MIN(Supply!N13*Inputs!B54,MAX(Supply!N8-N18,0)) -> 351.27404 | O21: =MIN(Supply!O13*Inputs!B54,MAX(Supply!O8-O18,0)) -> 363.12209 | P21: =MIN(Supply!P13*Inputs!B54,MAX(Supply!P8-P18,0)) -> 375.27973 | Q21: =MIN(Supply!Q13*Inputs!B54,MAX(Supply!Q8-Q18,0)) -> 387.75422 | R21: =MIN(Supply!R13*Inputs!B54,MAX(Supply!R8-R18,0)) -> 400.55297 | S21: =MIN(Supply!S13*Inputs!B54,MAX(Supply!S8-S18,0)) -> 413.68356 | T21: =MIN(Supply!T13*Inputs!B54,MAX(Supply!T8-T18,0)) -> 427.15371 | U21: =MIN(Supply!U13*Inputs!B54,MAX(Supply!U8-U18,0)) -> 440.97136 | V21: =MIN(Supply!V13*Inputs!B54,MAX(Supply!V8-V18,0)) -> 455.14458 | W21: =MIN(Supply!W13*Inputs!B54,MAX(Supply!W8-W18,0)) -> 469.68163 | X21: =MIN(Supply!X13*Inputs!B54,MAX(Supply!X8-X18,0)) -> 484.59096 | Y21: =MIN(Supply!Y13*Inputs!B54,MAX(Supply!Y8-Y18,0)) -> 499.88119 | Z21: =MIN(Supply!Z13*Inputs!B54,MAX(Supply!Z8-Z18,0)) -> 515.56116 | AA21: =MIN(Supply!AA13*Inputs!B54,MAX(Supply!AA8-AA18,0)) -> 531.63985 | AB21: =MIN(Supply!AB13*Inputs!B54,MAX(Supply!AB8-AB18,0)) -> 548.1265 | AC21: =MIN(Supply!AC13*Inputs!B54,MAX(Supply!AC8-AC18,0)) -> 565.03049 | AD21: =MIN(Supply!AD13*Inputs!B54,MAX(Supply!AD8-AD18,0)) -> 582.36145 | AE21: =MIN(Supply!AE13*Inputs!B54,MAX(Supply!AE8-AE18,0)) -> 600.1292 | AF21: =MIN(Supply!AF13*Inputs!B54,MAX(Supply!AF8-AF18,0)) -> 618.34378 | AG21: =MIN(Supply!AG13*Inputs!B54,MAX(Supply!AG8-AG18,0)) -> 637.01545 | AH21: =MIN(Supply!AH13*Inputs!B54,MAX(Supply!AH8-AH18,0)) -> 656.15468
A22: Industrial from GMMR | B22: M m³/yr | C22: Industrial then GMMR | D22: =MIN(MAX(Supply!D13-D21,0)*Inputs!B55,MAX(Supply!D9-D19,0)) -> 0 | E22: =MIN(MAX(Supply!E13-E21,0)*Inputs!B55,MAX(Supply!E9-E19,0)) -> 0 | F22: =MIN(MAX(Supply!F13-F21,0)*Inputs!B55,MAX(Supply!F9-F19,0)) -> 0 | G22: =MIN(MAX(Supply!G13-G21,0)*Inputs!B55,MAX(Supply!G9-G19,0)) -> 0 | H22: =MIN(MAX(Supply!H13-H21,0)*Inputs!B55,MAX(Supply!H9-H19,0)) -> 0 | I22: =MIN(MAX(Supply!I13-I21,0)*Inputs!B55,MAX(Supply!I9-I19,0)) -> 0 | J22: =MIN(MAX(Supply!J13-J21,0)*Inputs!B55,MAX(Supply!J9-J19,0)) -> 0 | K22: =MIN(MAX(Supply!K13-K21,0)*Inputs!B55,MAX(Supply!K9-K19,0)) -> 0 | L22: =MIN(MAX(Supply!L13-L21,0)*Inputs!B55,MAX(Supply!L9-L19,0)) -> 0 | M22: =MIN(MAX(Supply!M13-M21,0)*Inputs!B55,MAX(Supply!M9-M19,0)) -> 0 | N22: =MIN(MAX(Supply!N13-N21,0)*Inputs!B55,MAX(Supply!N9-N19,0)) -> 0 | O22: =MIN(MAX(Supply!O13-O21,0)*Inputs!B55,MAX(Supply!O9-O19,0)) -> 0 | P22: =MIN(MAX(Supply!P13-P21,0)*Inputs!B55,MAX(Supply!P9-P19,0)) -> 0 | Q22: =MIN(MAX(Supply!Q13-Q21,0)*Inputs!B55,MAX(Supply!Q9-Q19,0)) -> 0 | R22: =MIN(MAX(Supply!R13-R21,0)*Inputs!B55,MAX(Supply!R9-R19,0)) -> 0 | S22: =MIN(MAX(Supply!S13-S21,0)*Inputs!B55,MAX(Supply!S9-S19,0)) -> 0 | T22: =MIN(MAX(Supply!T13-T21,0)*Inputs!B55,MAX(Supply!T9-T19,0)) -> 0 | U22: =MIN(MAX(Supply!U13-U21,0)*Inputs!B55,MAX(Supply!U9-U19,0)) -> 0 | V22: =MIN(MAX(Supply!V13-V21,0)*Inputs!B55,MAX(Supply!V9-V19,0)) -> 0 | W22: =MIN(MAX(Supply!W13-W21,0)*Inputs!B55,MAX(Supply!W9-W19,0)) -> 0 | X22: =MIN(MAX(Supply!X13-X21,0)*Inputs!B55,MAX(Supply!X9-X19,0)) -> 0 | Y22: =MIN(MAX(Supply!Y13-Y21,0)*Inputs!B55,MAX(Supply!Y9-Y19,0)) -> 0 | Z22: =MIN(MAX(Supply!Z13-Z21,0)*Inputs!B55,MAX(Supply!Z9-Z19,0)) -> 0 | AA22: =MIN(MAX(Supply!AA13-AA21,0)*Inputs!B55,MAX(Supply!AA9-AA19,0)) -> 0 | AB22: =MIN(MAX(Supply!AB13-AB21,0)*Inputs!B55,MAX(Supply!AB9-AB19,0)) -> 0 | AC22: =MIN(MAX(Supply!AC13-AC21,0)*Inputs!B55,MAX(Supply!AC9-AC19,0)) -> 0 | AD22: =MIN(MAX(Supply!AD13-AD21,0)*Inputs!B55,MAX(Supply!AD9-AD19,0)) -> 0 | AE22: =MIN(MAX(Supply!AE13-AE21,0)*Inputs!B55,MAX(Supply!AE9-AE19,0)) -> 0 | AF22: =MIN(MAX(Supply!AF13-AF21,0)*Inputs!B55,MAX(Supply!AF9-AF19,0)) -> 0 | AG22: =MIN(MAX(Supply!AG13-AG21,0)*Inputs!B55,MAX(Supply!AG9-AG19,0)) -> 0 | AH22: =MIN(MAX(Supply!AH13-AH21,0)*Inputs!B55,MAX(Supply!AH9-AH19,0)) -> 0
A23: Industrial from desalination | B23: M m³/yr | C23: Industrial residual desal | D23: =MAX(Supply!D13-D21-D22,0) -> 0 | E23: =MAX(Supply!E13-E21-E22,0) -> 0 | F23: =MAX(Supply!F13-F21-F22,0) -> 0 | G23: =MAX(Supply!G13-G21-G22,0) -> 0 | H23: =MAX(Supply!H13-H21-H22,0) -> 0 | I23: =MAX(Supply!I13-I21-I22,0) -> 0 | J23: =MAX(Supply!J13-J21-J22,0) -> 0 | K23: =MAX(Supply!K13-K21-K22,0) -> 0 | ... AH23: =MAX(Supply!AH13-AH21-AH22,0) -> 0
A24: Agriculture from groundwater | B24: M m³/yr | C24: Agriculture draw on GW after recycled | D24: =MIN(MAX(Supply!D14-Supply!D17,0)*Inputs!B56,MAX(Supply!D8-D18-D21,0)) -> 2231.4402 | E24: =MIN(MAX(Supply!E14-Supply!E17,0)*Inputs!B56,MAX(Supply!E8-E18-E21,0)) -> 2155.9747 | F24: =MIN(MAX(Supply!F14-Supply!F17,0)*Inputs!B56,MAX(Supply!F8-F18-F21,0)) -> 2081.2154 | G24: =MIN(MAX(Supply!G14-Supply!G17,0)*Inputs!B56,MAX(Supply!G8-G18-G21,0)) -> 2007.1436 | H24: =MIN(MAX(Supply!H14-Supply!H17,0)*Inputs!B56,MAX(Supply!H8-H18-H21,0)) -> 1933.7402 | I24: =MIN(MAX(Supply!I14-Supply!I17,0)*Inputs!B56,MAX(Supply!I8-I18-I21,0)) -> 1860.9866 | J24: =MIN(MAX(Supply!J14-Supply!J17,0)*Inputs!B56,MAX(Supply!J8-J18-J21,0)) -> 1788.8638 | K24: =MIN(MAX(Supply!K14-Supply!K17,0)*Inputs!B56,MAX(Supply!K8-K18-K21,0)) -> 1717.3532 | L24: =MIN(MAX(Supply!L14-Supply!L17,0)*Inputs!B56,MAX(Supply!L8-L18-L21,0)) -> 1646.4361 | M24: =MIN(MAX(Supply!M14-Supply!M17,0)*Inputs!B56,MAX(Supply!M8-M18-M21,0)) -> 1576.0937 | N24: =MIN(MAX(Supply!N14-Supply!N17,0)*Inputs!B56,MAX(Supply!N8-N18-N21,0)) -> 1506.3075 | O24: =MIN(MAX(Supply!O14-Supply!O17,0)*Inputs!B56,MAX(Supply!O8-O18-O21,0)) -> 1437.0588 | P24: =MIN(MAX(Supply!P14-Supply!P17,0)*Inputs!B56,MAX(Supply!P8-P18-P21,0)) -> 1368.3289 | Q24: =MIN(MAX(Supply!Q14-Supply!Q17,0)*Inputs!B56,MAX(Supply!Q8-Q18-Q21,0)) -> 1300.0993 | R24: =MIN(MAX(Supply!R14-Supply!R17,0)*Inputs!B56,MAX(Supply!R8-R18-R21,0)) -> 1232.3514 | S24: =MIN(MAX(Supply!S14-Supply!S17,0)*Inputs!B56,MAX(Supply!S8-S18-S21,0)) -> 1165.0665 | T24: =MIN(MAX(Supply!T14-Supply!T17,0)*Inputs!B56,MAX(Supply!T8-T18-T21,0)) -> 1098.226 | U24: =MIN(MAX(Supply!U14-Supply!U17,0)*Inputs!B56,MAX(Supply!U8-U18-U21,0)) -> 1031.8112 | V24: =MIN(MAX(Supply!V14-Supply!V17,0)*Inputs!B56,MAX(Supply!V8-V18-V21,0)) -> 965.80356 | W24: =MIN(MAX(Supply!W14-Supply!W17,0)*Inputs!B56,MAX(Supply!W8-W18-W21,0)) -> 900.18427 | X24: =MIN(MAX(Supply!X14-Supply!X17,0)*Inputs!B56,MAX(Supply!X8-X18-X21,0)) -> 834.93465 | Y24: =MIN(MAX(Supply!Y14-Supply!Y17,0)*Inputs!B56,MAX(Supply!Y8-Y18-Y21,0)) -> 770.03591 | Z24: =MIN(MAX(Supply!Z14-Supply!Z17,0)*Inputs!B56,MAX(Supply!Z8-Z18-Z21,0)) -> 705.46924 | AA24: =MIN(MAX(Supply!AA14-Supply!AA17,0)*Inputs!B56,MAX(Supply!AA8-AA18-AA21,0)) -> 641.21577 | AB24: =MIN(MAX(Supply!AB14-Supply!AB17,0)*Inputs!B56,MAX(Supply!AB8-AB18-AB21,0)) -> 577.25657 | AC24: =MIN(MAX(Supply!AC14-Supply!AC17,0)*Inputs!B56,MAX(Supply!AC8-AC18-AC21,0)) -> 513.57266 | AD24: =MIN(MAX(Supply!AD14-Supply!AD17,0)*Inputs!B56,MAX(Supply!AD8-AD18-AD21,0)) -> 450.14496 | AE24: =MIN(MAX(Supply!AE14-Supply!AE17,0)*Inputs!B56,MAX(Supply!AE8-AE18-AE21,0)) -> 386.95435 | AF24: =MIN(MAX(Supply!AF14-Supply!AF17,0)*Inputs!B56,MAX(Supply!AF8-AF18-AF21,0)) -> 323.98159 | AG24: =MIN(MAX(Supply!AG14-Supply!AG17,0)*Inputs!B56,MAX(Supply!AG8-AG18-AG21,0)) -> 261.20738 | AH24: =MIN(MAX(Supply!AH14-Supply!AH17,0)*Inputs!B56,MAX(Supply!AH8-AH18-AH21,0)) -> 198.61231
A25: Agriculture from GMMR | B25: M m³/yr | C25: Agriculture then GMMR | D25: =MIN(MAX(MAX(D14-D17,0)-D24,0)*Inputs!B57,MAX(D9-D19-D22,0)) -> 912 | E25: =MIN(MAX(MAX(Supply!E14-Supply!E17,0)-E24,0)*Inputs!B57,MAX(Supply!E9-E19-E22,0)) -> 893.76 | F25: =MIN(MAX(MAX(Supply!F14-Supply!F17,0)-F24,0)*Inputs!B57,MAX(Supply!F9-F19-F22,0)) -> 875.8848 | G25: =MIN(MAX(MAX(Supply!G14-Supply!G17,0)-G24,0)*Inputs!B57,MAX(Supply!G9-G19-G22,0)) -> 858.3671 | H25: =MIN(MAX(MAX(Supply!H14-Supply!H17,0)-H24,0)*Inputs!B57,MAX(Supply!H9-H19-H22,0)) -> 841.19976 | I25: =MIN(MAX(MAX(Supply!I14-Supply!I17,0)-I24,0)*Inputs!B57,MAX(Supply!I9-I19-I22,0)) -> 824.37577 | J25: =MIN(MAX(MAX(Supply!J14-Supply!J17,0)-J24,0)*Inputs!B57,MAX(Supply!J9-J19-J22,0)) -> 807.88825 | K25: =MIN(MAX(MAX(Supply!K14-Supply!K17,0)-K24,0)*Inputs!B57,MAX(Supply!K9-K19-K22,0)) -> 791.73049 | L25: =MIN(MAX(MAX(Supply!L14-Supply!L17,0)-L24,0)*Inputs!B57,MAX(Supply!L9-L19-L22,0)) -> 775.89588 | M25: =MIN(MAX(MAX(Supply!M14-Supply!M17,0)-M24,0)*Inputs!B57,MAX(Supply!M9-M19-M22,0)) -> 760.37796 | N25: =MIN(MAX(MAX(Supply!N14-Supply!N17,0)-N24,0)*Inputs!B57,MAX(Supply!N9-N19-N22,0)) -> 745.1704 | O25: =MIN(MAX(MAX(Supply!O14-Supply!O17,0)-O24,0)*Inputs!B57,MAX(Supply!O9-O19-O22,0)) -> 730.26699 | P25: =MIN(MAX(MAX(Supply!P14-Supply!P17,0)-P24,0)*Inputs!B57,MAX(Supply!P9-P19-P22,0)) -> 715.66165 | Q25: =MIN(MAX(MAX(Supply!Q14-Supply!Q17,0)-Q24,0)*Inputs!B57,MAX(Supply!Q9-Q19-Q22,0)) -> 701.34842 | R25: =MIN(MAX(MAX(Supply!R14-Supply!R17,0)-R24,0)*Inputs!B57,MAX(Supply!R9-R19-R22,0)) -> 687.32145 | S25: =MIN(MAX(MAX(Supply!S14-Supply!S17,0)-S24,0)*Inputs!B57,MAX(Supply!S9-S19-S22,0)) -> 673.57502 | T25: =MIN(MAX(MAX(Supply!T14-Supply!T17,0)-T24,0)*Inputs!B57,MAX(Supply!T9-T19-T22,0)) -> 660.10352 | U25: =MIN(MAX(MAX(Supply!U14-Supply!U17,0)-U24,0)*Inputs!B57,MAX(Supply!U9-U19-U22,0)) -> 646.90145 | V25: =MIN(MAX(MAX(Supply!V14-Supply!V17,0)-V24,0)*Inputs!B57,MAX(Supply!V9-V19-V22,0)) -> 633.96342 | W25: =MIN(MAX(MAX(Supply!W14-Supply!W17,0)-W24,0)*Inputs!B57,MAX(Supply!W9-W19-W22,0)) -> 621.28415 | X25: =MIN(MAX(MAX(Supply!X14-Supply!X17,0)-X24,0)*Inputs!B57,MAX(Supply!X9-X19-X22,0)) -> 608.85847 | Y25: =MIN(MAX(MAX(Supply!Y14-Supply!Y17,0)-Y24,0)*Inputs!B57,MAX(Supply!Y9-Y19-Y22,0)) -> 596.6813 | Z25: =MIN(MAX(MAX(Supply!Z14-Supply!Z17,0)-Z24,0)*Inputs!B57,MAX(Supply!Z9-Z19-Z22,0)) -> 584.74767 | AA25: =MIN(MAX(MAX(Supply!AA14-Supply!AA17,0)-AA24,0)*Inputs!B57,MAX(Supply!AA9-AA19-AA22,0)) -> 573.05272 | AB25: =MIN(MAX(MAX(Supply!AB14-Supply!AB17,0)-AB24,0)*Inputs!B57,MAX(Supply!AB9-AB19-AB22,0)) -> 561.59167 | AC25: =MIN(MAX(MAX(Supply!AC14-Supply!AC17,0)-AC24,0)*Inputs!B57,MAX(Supply!AC9-AC19-AC22,0)) -> 550.35983 | AD25: =MIN(MAX(MAX(Supply!AD14-Supply!AD17,0)-AD24,0)*Inputs!B57,MAX(Supply!AD9-AD19-AD22,0)) -> 539.35264 | AE25: =MIN(MAX(MAX(Supply!AE14-Supply!AE17,0)-AE24,0)*Inputs!B57,MAX(Supply!AE9-AE19-AE22,0)) -> 528.56558 | AF25: =MIN(MAX(MAX(Supply!AF14-Supply!AF17,0)-AF24,0)*Inputs!B57,MAX(Supply!AF9-AF19-AF22,0)) -> 517.99427 | AG25: =MIN(MAX(MAX(Supply!AG14-Supply!AG17,0)-AG24,0)*Inputs!B57,MAX(Supply!AG9-AG19-AG22,0)) -> 507.63439 | AH25: =MIN(MAX(MAX(Supply!AH14-Supply!AH17,0)-AH24,0)*Inputs!B57,MAX(Supply!AH9-AH19-AH22,0)) -> 497.4817
A26: Agriculture from desalination | B26: M m³/yr | C26: Agriculture residual desal | D26: =MAX(MAX(D14-D17,0)-D24-D25,0) -> 372.65221 | E26: =MAX(MAX(Supply!E14-Supply!E17,0)-E24-E25,0) -> 495.97479 | F26: =MAX(MAX(Supply!F14-Supply!F17,0)-F24-F25,0) -> 617.21618 | G26: =MAX(MAX(Supply!G14-Supply!G17,0)-G24-G25,0) -> 736.41683 | H26: =MAX(MAX(Supply!H14-Supply!H17,0)-H24-H25,0) -> 853.61683 | I26: =MAX(MAX(Supply!I14-Supply!I17,0)-I24-I25,0) -> 968.85594 | J26: =MAX(MAX(Supply!J14-Supply!J17,0)-J24-J25,0) -> 1082.1735 | K26: =MAX(MAX(Supply!K14-Supply!K17,0)-K24-K25,0) -> 1248.3587 | L26: =MAX(MAX(Supply!L14-Supply!L17,0)-L24-L25,0) -> 1405.5102 | ... AH26: =MAX(MAX(Supply!AH14-Supply!AH17,0)-AH24-AH25,0) -> 3466.5705
A27: Trees from desalination | B27: M m³/yr | C27: Tree residual after recycled | D27: =MAX(Supply!D6-Supply!D16,0) -> 0 | E27: =MAX(Supply!E6-Supply!E16,0) -> 0 | F27: =MAX(Supply!F6-Supply!F16,0) -> 0 | G27: =MAX(Supply!G6-Supply!G16,0) -> 0 | H27: =MAX(Supply!H6-Supply!H16,0) -> 0 | I27: =MAX(Supply!I6-Supply!I16,0) -> 0 | J27: =MAX(Supply!J6-Supply!J16,0) -> 0 | K27: =MAX(Supply!K6-Supply!K16,0) -> 0 | ... AH27: =MAX(Supply!AH6-Supply!AH16,0) -> 403.71968
A28: CHECK: allocated demand incl recycled | B28: M m³/yr | C28: Should equal total demand | D28: =D18+D19+D20+D21+D22+D23+D17+D24+D25+D26+D16+D27 -> 4937.6861 | E28: =E18+E19+E20+E21+E22+E23+E17+E24+E25+E26+E16+E27 -> 4999.2396 | F28: =F18+F19+F20+F21+F22+F23+F17+F24+F25+F26+F16+F27 -> 5060.0221 | G28: =G18+G19+G20+G21+G22+G23+G17+G24+G25+G26+G16+G27 -> 5120.0519 | H28: =H18+H19+H20+H21+H22+H23+H17+H24+H25+H26+H16+H27 -> 5179.3471 | I28: =I18+I19+I20+I21+I22+I23+I17+I24+I25+I26+I16+I27 -> 5237.9262 | J28: =J18+J19+J20+J21+J22+J23+J17+J24+J25+J26+J16+J27 -> 5295.8073 | K28: =K18+K19+K20+K21+K22+K23+K17+K24+K25+K26+K16+K27 -> 5407.7588 | ... AH28: =AH18+AH19+AH20+AH21+AH22+AH23+AH17+AH24+AH25+AH26+AH16+AH27 -> 7071.1429
A29: Desalination required (total) | B29: M m³/yr | C29: MAX(0, Total demand − GW − GMMR) | D29: =D20+D23+D26+D27 -> 372.65221 | E29: =Supply!E20+Supply!E23+Supply!E26+Supply!E27 -> 495.97479 | F29: =Supply!F20+Supply!F23+Supply!F26+Supply!F27 -> 617.21618 | G29: =Supply!G20+Supply!G23+Supply!G26+Supply!G27 -> 736.41683 | H29: =Supply!H20+Supply!H23+Supply!H26+Supply!H27 -> 853.61683 | I29: =Supply!I20+Supply!I23+Supply!I26+Supply!I27 -> 968.85594 | J29: =Supply!J20+Supply!J23+Supply!J26+Supply!J27 -> 1082.1735 | K29: =Supply!K20+Supply!K23+Supply!K26+Supply!K27 -> 1248.3587 | L29: =Supply!L20+Supply!L23+Supply!L26+Supply!L27 -> 1412.7002 | ... AH29: =Supply!AH20+Supply!AH23+Supply!AH26+Supply!AH27 -> 3870.2902
A30: Desalination if NO tree programme | B30: M m³/yr | C30: MAX(0, (Demand−Tree) − GW − GMMR) | D30: =D20+D23+D26 -> 372.65221 | E30: =E20+E23+E26 -> 495.97479 | F30: =F20+F23+F26 -> 617.21618 | G30: =G20+G23+G26 -> 736.41683 | H30: =H20+H23+H26 -> 853.61683 | I30: =I20+I23+I26 -> 968.85594 | J30: =J20+J23+J26 -> 1082.1735 | K30: =K20+K23+K26 -> 1248.3587 | L30: =L20+L23+L26 -> 1405.5102 | M30: =Supply!M20+Supply!M23+Supply!M26 -> 1516.2355 | N30: =Supply!N20+Supply!N23+Supply!N26 -> 1625.1165 | O30: =Supply!O20+Supply!O23+Supply!O26 -> 1732.1872 | P30: =Supply!P20+Supply!P23+Supply!P26 -> 1837.4815 | Q30: =Supply!Q20+Supply!Q23+Supply!Q26 -> 1941.0329 | R30: =Supply!R20+Supply!R23+Supply!R26 -> 2042.8749 | S30: =Supply!S20+Supply!S23+Supply!S26 -> 2143.0406 | T30: =Supply!T20+Supply!T23+Supply!T26 -> 2241.5632 | ... AH30: =Supply!AH20+Supply!AH23+Supply!AH26 -> 3466.5705
A31: Incremental desal for tree programme | B31: M m³/yr | C31: Row 12 − Row 13 | D31: =D29-D30 -> 0 | E31: =Supply!E29-Supply!E30 -> 0 | F31: =Supply!F29-Supply!F30 -> 0 | G31: =Supply!G29-Supply!G30 -> 0 | H31: =Supply!H29-Supply!H30 -> 0 | I31: =Supply!I29-Supply!I30 -> 0 | J31: =Supply!J29-Supply!J30 -> 0 | K31: =Supply!K29-Supply!K30 -> 0 | L31: =Supply!L29-Supply!L30 -> 7.1900208 | ... AH31: =Supply!AH29-Supply!AH30 -> 403.71968
A32: → equivalent SWRO capacity | B32: m³/day | C32: Row 14 × 1e6 / 365 | D32: =D31*1000000/365 -> 0 | E32: =Supply!E31*1000000/365 -> 0 | F32: =Supply!F31*1000000/365 -> 0 | G32: =Supply!G31*1000000/365 -> 0 | H32: =Supply!H31*1000000/365 -> 0 | I32: =Supply!I31*1000000/365 -> 0 | J32: =Supply!J31*1000000/365 -> 0 | K32: =Supply!K31*1000000/365 -> 0 | L32: =Supply!L31*1000000/365 -> 19698.687 | ... AH32: =Supply!AH31*1000000/365 -> 1106081.3
A34: Recycled water used (total) | B34: M m³/yr | C34: Recycled water to trees + agriculture | D34: =Supply!D16+Supply!D17 -> 153.03391 | E34: =Supply!E16+Supply!E17 -> 162.00486 | F34: =Supply!F16+Supply!F17 -> 171.13365 | G34: =Supply!G16+Supply!G17 -> 180.41723 | H34: =Supply!H16+Supply!H17 -> 189.85258 | I34: =Supply!I16+Supply!I17 -> 199.43669 | J34: =Supply!J16+Supply!J17 -> 209.16661 | K34: =Supply!K16+Supply!K17 -> 219.03941 | ... AH34: =Supply!AH16+Supply!AH17 -> 479.26772
A35: Total water supply (incl. recycled) | B35: M m³/yr | C35: GW + GMMR + desal + recycled | D35: =Supply!D8+Supply!D9+Supply!D29+Supply!D34 -> 4937.6861 | E35: =Supply!E8+Supply!E9+Supply!E29+Supply!E34 -> 4999.2396 | F35: =Supply!F8+Supply!F9+Supply!F29+Supply!F34 -> 5060.0221 | G35: =Supply!G8+Supply!G9+Supply!G29+Supply!G34 -> 5120.0519 | H35: =Supply!H8+Supply!H9+Supply!H29+Supply!H34 -> 5179.3471 | I35: =Supply!I8+Supply!I9+Supply!I29+Supply!I34 -> 5237.9262 | J35: =Supply!J8+Supply!J9+Supply!J29+Supply!J34 -> 5295.8073 | K35: =Supply!K8+Supply!K9+Supply!K29+Supply!K34 -> 5407.7588 | ... AH35: =Supply!AH8+Supply!AH9+Supply!AH29+Supply!AH34 -> 7071.1429
A36: Share: Local groundwater | B36: % | D36: =Supply!D8/Supply!D5 -> 0.70883404 | E36: =Supply!E8/Supply!E5 -> 0.68960487 | F36: =Supply!F8/Supply!F5 -> 0.67110131 | G36: =Supply!G8/Supply!G5 -> 0.65328453 | H36: =Supply!H8/Supply!H5 -> 0.63611839 | I36: =Supply!I8/Supply!I5 -> 0.61956921 | J36: =Supply!J8/Supply!J5 -> 0.60360559 | K36: =Supply!K8/Supply!K5 -> 0.58224309 | ... AH36: =Supply!AH8/Supply!AH5 -> 0.31453237
A37: Share: GMMR pipeline | B37: % | D37: =Supply!D9/Supply!D5 -> 0.1847019 | E37: =Supply!E9/Supply!E5 -> 0.17877919 | F37: =Supply!F9/Supply!F5 -> 0.17309901 | G37: =Supply!G9/Supply!G5 -> 0.16764813 | H37: =Supply!H9/Supply!H5 -> 0.16241425 | I37: =Supply!I9/Supply!I5 -> 0.15738591 | J37: =Supply!J9/Supply!J5 -> 0.15255243 | K37: =Supply!K9/Supply!K5 -> 0.1464064 | ... AH37: =Supply!AH9/Supply!AH5 -> 0.070353789
A38: Share: Desalination | B38: % | D38: =Supply!D29/Supply!D5 -> 0.075471021 | E38: =Supply!E29/Supply!E5 -> 0.099210046 | F38: =Supply!F29/Supply!F5 -> 0.12197895 | G38: =Supply!G29/Supply!G5 -> 0.14382996 | H38: =Supply!H29/Supply!H5 -> 0.16481167 | I38: =Supply!I29/Supply!I5 -> 0.18496938 | J38: =Supply!J29/Supply!J5 -> 0.20434534 | K38: =Supply!K29/Supply!K5 -> 0.23084586 | ... AH38: =Supply!AH29/Supply!AH5 -> 0.54733587
A40: CHECK: Supply − Demand | B40: M m³/yr | C40: Should equal zero | D40: =Supply!D35-Supply!D5 -> 0 | E40: =Supply!E35-Supply!E5 -> 0 | F40: =Supply!F35-Supply!F5 -> 0 | G40: =Supply!G35-Supply!G5 -> 0 | H40: =Supply!H35-Supply!H5 -> 0 | I40: =Supply!I35-Supply!I5 -> 0 | J40: =Supply!J35-Supply!J5 -> 0 | K40: =Supply!K35-Supply!K5 -> 0 | ... AH40: =Supply!AH35-Supply!AH5 -> 0

Sheet Energy
A1: Electricity Demand for Water Supply — Libya (2020–2050)
A3: Metric | B3: Units | C3: Notes | D3: 2020 | E3: 2021 | F3: 2022 | G3: 2023 | H3: 2024 | I3: 2025 | J3: 2026 | K3: 2027 | L3: 2028 | M3: 2029 | N3: 2030 | O3: 2031 | P3: 2032 | Q3: 2033 | R3: 2034 | S3: 2035 | T3: 2036 | U3: 2037 | V3: 2038 | W3: 2039 | X3: 2040 | Y3: 2041 | Z3: 2042 | AA3: 2043 | AB3: 2044 | AC3: 2045 | AD3: 2046 | AE3: 2047 | AF3: 2048 | AG3: 2049 | AH3: 2050
A5: EI local groundwater | B5: kWh/m³ | C5: EI_GW_2020 × (1+rise)^(year-2020) | D5: =Inputs!$B$26*(1+Inputs!$B$27)^(D$3-2020) -> 0.35 | E5: =Inputs!$B$26*(1+Inputs!$B$27)^(E$3-2020) -> 0.35525 | F5: =Inputs!$B$26*(1+Inputs!$B$27)^(F$3-2020) -> 0.36057875 | G5: =Inputs!$B$26*(1+Inputs!$B$27)^(G$3-2020) -> 0.36598743 | H5: =Inputs!$B$26*(1+Inputs!$B$27)^(H$3-2020) -> 0.37147724 | I5: =Inputs!$B$26*(1+Inputs!$B$27)^(I$3-2020) -> 0.3770494 | J5: =Inputs!$B$26*(1+Inputs!$B$27)^(J$3-2020) -> 0.38270514 | K5: =Inputs!$B$26*(1+Inputs!$B$27)^(K$3-2020) -> 0.38844572 | ... AH5: =Inputs!$B$26*(1+Inputs!$B$27)^(AH$3-2020) -> 0.54707808
A6: EI pipeline (GMMR) | B6: kWh/m³ | C6: EI_pipe × (1+rise)^(year-2020) | D6: =Inputs!$B$28*(1+Inputs!$B$29)^(D$3-2020) -> 1.8 | E6: =Inputs!$B$28*(1+Inputs!$B$29)^(E$3-2020) -> 1.818 | F6: =Inputs!$B$28*(1+Inputs!$B$29)^(F$3-2020) -> 1.83618 | G6: =Inputs!$B$28*(1+Inputs!$B$29)^(G$3-2020) -> 1.8545418 | H6: =Inputs!$B$28*(1+Inputs!$B$29)^(H$3-2020) -> 1.8730872 | I6: =Inputs!$B$28*(1+Inputs!$B$29)^(I$3-2020) -> 1.8918181 | J6: =Inputs!$B$28*(1+Inputs!$B$29)^(J$3-2020) -> 1.9107363 | K6: =Inputs!$B$28*(1+Inputs!$B$29)^(K$3-2020) -> 1.9298436 | ... AH6: =Inputs!$B$28*(1+Inputs!$B$29)^(AH$3-2020) -> 2.426128
A7: EI desalination (SWRO) | B7: kWh/m³ | C7: Linear from EI_2020 to EI_2050 | D7: =Inputs!$B$30+(Inputs!$B$31-Inputs!$B$30)*(D$3-2020)/30 -> 3.5 | E7: =Inputs!$B$30+(Inputs!$B$31-Inputs!$B$30)*(E$3-2020)/30 -> 3.4833333 | F7: =Inputs!$B$30+(Inputs!$B$31-Inputs!$B$30)*(F$3-2020)/30 -> 3.4666667 | G7: =Inputs!$B$30+(Inputs!$B$31-Inputs!$B$30)*(G$3-2020)/30 -> 3.45 | H7: =Inputs!$B$30+(Inputs!$B$31-Inputs!$B$30)*(H$3-2020)/30 -> 3.4333333 | I7: =Inputs!$B$30+(Inputs!$B$31-Inputs!$B$30)*(I$3-2020)/30 -> 3.4166667 | J7: =Inputs!$B$30+(Inputs!$B$31-Inputs!$B$30)*(J$3-2020)/30 -> 3.4 | K7: =Inputs!$B$30+(Inputs!$B$31-Inputs!$B$30)*(K$3-2020)/30 -> 3.3833333 | ... AH7: =Inputs!$B$30+(Inputs!$B$31-Inputs!$B$30)*(AH$3-2020)/30 -> 3
A9: Energy: Local groundwater | B9: GWh/yr | C9: EI × volume (M m³) | D9: =D5*Supply!D8 -> 1225 | E9: =E5*Supply!E8 -> 1224.7244 | F9: =F5*Supply!F8 -> 1224.4488 | G9: =G5*Supply!G8 -> 1224.1733 | H9: =H5*Supply!H8 -> 1223.8979 | I9: =I5*Supply!I8 -> 1223.6225 | J9: =J5*Supply!J8 -> 1223.3472 | K9: =K5*Supply!K8 -> 1223.0719 | ... AH9: =AH5*Supply!AH8 -> 1216.7582
A10: Energy: Pipeline (GMMR) | B10: GWh/yr | C10: EI × volume | D10: =D6*Supply!D9 -> 1641.6 | E10: =E6*Supply!E9 -> 1624.8557 | F10: =F6*Supply!F9 -> 1608.2822 | G10: =G6*Supply!G9 -> 1591.8777 | H10: =H6*Supply!H9 -> 1575.6405 | I10: =I6*Supply!I9 -> 1559.569 | J10: =J6*Supply!J9 -> 1543.6614 | K10: =K6*Supply!K9 -> 1527.916 | ... AH10: =AH6*Supply!AH9 -> 1206.9543
A11: Energy: Desalination (total) (DESAL) | B11: GWh/yr | C11: EI × volume | D11: =D7*Supply!D29 -> 1304.2827 | E11: =E7*Supply!E29 -> 1727.6455 | F11: =F7*Supply!F29 -> 2139.6828 | G11: =G7*Supply!G29 -> 2540.6381 | H11: =H7*Supply!H29 -> 2930.7511 | I11: =I7*Supply!I29 -> 3310.2578 | J11: =J7*Supply!J29 -> 3679.39 | K11: =K7*Supply!K29 -> 4223.6137 | ... AH11: =AH7*Supply!AH29 -> 11610.871
A12: of which: for tree programme | B12: GWh/yr | C12: EI × incremental desal volume | D12: =D7*Supply!D31 -> 0 | E12: =E7*Supply!E31 -> 0 | F12: =F7*Supply!F31 -> 0 | G12: =G7*Supply!G31 -> 0 | H12: =H7*Supply!H31 -> 0 | I12: =I7*Supply!I31 -> 0 | J12: =J7*Supply!J31 -> 0 | K12: =K7*Supply!K31 -> 0 | ... AH12: =AH7*Supply!AH31 -> 1211.1591
A13: EI recycled water | B13: kWh/m³ | C13: Linear from EI_2020 to EI_2050 | D13: =Inputs!B45+(Inputs!B46-Inputs!B45)*(D3-2020)/30 -> 0.8 | E13: =Inputs!B45+(Inputs!B46-Inputs!B45)*(E3-2020)/30 -> 0.795 | F13: =Inputs!B45+(Inputs!B46-Inputs!B45)*(F3-2020)/30 -> 0.79 | G13: =Inputs!B45+(Inputs!B46-Inputs!B45)*(G3-2020)/30 -> 0.785 | H13: =Inputs!B45+(Inputs!B46-Inputs!B45)*(H3-2020)/30 -> 0.78 | I13: =Inputs!B45+(Inputs!B46-Inputs!B45)*(I3-2020)/30 -> 0.775 | J13: =Inputs!B45+(Inputs!B46-Inputs!B45)*(J3-2020)/30 -> 0.77 | K13: =Inputs!B45+(Inputs!B46-Inputs!B45)*(K3-2020)/30 -> 0.765 | L13: =Inputs!B45+(Inputs!B46-Inputs!B45)*(L3-2020)/30 -> 0.76 | M13: =Inputs!B45+(Inputs!B46-Inputs!B45)*(M3-2020)/30 -> 0.755 | N13: =Inputs!B45+(Inputs!B46-Inputs!B45)*(N3-2020)/30 -> 0.75 | O13: =Inputs!B45+(Inputs!B46-Inputs!B45)*(O3-2020)/30 -> 0.745 | P13: =Inputs!B45+(Inputs!B46-Inputs!B45)*(P3-2020)/30 -> 0.74 | Q13: =Inputs!B45+(Inputs!B46-Inputs!B45)*(Q3-2020)/30 -> 0.735 | R13: =Inputs!B45+(Inputs!B46-Inputs!B45)*(R3-2020)/30 -> 0.73 | S13: =Inputs!B45+(Inputs!B46-Inputs!B45)*(S3-2020)/30 -> 0.725 | T13: =Inputs!B45+(Inputs!B46-Inputs!B45)*(T3-2020)/30 -> 0.72 | U13: =Inputs!B45+(Inputs!B46-Inputs!B45)*(U3-2020)/30 -> 0.715 | V13: =Inputs!B45+(Inputs!B46-Inputs!B45)*(V3-2020)/30 -> 0.71 | W13: =Inputs!B45+(Inputs!B46-Inputs!B45)*(W3-2020)/30 -> 0.705 | X13: =Inputs!B45+(Inputs!B46-Inputs!B45)*(X3-2020)/30 -> 0.7 | Y13: =Inputs!B45+(Inputs!B46-Inputs!B45)*(Y3-2020)/30 -> 0.695 | Z13: =Inputs!B45+(Inputs!B46-Inputs!B45)*(Z3-2020)/30 -> 0.69 | AA13: =Inputs!B45+(Inputs!B46-Inputs!B45)*(AA3-2020)/30 -> 0.685 | AB13: =Inputs!B45+(Inputs!B46-Inputs!B45)*(AB3-2020)/30 -> 0.68 | AC13: =Inputs!B45+(Inputs!B46-Inputs!B45)*(AC3-2020)/30 -> 0.675 | AD13: =Inputs!B45+(Inputs!B46-Inputs!B45)*(AD3-2020)/30 -> 0.67 | AE13: =Inputs!B45+(Inputs!B46-Inputs!B45)*(AE3-2020)/30 -> 0.665 | AF13: =Inputs!B45+(Inputs!B46-Inputs!B45)*(AF3-2020)/30 -> 0.66 | AG13: =Inputs!B45+(Inputs!B46-Inputs!B45)*(AG3-2020)/30 -> 0.655 | AH13: =Inputs!B45+(Inputs!B46-Inputs!B45)*(AH3-2020)/30 -> 0.65
A14: Energy: Recycled water (RW) | B14: GWh/yr | C14: EI × recycled water volume | D14: =D13*(Supply!D16+Supply!D17) -> 122.42713 | E14: =E13*(Supply!E16+Supply!E17) -> 128.79386 | F14: =F13*(Supply!F16+Supply!F17) -> 135.19558 | G14: =G13*(Supply!G16+Supply!G17) -> 141.62753 | H14: =H13*(Supply!H16+Supply!H17) -> 148.08501 | I14: =I13*(Supply!I16+Supply!I17) -> 154.56344 | J14: =J13*(Supply!J16+Supply!J17) -> 161.05829 | K14: =K13*(Supply!K16+Supply!K17) -> 167.56515 | ... AH14: =AH13*(Supply!AH16+Supply!AH17) -> 311.52402
A15: TOTAL electricity demand | B15: GWh/yr | C15: GW + GMMR + Desal | D15: =D9+D10+D11+D14 -> 4293.3099 | E15: =E9+E10+E11+E14 -> 4706.0194 | F15: =F9+F10+F11+F14 -> 5107.6093 | G15: =G9+G10+G11+G14 -> 5498.3166 | H15: =H9+H10+H11+H14 -> 5878.3745 | I15: =I9+I10+I11+I14 -> 6248.0127 | J15: =J9+J10+J11+J14 -> 6607.4569 | K15: =K9+K10+K11+K14 -> 7142.1668 | ... AH15: =AH9+AH10+AH11+AH14 -> 14346.107
A16: TOTAL electricity demand | B16: TWh/yr | C16: GWh / 1000 | D16: =D15/1000 -> 4.2933099 | E16: =E15/1000 -> 4.7060194 | F16: =F15/1000 -> 5.1076093 | G16: =G15/1000 -> 5.4983166 | H16: =H15/1000 -> 5.8783745 | I16: =I15/1000 -> 6.2480127 | J16: =J15/1000 -> 6.6074569 | K16: =K15/1000 -> 7.1421668 | ... AH16: =AH15/1000 -> 14.346107
B17: PJ/yr | C17: GW * × 0.0036 PJ/GWh | D17: =+D15*Inputs!$B$64 -> 15.455916 | E17: =+E15*Inputs!$B$64 -> 16.94167 | F17: =+F15*Inputs!$B$64 -> 18.387394 | G17: =+G15*Inputs!$B$64 -> 19.79394 | H17: =+H15*Inputs!$B$64 -> 21.162148 | I17: =+I15*Inputs!$B$64 -> 22.492846 | J17: =+J15*Inputs!$B$64 -> 23.786845 | K17: =+K15*Inputs!$B$64 -> 25.711801 | ... AH17: =+AH15*Inputs!$B$64 -> 51.645985
A19: BAU (no tree programme) | B19: PJ/yr | C19: GW + GMMR + desal (excl. tree programme) + RW | D19: =+(D9+D10+(D11-D12)+D14)*Inputs!$B$64 -> 15.455916 | E19: =+(E9+E10+(E11-E12)+E14)*Inputs!$B$64 -> 16.94167 | F19: =+(F9+F10+(F11-F12)+F14)*Inputs!$B$64 -> 18.387394 | G19: =+(G9+G10+(G11-G12)+G14)*Inputs!$B$64 -> 19.79394 | H19: =+(H9+H10+(H11-H12)+H14)*Inputs!$B$64 -> 21.162148 | I19: =+(I9+I10+(I11-I12)+I14)*Inputs!$B$64 -> 22.492846 | J19: =+(J9+J10+(J11-J12)+J14)*Inputs!$B$64 -> 23.786845 | K19: =+(K9+K10+(K11-K12)+K14)*Inputs!$B$64 -> 25.711801 | ... AH19: =+(AH9+AH10+(AH11-AH12)+AH14)*Inputs!$B$64 -> 47.285813
A20: Unconditional (incl. tree programme) | B20: PJ/yr | C20: GW + GMMR + desal (incl. tree) + RW | D20: =+(D9+D10+D11+D14)*Inputs!$B$64 -> 15.455916 | E20: =+(E9+E10+E11+E14)*Inputs!$B$64 -> 16.94167 | F20: =+(F9+F10+F11+F14)*Inputs!$B$64 -> 18.387394 | G20: =+(G9+G10+G11+G14)*Inputs!$B$64 -> 19.79394 | H20: =+(H9+H10+H11+H14)*Inputs!$B$64 -> 21.162148 | I20: =+(I9+I10+I11+I14)*Inputs!$B$64 -> 22.492846 | J20: =+(J9+J10+J11+J14)*Inputs!$B$64 -> 23.786845 | K20: =+(K9+K10+K11+K14)*Inputs!$B$64 -> 25.711801 | ... AH20: =+(AH9+AH10+AH11+AH14)*Inputs!$B$64 -> 51.645985
A21: Conditional (incl. tree programme) | B21: PJ/yr | C21: GW + GMMR + desal (incl. tree) + RW | D21: =+(D9+D10+D11+D14)*Inputs!$B$64 -> 15.455916 | E21: =+(E9+E10+E11+E14)*Inputs!$B$64 -> 16.94167 | F21: =+(F9+F10+F11+F14)*Inputs!$B$64 -> 18.387394 | G21: =+(G9+G10+G11+G14)*Inputs!$B$64 -> 19.79394 | H21: =+(H9+H10+H11+H14)*Inputs!$B$64 -> 21.162148 | I21: =+(I9+I10+I11+I14)*Inputs!$B$64 -> 22.492846 | J21: =+(J9+J10+J11+J14)*Inputs!$B$64 -> 23.786845 | K21: =+(K9+K10+K11+K14)*Inputs!$B$64 -> 25.711801 | ... AH21: =+(AH9+AH10+AH11+AH14)*Inputs!$B$64 -> 51.645985
A23: System-avg EI (kWh/m³) | B23: kWh/m³ | C23: Total energy (GWh) / Total water (M m³) | D23: =D15/Supply!D5 -> 0.86949834 | E23: =E15/Supply!E5 -> 0.94134704 | F23: =F15/Supply!F5 -> 1.0094045 | G23: =G15/Supply!G5 -> 1.0738791 | H23: =H15/Supply!H5 -> 1.1349644 | I23: =I15/Supply!I5 -> 1.1928409 | J23: =J15/Supply!J5 -> 1.247677 | K23: =K15/Supply!K5 -> 1.3207258 | ... AH23: =AH15/Supply!AH5 -> 2.0288244
A24: Electricity per capita | B24: kWh/cap/yr | C24: Total energy × 1e6 / Population | D24: =D15*1000000/Demand!D5 -> 637.43627 | E24: =E15*1000000/Demand!E5 -> 685.90873 | F24: =F15*1000000/Demand!F5 -> 731.04516 | G24: =G15*1000000/Demand!G5 -> 773.05581 | H24: =H15*1000000/Demand!H5 -> 812.1358 | I24: =I15*1000000/Demand!I5 -> 848.46638 | J24: =J15*1000000/Demand!J5 -> 882.21618 | K24: =K15*1000000/Demand!K5 -> 937.86646 | ... AH24: =AH15*1000000/Demand!AH5 -> 1365.3919
A25: Desalination share of energy | B25: % | D25: =D11/D15 -> 0.30379422 | E25: =E11/E15 -> 0.36711398 | F25: =F11/F15 -> 0.4189206 | G25: =G11/G15 -> 0.46207562 | H25: =H11/H15 -> 0.49856489 | I25: =I11/I15 -> 0.52980971 | J25: =J11/J15 -> 0.55685419 | K25: =K11/K15 -> 0.59136307 | ... AH25: =AH11/AH15 -> 0.80933946
A27: ADJUSTED SCENARIOS (v2 — from technical review)
A28: Adj: Groundwater (grid-electrified only) | B28: GWh/yr | C28: GW energy × Inputs!B60 | D28: =D9*Inputs!$B$60 -> 649.25 | E28: =E9*Inputs!$B$60 -> 649.10392 | F28: =F9*Inputs!$B$60 -> 648.95787 | G28: =G9*Inputs!$B$60 -> 648.81185 | H28: =H9*Inputs!$B$60 -> 648.66587 | I28: =I9*Inputs!$B$60 -> 648.51992 | J28: =J9*Inputs!$B$60 -> 648.37401 | K28: =K9*Inputs!$B$60 -> 648.22812 | ... AH28: =AH9*Inputs!$B$60 -> 644.88183
A29: Adj: Thermal desal fleet share | B29: share | C29: Linear interp B61 → B62 | D29: =Inputs!$B$61+(Inputs!$B$62-Inputs!$B$61)*(D$3-2020)/30 -> 0.95 | E29: =Inputs!$B$61+(Inputs!$B$62-Inputs!$B$61)*(E$3-2020)/30 -> 0.92166667 | F29: =Inputs!$B$61+(Inputs!$B$62-Inputs!$B$61)*(F$3-2020)/30 -> 0.89333333 | G29: =Inputs!$B$61+(Inputs!$B$62-Inputs!$B$61)*(G$3-2020)/30 -> 0.865 | H29: =Inputs!$B$61+(Inputs!$B$62-Inputs!$B$61)*(H$3-2020)/30 -> 0.83666667 | I29: =Inputs!$B$61+(Inputs!$B$62-Inputs!$B$61)*(I$3-2020)/30 -> 0.80833333 | J29: =Inputs!$B$61+(Inputs!$B$62-Inputs!$B$61)*(J$3-2020)/30 -> 0.78 | K29: =Inputs!$B$61+(Inputs!$B$62-Inputs!$B$61)*(K$3-2020)/30 -> 0.75166667 | ... AH29: =Inputs!$B$61+(Inputs!$B$62-Inputs!$B$61)*(AH$3-2020)/30 -> 0.1
A30: Adj: Fleet-blended desal EI | B30: kWh/m³ | C30: (1-share)×SWRO + share×thermal | D30: =(1-D29)*D7+D29*Inputs!$B$63 -> 14.425 | E30: =(1-E29)*E7+E29*Inputs!$B$63 -> 14.097861 | F30: =(1-F29)*F7+F29*Inputs!$B$63 -> 13.769778 | G30: =(1-G29)*G7+G29*Inputs!$B$63 -> 13.44075 | H30: =(1-H29)*H7+H29*Inputs!$B$63 -> 13.110778 | I30: =(1-I29)*I7+I29*Inputs!$B$63 -> 12.779861 | J30: =(1-J29)*J7+J29*Inputs!$B$63 -> 12.448 | K30: =(1-K29)*K7+K29*Inputs!$B$63 -> 12.115194 | ... AH30: =(1-AH29)*AH7+AH29*Inputs!$B$63 -> 4.2
A31: Adj: Desal energy (fleet-blended) | B31: GWh/yr | C31: Blended EI × total desal volume | D31: =D30*Supply!D29 -> 5375.5082 | E31: =E30*Supply!E29 -> 6992.1838 | F31: =F30*Supply!F29 -> 8498.9297 | G31: =G30*Supply!G29 -> 9897.9945 | H31: =H30*Supply!H29 -> 11191.581 | I31: =I30*Supply!I29 -> 12381.844 | J31: =J30*Supply!J29 -> 13470.896 | K31: =K30*Supply!K29 -> 15124.109 | ... AH31: =AH30*Supply!AH29 -> 16255.219
A32: Adj: TOTAL electricity (v2 fleet-blended) | B32: PJ/yr | C32: GridGW + GMMR + FleetDesal + RW | D32: =(D28+D10+D31+D14)*Inputs!$B$64 -> 28.039627 | E32: =(E28+E10+E31+E14)*Inputs!$B$64 -> 33.821774 | F32: =(F28+F10+F31+F14)*Inputs!$B$64 -> 39.208915 | G32: =(G28+G10+G31+G14)*Inputs!$B$64 -> 44.209122 | H32: =(H28+H10+H31+H14)*Inputs!$B$64 -> 48.830299 | I32: =(I28+I10+I31+I14)*Inputs!$B$64 -> 53.080188 | J32: =(J28+J10+J31+J14)*Inputs!$B$64 -> 56.966364 | K32: =(K28+K10+K31+K14)*Inputs!$B$64 -> 62.884145 | ... AH32: =(AH28+AH10+AH31+AH14)*Inputs!$B$64 -> 66.306884
A33: % of Libya total generation (cross-check) | B33: % | C33: Uncond total / Inputs!B65 | D33: =D15/Inputs!$B$65 -> 0.122666 | E33: =E15/Inputs!$B$65 -> 0.1344577 | F33: =F15/Inputs!$B$65 -> 0.14593169 | G33: =G15/Inputs!$B$65 -> 0.15709476 | H33: =H15/Inputs!$B$65 -> 0.16795356 | I33: =I15/Inputs!$B$65 -> 0.17851465 | J33: =J15/Inputs!$B$65 -> 0.18878448 | K33: =K15/Inputs!$B$65 -> 0.20406191 | ... AH33: =AH15/Inputs!$B$65 -> 0.40988877
